Workbook

Sheet Dashboard
A2: Production Performance ULULULU
A3: PT Bulawan Daya Lestari | Site Gunung Patung, Bolaang Mongondow | K3: Data through | L3: Data through | M3: =MAX('Daily Production'!A6:A33) -> 46275
B5: Ore Processed | C5: Ore Processed | D5: Ore Processed | E5: Average TPD | F5: Average TPD | G5: Average TPD | H5: Weighted Throughput | I5: Weighted Throughput | J5: Weighted Throughput | K5: Weighted Au Grade | L5: Weighted Au Grade | M5: Weighted Au Grade | R5: Date | S5: Ore Processed | T5: Crushing Availability | U5: Milling Availability
B6: =SUM('Daily Production'!B6:B33) -> 2145.0891 | E6: =IFERROR(AVERAGEIF('Daily Production'!B6:B33,">0"),0) -> 165.00685 | H6: =IFERROR(SUM('Daily Production'!B6:B33)/SUM('Daily Production'!D6:D33),0) -> 19.773444 | K6: =IFERROR(SUM('Daily Production'!H6:H33)/SUM('Daily Production'!B6:B33),0) -> 0.8278617 | R6: =TEXT('Daily Production'!A6,"dd-mmm") -> 01-Jun | S6: ='Daily Production'!B6 -> 0 | T6: ='Daily Production'!I6 -> 0 | U6: ='Daily Production'!J6 -> 0
R7: =TEXT('Daily Production'!A7,"dd-mmm") -> 02-Jun | S7: ='Daily Production'!B7 -> 78.0435 | T7: ='Daily Production'!I7 -> 0 | U7: ='Daily Production'!J7 -> 0
R8: =TEXT('Daily Production'!A8,"dd-mmm") -> 03-Jun | S8: ='Daily Production'!B8 -> 17.712 | T8: ='Daily Production'!I8 -> 0 | U8: ='Daily Production'!J8 -> 0
R9: =TEXT('Daily Production'!A9,"dd-mmm") -> 04-Jun | S9: ='Daily Production'!B9 -> 157.9905 | T9: ='Daily Production'!I9 -> 0 | U9: ='Daily Production'!J9 -> 0
B10: Au in Feed | C10: Au in Feed | D10: Au in Feed | E10: Crushing Availability | F10: Crushing Availability | G10: Crushing Availability | H10: Milling Availability | I10: Milling Availability | J10: Milling Availability | K10: Sandios Intensity | L10: Sandios Intensity | M10: Sandios Intensity | R10: =TEXT('Daily Production'!A10,"dd-mmm") -> 18-Aug | S10: ='Daily Production'!B10 -> 37.9192 | T10: ='Daily Production'!I10 -> 0.16944444 | U10: ='Daily Production'!J10 -> 0
B11: =SUM('Daily Production'!H6:H33)/1000 -> 1.7758371 | E11: =IFERROR(AVERAGE('Daily Production'!I6:I33),0) -> 0.23214286 | H11: =IFERROR(AVERAGE('Daily Production'!J6:J33),0) -> 0.30128968 | K11: =IFERROR(SUM('Daily Production'!M6:M33)/SUM('Daily Production'!B6:B33),0) -> 0.52445374 | R11: =TEXT('Daily Production'!A11,"dd-mmm") -> 19-Aug | S11: ='Daily Production'!B11 -> 283.1708 | T11: ='Daily Production'!I11 -> 0.91944444 | U11: ='Daily Production'!J11 -> 0
R12: =TEXT('Daily Production'!A12,"dd-mmm") -> 20-Aug | S12: ='Daily Production'!B12 -> 337.1445 | T12: ='Daily Production'!I12 -> 0.91944444 | U12: ='Daily Production'!J12 -> 0
R13: =TEXT('Daily Production'!A13,"dd-mmm") -> 21-Aug | S13: ='Daily Production'!B13 -> 287.1045 | T13: ='Daily Production'!I13 -> 0.78611111 | U13: ='Daily Production'!J13 -> 0
R14: =TEXT('Daily Production'!A14,"dd-mmm") -> 22-Aug | S14: ='Daily Production'!B14 -> 197.0325 | T14: ='Daily Production'!I14 -> 0.75138889 | U14: ='Daily Production'!J14 -> 0
B15: Consumption Intensity | I15: Legacy Data Quality Notes | R15: =TEXT('Daily Production'!A15,"dd-mmm") -> 23-Aug | S15: ='Daily Production'!B15 -> 0 | T15: ='Daily Production'!I15 -> 0.0027777778 | U15: ='Daily Production'!J15 -> 0
B16: Material | C16: Total | D16: Unit | E16: Per tonne | F16: Rate unit | G16: Source | I16: Daily Summary: #DIV/0! muncul jika jam operasional atau input analitis bernilai nol. | R16: =TEXT('Daily Production'!A16,"dd-mmm") -> 24-Aug | S16: ='Daily Production'!B16 -> 162.0045 | T16: ='Daily Production'!I16 -> 0.83472222 | U16: ='Daily Production'!J16 -> 0
B17: Sandios | C17: =SUM('Daily Production'!M6:M33) -> 1125 | D17: kg | E17: =IFERROR(C17/$C$23,0) -> 0.52445374 | F17: kg/t | G17: Daily Production | I17: Milling and Leach Feed: #REF! lama tetap ada di T80:Y94 dan dikecualikan dari dashboard | R17: =TEXT('Daily Production'!A17,"dd-mmm") -> 25-Aug | S17: ='Daily Production'!B17 -> 0 | T17: ='Daily Production'!I17 -> 0.0027777778 | U17: ='Daily Production'!J17 -> 0
B18: Lime | C18: =SUM('Daily Production'!N6:N33) -> 2250 | D18: kg | E18: =IFERROR(C18/$C$23,0) -> 1.0489075 | F18: kg/t | G18: Daily Production | I18: Berkas tersebut memuat data dari beberapa bulan; KPI utama menggunakan tanggal yang tertaut hingga 10 September 2026. | R18: =TEXT('Daily Production'!A18,"dd-mmm") -> 26-Aug | S18: ='Daily Production'!B18 -> 0 | T18: ='Daily Production'!I18 -> 0.0027777778 | U18: ='Daily Production'!J18 -> 0
B19: Carbon | C19: =SUM('Daily Production'!O6:O33) -> 2000 | D19: kg | E19: =IFERROR(C19/$C$23,0) -> 0.9323622 | F19: kg/t | G19: Daily Production | I19: Gold recovery is not shown until feed, tail, solution, and carbon results reconcile. | R19: =TEXT('Daily Production'!A19,"dd-mmm") -> 27-Aug | S19: ='Daily Production'!B19 -> 124.9471 | T19: ='Daily Production'!I19 -> 0.43888889 | U19: ='Daily Production'!J19 -> 0
B20: Flocculant | C20: =SUM('Daily Production'!P6:P33) -> 50 | D20: kg | E20: =IFERROR(C20/$C$23,0) -> 0.023309055 | F20: kg/t | G20: Daily Production | I20: All legacy worksheets remain unchanged as the supporting source. | R20: =TEXT('Daily Production'!A20,"dd-mmm") -> 28-Aug | S20: ='Daily Production'!B20 -> 167.765 | T20: ='Daily Production'!I20 -> 0.66805556 | U20: ='Daily Production'!J20 -> 0
B21: Fuel | C21: =SUM('Daily Production'!Q6:Q33) -> 0 | D21: L | E21: =IFERROR(C21/$C$23,0) -> 0 | F21: L/t | G21: Daily Production | R21: =TEXT('Daily Production'!A21,"dd-mmm") -> 29-Aug | S21: ='Daily Production'!B21 -> 240.435 | T21: ='Daily Production'!I21 -> 0.83472222 | U21: ='Daily Production'!J21 -> 0
R22: =TEXT('Daily Production'!A22,"dd-mmm") -> 30-Aug | S22: ='Daily Production'!B22 -> 53.82 | T22: ='Daily Production'!I22 -> 0.16944444 | U22: ='Daily Production'!J22 -> 0
B23: KPI denominator | C23: =SUM('Daily Production'!B6:B33) -> 2145.0891 | D23: t | R23: =TEXT('Daily Production'!A23,"dd-mmm") -> 31-Aug | S23: ='Daily Production'!B23 -> 0 | T23: ='Daily Production'!I23 -> 0 | U23: ='Daily Production'!J23 -> 0.93472222
R24: =TEXT('Daily Production'!A24,"dd-mmm") -> 01-Sep | S24: ='Daily Production'!B24 -> 0 | T24: ='Daily Production'!I24 -> 0 | U24: ='Daily Production'!J24 -> 0.95416667
R25: =TEXT('Daily Production'!A25,"dd-mmm") -> 02-Sep | S25: ='Daily Production'!B25 -> 0 | T25: ='Daily Production'!I25 -> 0 | U25: ='Daily Production'!J25 -> 0.91666667
R26: =TEXT('Daily Production'!A26,"dd-mmm") -> 03-Sep | S26: ='Daily Production'!B26 -> 0 | T26: ='Daily Production'!I26 -> 0 | U26: ='Daily Production'!J26 -> 0.45902778
R27: =TEXT('Daily Production'!A27,"dd-mmm") -> 04-Sep | S27: ='Daily Production'!B27 -> 0 | T27: ='Daily Production'!I27 -> 0 | U27: ='Daily Production'!J27 -> 0.0013888889
R28: =TEXT('Daily Production'!A28,"dd-mmm") -> 05-Sep | S28: ='Daily Production'!B28 -> 0 | T28: ='Daily Production'!I28 -> 0 | U28: ='Daily Production'!J28 -> 0.45902778
R29: =TEXT('Daily Production'!A29,"dd-mmm") -> 06-Sep | S29: ='Daily Production'!B29 -> 0 | T29: ='Daily Production'!I29 -> 0 | U29: ='Daily Production'!J29 -> 0.90972222
R30: =TEXT('Daily Production'!A30,"dd-mmm") -> 07-Sep | S30: ='Daily Production'!B30 -> 0 | T30: ='Daily Production'!I30 -> 0 | U30: ='Daily Production'!J30 -> 0.93541667
R31: =TEXT('Daily Production'!A31,"dd-mmm") -> 08-Sep | S31: ='Daily Production'!B31 -> 0 | T31: ='Daily Production'!I31 -> 0 | U31: ='Daily Production'!J31 -> 0.98680556
R32: =TEXT('Daily Production'!A32,"dd-mmm") -> 09-Sep | S32: ='Daily Production'!B32 -> 0 | T32: ='Daily Production'!I32 -> 0 | U32: ='Daily Production'!J32 -> 0.94861111
R33: =TEXT('Daily Production'!A33,"dd-mmm") -> 10-Sep | S33: ='Daily Production'!B33 -> 0 | T33: ='Daily Production'!I33 -> 0 | U33: ='Daily Production'!J33 -> 0.93055556

Sheet Daily Production
A2: Daily Production
A3: PT Bulawan Daya Lestari | linked operational view through 10-Sep-2026
A4: Tampilan ini diperbarui berdasarkan Ringkasan Harian
A5: Date | B5: Ore Processed (t) | C5: MTD (t) | D5: Crushing Run (h) | E5: Milling Run (h) | F5: Throughput (t/h) | G5: Au Grade (g/t) | H5: Au in Feed (g) | I5: Crushing Availability | J5: Milling Availability | K5: CIP Availability | L5: Plant Usability | M5: Sandios (kg) | N5: Lime (kg) | O5: Carbon (kg) | P5: Flocculant (kg) | Q5: Fuel (L)
A6: ='Daily Summary '!B7 -> 46174 | B6: =IFERROR('Daily Summary '!C7,"") -> 0 | C6: =IFERROR('Daily Summary '!D7,"") -> 0 | D6: =IFERROR('Daily Summary '!I7,"") -> 0 | E6: =IFERROR('Daily Summary '!J7,"") -> 0 | F6: =IFERROR('Daily Summary '!E7,"") | G6: =IFERROR('Daily Summary '!F7,"") -> 0 | H6: =IFERROR('Daily Summary '!G7,"") -> 0 | I6: =IFERROR('Daily Summary '!K7,"") -> 0 | J6: =IFERROR('Daily Summary '!L7,"") -> 0 | K6: =IFERROR('Daily Summary '!M7,"") -> 1 | L6: =IFERROR('Daily Summary '!N7,"") -> 0 | M6: =IFERROR('Daily Summary '!Z7,"") -> 0 | N6: =IFERROR('Daily Summary '!AC7,"") -> 0 | O6: =IFERROR('Daily Summary '!AB7,"") -> 0 | P6: =IFERROR('Daily Summary '!AF7,"") -> 0 | Q6: =IFERROR('Daily Summary '!AG7,"") -> 0
A7: ='Daily Summary '!B8 -> 46175 | B7: =IFERROR('Daily Summary '!C8,"") -> 78.0435 | C7: =IFERROR('Daily Summary '!D8,"") -> 78.0435 | D7: =IFERROR('Daily Summary '!I8,"") -> 11.033333 | E7: =IFERROR('Daily Summary '!J8,"") -> 0 | F7: =IFERROR('Daily Summary '!E8,"") -> 7.073429 | G7: =IFERROR('Daily Summary '!F8,"") -> 1.45 | H7: =IFERROR('Daily Summary '!G8,"") -> 113.16308 | I7: =IFERROR('Daily Summary '!K8,"") -> 0 | J7: =IFERROR('Daily Summary '!L8,"") -> 0 | K7: =IFERROR('Daily Summary '!M8,"") -> 1 | L7: =IFERROR('Daily Summary '!N8,"") -> 0 | M7: =IFERROR('Daily Summary '!Z8,"") -> 0 | N7: =IFERROR('Daily Summary '!AC8,"") -> 0 | O7: =IFERROR('Daily Summary '!AB8,"") -> 0 | P7: =IFERROR('Daily Summary '!AF8,"") -> 0 | Q7: =IFERROR('Daily Summary '!AG8,"") -> 0
A8: ='Daily Summary '!B9 -> 46176 | B8: =IFERROR('Daily Summary '!C9,"") -> 17.712 | C8: =IFERROR('Daily Summary '!D9,"") -> 95.7555 | D8: =IFERROR('Daily Summary '!I9,"") -> 11.033333 | E8: =IFERROR('Daily Summary '!J9,"") -> 0 | F8: =IFERROR('Daily Summary '!E9,"") -> 1.6053172 | G8: =IFERROR('Daily Summary '!F9,"") -> 1.45 | H8: =IFERROR('Daily Summary '!G9,"") -> 25.6824 | I8: =IFERROR('Daily Summary '!K9,"") -> 0 | J8: =IFERROR('Daily Summary '!L9,"") -> 0 | K8: =IFERROR('Daily Summary '!M9,"") -> 1 | L8: =IFERROR('Daily Summary '!N9,"") -> 0 | M8: =IFERROR('Daily Summary '!Z9,"") -> 0 | N8: =IFERROR('Daily Summary '!AC9,"") -> 0 | O8: =IFERROR('Daily Summary '!AB9,"") -> 0 | P8: =IFERROR('Daily Summary '!AF9,"") -> 0 | Q8: =IFERROR('Daily Summary '!AG9,"") -> 0
A9: ='Daily Summary '!B10 -> 46177 | B9: =IFERROR('Daily Summary '!C10,"") -> 157.9905 | C9: =IFERROR('Daily Summary '!D10,"") -> 253.746 | D9: =IFERROR('Daily Summary '!I10,"") -> 9.4333333 | E9: =IFERROR('Daily Summary '!J10,"") -> 0 | F9: =IFERROR('Daily Summary '!E10,"") -> 16.74811 | G9: =IFERROR('Daily Summary '!F10,"") -> 1.45 | H9: =IFERROR('Daily Summary '!G10,"") -> 229.08622 | I9: =IFERROR('Daily Summary '!K10,"") -> 0 | J9: =IFERROR('Daily Summary '!L10,"") -> 0 | K9: =IFERROR('Daily Summary '!M10,"") -> 1 | L9: =IFERROR('Daily Summary '!N10,"") -> 0 | M9: =IFERROR('Daily Summary '!Z10,"") -> 150 | N9: =IFERROR('Daily Summary '!AC10,"") -> 250 | O9: =IFERROR('Daily Summary '!AB10,"") -> 0 | P9: =IFERROR('Daily Summary '!AF10,"") -> 0 | Q9: =IFERROR('Daily Summary '!AG10,"") -> 0
A10: ='Daily Summary '!B11 -> 46252 | B10: =IFERROR('Daily Summary '!C11,"") -> 37.9192 | C10: =IFERROR('Daily Summary '!D11,"") -> 291.6652 | D10: =IFERROR('Daily Summary '!I11,"") -> 2.0333333 | E10: =IFERROR('Daily Summary '!J11,"") -> 0 | F10: =IFERROR('Daily Summary '!E11,"") -> 18.648787 | G10: =IFERROR('Daily Summary '!F11,"") -> 0.77 | H10: =IFERROR('Daily Summary '!G11,"") -> 29.197784 | I10: =IFERROR('Daily Summary '!K11,"") -> 0.16944444 | J10: =IFERROR('Daily Summary '!L11,"") -> 0 | K10: =IFERROR('Daily Summary '!M11,"") -> 1 | L10: =IFERROR('Daily Summary '!N11,"") -> 0 | M10: =IFERROR('Daily Summary '!Z11,"") -> 225 | N10: =IFERROR('Daily Summary '!AC11,"") -> 1250 | O10: =IFERROR('Daily Summary '!AB11,"") -> 1000 | P10: =IFERROR('Daily Summary '!AF11,"") -> 25 | Q10: =IFERROR('Daily Summary '!AG11,"") -> 0
A11: ='Daily Summary '!B12 -> 46253 | B11: =IFERROR('Daily Summary '!C12,"") -> 283.1708 | C11: =IFERROR('Daily Summary '!D12,"") -> 574.836 | D11: =IFERROR('Daily Summary '!I12,"") -> 11.033333 | E11: =IFERROR('Daily Summary '!J12,"") -> 0 | F11: =IFERROR('Daily Summary '!E12,"") -> 25.665027 | G11: =IFERROR('Daily Summary '!F12,"") -> 1.021 | H11: =IFERROR('Daily Summary '!G12,"") -> 289.11739 | I11: =IFERROR('Daily Summary '!K12,"") -> 0.91944444 | J11: =IFERROR('Daily Summary '!L12,"") -> 0 | K11: =IFERROR('Daily Summary '!M12,"") -> 1 | L11: =IFERROR('Daily Summary '!N12,"") -> 0 | M11: =IFERROR('Daily Summary '!Z12,"") -> 275 | N11: =IFERROR('Daily Summary '!AC12,"") -> 0 | O11: =IFERROR('Daily Summary '!AB12,"") -> 1000 | P11: =IFERROR('Daily Summary '!AF12,"") -> 25 | Q11: =IFERROR('Daily Summary '!AG12,"") -> 0
A12: ='Daily Summary '!B13 -> 46254 | B12: =IFERROR('Daily Summary '!C13,"") -> 337.1445 | C12: =IFERROR('Daily Summary '!D13,"") -> 911.9805 | D12: =IFERROR('Daily Summary '!I13,"") -> 10.016667 | E12: =IFERROR('Daily Summary '!J13,"") -> 0 | F12: =IFERROR('Daily Summary '!E13,"") -> 33.658353 | G12: =IFERROR('Daily Summary '!F13,"") -> 0.604 | H12: =IFERROR('Daily Summary '!G13,"") -> 203.63528 | I12: =IFERROR('Daily Summary '!K13,"") -> 0.91944444 | J12: =IFERROR('Daily Summary '!L13,"") -> 0 | K12: =IFERROR('Daily Summary '!M13,"") -> 1 | L12: =IFERROR('Daily Summary '!N13,"") -> 0 | M12: =IFERROR('Daily Summary '!Z13,"") -> 100 | N12: =IFERROR('Daily Summary '!AC13,"") -> 0 | O12: =IFERROR('Daily Summary '!AB13,"") -> 0 | P12: =IFERROR('Daily Summary '!AF13,"") -> 0 | Q12: =IFERROR('Daily Summary '!AG13,"") -> 0
A13: ='Daily Summary '!B14 -> 46255 | B13: =IFERROR('Daily Summary '!C14,"") -> 287.1045 | C13: =IFERROR('Daily Summary '!D14,"") -> 1199.085 | D13: =IFERROR('Daily Summary '!I14,"") -> 9.4333333 | E13: =IFERROR('Daily Summary '!J14,"") -> 0 | F13: =IFERROR('Daily Summary '!E14,"") -> 30.435106 | G13: =IFERROR('Daily Summary '!F14,"") -> 0.442 | H13: =IFERROR('Daily Summary '!G14,"") -> 126.90019 | I13: =IFERROR('Daily Summary '!K14,"") -> 0.78611111 | J13: =IFERROR('Daily Summary '!L14,"") -> 0 | K13: =IFERROR('Daily Summary '!M14,"") -> 1 | L13: =IFERROR('Daily Summary '!N14,"") -> 0 | M13: =IFERROR('Daily Summary '!Z14,"") -> 0 | N13: =IFERROR('Daily Summary '!AC14,"") -> 0 | O13: =IFERROR('Daily Summary '!AB14,"") -> 0 | P13: =IFERROR('Daily Summary '!AF14,"") -> 0 | Q13: =IFERROR('Daily Summary '!AG14,"") -> 0
A14: ='Daily Summary '!B15 -> 46256 | B14: =IFERROR('Daily Summary '!C15,"") -> 197.0325 | C14: =IFERROR('Daily Summary '!D15,"") -> 1396.1175 | D14: =IFERROR('Daily Summary '!I15,"") -> 9.0166667 | E14: =IFERROR('Daily Summary '!J15,"") -> 0 | F14: =IFERROR('Daily Summary '!E15,"") -> 21.852033 | G14: =IFERROR('Daily Summary '!F15,"") -> 0.62933333 | H14: =IFERROR('Daily Summary '!G15,"") -> 123.99912 | I14: =IFERROR('Daily Summary '!K15,"") -> 0.75138889 | J14: =IFERROR('Daily Summary '!L15,"") -> 0 | K14: =IFERROR('Daily Summary '!M15,"") -> 1 | L14: =IFERROR('Daily Summary '!N15,"") -> 0 | M14: =IFERROR('Daily Summary '!Z15,"") -> 50 | N14: =IFERROR('Daily Summary '!AC15,"") -> 0 | O14: =IFERROR('Daily Summary '!AB15,"") -> 0 | P14: =IFERROR('Daily Summary '!AF15,"") -> 0 | Q14: =IFERROR('Daily Summary '!AG15,"") -> 0
A15: ='Daily Summary '!B16 -> 46257 | B15: =IFERROR('Daily Summary '!C16,"") -> 0 | C15: =IFERROR('Daily Summary '!D16,"") -> 1396.1175 | D15: =IFERROR('Daily Summary '!I16,"") -> 0.033333333 | E15: =IFERROR('Daily Summary '!J16,"") -> 0 | F15: =IFERROR('Daily Summary '!E16,"") -> 0 | G15: =IFERROR('Daily Summary '!F16,"") -> 0 | H15: =IFERROR('Daily Summary '!G16,"") -> 0 | I15: =IFERROR('Daily Summary '!K16,"") -> 0.0027777778 | J15: =IFERROR('Daily Summary '!L16,"") -> 0 | K15: =IFERROR('Daily Summary '!M16,"") -> 1 | L15: =IFERROR('Daily Summary '!N16,"") -> 0 | M15: =IFERROR('Daily Summary '!Z16,"") -> 175 | N15: =IFERROR('Daily Summary '!AC16,"") -> 500 | O15: =IFERROR('Daily Summary '!AB16,"") -> 0 | P15: =IFERROR('Daily Summary '!AF16,"") -> 0 | Q15: =IFERROR('Daily Summary '!AG16,"") -> 0
A16: ='Daily Summary '!B17 -> 46258 | B16: =IFERROR('Daily Summary '!C17,"") -> 162.0045 | C16: =IFERROR('Daily Summary '!D17,"") -> 1558.122 | D16: =IFERROR('Daily Summary '!I17,"") -> 10.016667 | E16: =IFERROR('Daily Summary '!J17,"") -> 0 | F16: =IFERROR('Daily Summary '!E17,"") -> 16.173494 | G16: =IFERROR('Daily Summary '!F17,"") -> 1.0302222 | H16: =IFERROR('Daily Summary '!G17,"") -> 166.90064 | I16: =IFERROR('Daily Summary '!K17,"") -> 0.83472222 | J16: =IFERROR('Daily Summary '!L17,"") -> 0 | K16: =IFERROR('Daily Summary '!M17,"") -> 1 | L16: =IFERROR('Daily Summary '!N17,"") -> 0 | M16: =IFERROR('Daily Summary '!Z17,"") -> 150 | N16: =IFERROR('Daily Summary '!AC17,"") -> 250 | O16: =IFERROR('Daily Summary '!AB17,"") -> 0 | P16: =IFERROR('Daily Summary '!AF17,"") -> 0 | Q16: =IFERROR('Daily Summary '!AG17,"") -> 0
A17: ='Daily Summary '!B18 -> 46259 | B17: =IFERROR('Daily Summary '!C18,"") -> 0 | C17: =IFERROR('Daily Summary '!D18,"") -> 1558.122 | D17: =IFERROR('Daily Summary '!I18,"") -> 0.033333333 | E17: =IFERROR('Daily Summary '!J18,"") -> 0 | F17: =IFERROR('Daily Summary '!E18,"") -> 0 | G17: =IFERROR('Daily Summary '!F18,"") -> 0 | H17: =IFERROR('Daily Summary '!G18,"") -> 0 | I17: =IFERROR('Daily Summary '!K18,"") -> 0.0027777778 | J17: =IFERROR('Daily Summary '!L18,"") -> 0 | K17: =IFERROR('Daily Summary '!M18,"") -> 1 | L17: =IFERROR('Daily Summary '!N18,"") -> 0 | M17: =IFERROR('Daily Summary '!Z18,"") -> 0 | N17: =IFERROR('Daily Summary '!AC18,"") -> 0 | O17: =IFERROR('Daily Summary '!AB18,"") -> 0 | P17: =IFERROR('Daily Summary '!AF18,"") -> 0 | Q17: =IFERROR('Daily Summary '!AG18,"") -> 0
... A33: ='Daily Summary '!B34 -> 46275 | B33: =IFERROR('Daily Summary '!C34,"") -> 0 | C33: =IFERROR('Daily Summary '!D34,"") -> 2145.0891 | D33: =IFERROR('Daily Summary '!I34,"") -> 0 | E33: =IFERROR('Daily Summary '!J34,"") -> 22.333333 | F33: =IFERROR('Daily Summary '!E34,"") | G33: =IFERROR('Daily Summary '!F34,"") -> 0 | H33: =IFERROR('Daily Summary '!G34,"") -> 0 | I33: =IFERROR('Daily Summary '!K34,"") -> 0 | J33: =IFERROR('Daily Summary '!L34,"") -> 0.93055556 | K33: =IFERROR('Daily Summary '!M34,"") -> 1 | L33: =IFERROR('Daily Summary '!N34,"") -> 0.93055556 | M33: =IFERROR('Daily Summary '!Z34,"") -> 0 | N33: =IFERROR('Daily Summary '!AC34,"") -> 0 | O33: =IFERROR('Daily Summary '!AB34,"") -> 0 | P33: =IFERROR('Daily Summary '!AF34,"") -> 0 | Q33: =IFERROR('Daily Summary '!AG34,"") -> 0
A34: Dashboard metrics use recorded rows above.

Sheet Daily Summary 
H1: Daily summary Production PT Bulawan Daya Lestari
H2: Site Gunung Patung, Mopait, Bolaang Mongondow, Sulawesi Utara
B5: Date | C5: Feeding, ton | I5: Hours Run Crushing | J5: Hours Milling | K5: Availability, % | N5: Plant Usability | O5: Gold Rom ( Elution and Electrowinning ) | Z5: Consumption | AH5: Stockpile, Estimated | AJ5: Inventory PPA | AP5: SHE | AS5: Result per month
C6: Tpd | D6: Mtd | E6: tph | F6: Au Lab, gpt | G6: Au, gr | H6: Au, kg | K6: Crusher | L6: Mill | M6: CIP | O6: Carbon to Elution (t) | P6: Carbon Transit (t) | Q6: Elution | R6: Loaded Carbon (g/t) | S6: Barren Carbon (g/t) | T6: Au Recovery gr | U6: Au Recovery Elution (%) | V6: E/W | W6: Smelting | X6: Dore Transit | Y6: Hand Over | Z6: Sandios kg | AA6: Fuel Diesel | AB6: Carbon kg | AC6: Lime kg | AD6: NaOH, kg | AE6: HCL, Liter | AF6: Floculant, kg | AG6: Fuel, L | AH6: Ore Inventory, ton | AI6: Au Inventory, kg | AJ6: Cyanide, kg | AK6: Carbon kg | AL6: Lime kg | AM6: NaOH, kg | AN6: HCL, Liter | AO6: Floculant, kg | AP6: LTA Free Hours | AQ6: Spills, Liter | AS6: Tpm
B7: 46174 | C7: =Crushing!N6 -> 0 | D7: =C7 -> 0 | E7: =C7/I7 -> #DIV/0! | G7: =C7*F7 -> 0 | H7: =G7/1000 -> 0 | J7: 0 | L7: =J7/24 -> 0 | M7: 1 | N7: =IF(L7=100%,I7/24*100%,L7) -> 0 | T7: =(O7*R7)-(S7*O7) -> 0 | U7: =((R7-S7)/R7) -> #DIV/0! | Z7: ='Reagent Consumption'!O7 -> 0 | AA7: ='Fuel Consumption'!F4 -> 0 | AB7: ='Reagent Consumption'!Q7 -> 0 | AC7: ='Reagent Consumption'!P7 -> 0 | AD7: ='Reagent Consumption'!R7 -> 0 | AE7: ='Reagent Consumption'!S7 -> 0 | AF7: ='Reagent Consumption'!T7 -> 0 | AG7: ='Fuel Consumption'!F4 -> 0 | AS7: avarage tpd
B8: 46175 | C8: =Crushing!N8 -> 78.0435 | D8: =D7+C8 -> 78.0435 | E8: =C8/I8 -> 7.073429 | F8: 1.45 | G8: =C8*F8 -> 113.16308 | H8: =G8/1000 -> 0.11316308 | I8: ='Crushing Down Time Hours'!L7 -> 11.033333 | J8: 0 | L8: =J8/24 -> 0 | M8: 1 | N8: =IF(L8=100%,I8/24*100%,L8) -> 0 | T8: =(P8*R8)-(S8*P8) -> 0 | U8: =((R8-S8)/R8) -> #DIV/0! | Z8: ='Reagent Consumption'!O8 -> 0 | AA8: ='Fuel Consumption'!F5 -> 0 | AB8: ='Reagent Consumption'!Q8 -> 0 | AC8: ='Reagent Consumption'!P8 -> 0 | AD8: ='Reagent Consumption'!R8 -> 0 | AE8: ='Reagent Consumption'!S8 -> 0 | AF8: ='Reagent Consumption'!T8 -> 0 | AG8: ='Fuel Consumption'!F5 -> 0 | AS8: Percentage ore blend
B9: 46176 | C9: =Crushing!N10 -> 17.712 | D9: =D8+C9 -> 95.7555 | E9: =C9/I9 -> 1.6053172 | F9: 1.45 | G9: =F9*C9 -> 25.6824 | H9: =G9/1000 -> 0.0256824 | I9: ='Crushing Down Time Hours'!L8 -> 11.033333 | J9: 0 | L9: =J9/24 -> 0 | M9: 1 | N9: =IF(L9=100%,(I9/24),L9) -> 0 | T9: =(P9*R9)-(S9*P9) -> 0 | U9: =((R9-S9)/R9) -> #DIV/0! | Z9: ='Reagent Consumption'!O9 -> 0 | AA9: ='Fuel Consumption'!F6 -> 0 | AB9: ='Reagent Consumption'!Q9 -> 0 | AC9: ='Reagent Consumption'!P9 -> 0 | AD9: ='Reagent Consumption'!R9 -> 0 | AE9: ='Reagent Consumption'!S9 -> 0 | AF9: ='Reagent Consumption'!T9 -> 0 | AG9: ='Fuel Consumption'!F6 -> 0 | AS9: Ops Time Crusher
B10: 46177 | C10: =Crushing!N12 -> 157.9905 | D10: =D9+C10 -> 253.746 | E10: =C10/I10 -> 16.74811 | F10: 1.45 | G10: =F10*C10 -> 229.08622 | H10: =G10/1000 -> 0.22908622 | I10: ='Crushing Down Time Hours'!L9 -> 9.4333333 | J10: 0 | L10: =J10/24 -> 0 | M10: 1 | N10: =IF(L10=100%,I10/24*100%,L10) -> 0 | T10: =(P10*R10)-(S10*P10) -> 0 | U10: =((R10-S10)/R10) -> #DIV/0! | Z10: ='Reagent Consumption'!O10 -> 150 | AA10: ='Fuel Consumption'!F7 -> 0 | AB10: ='Reagent Consumption'!Q10 -> 0 | AC10: ='Reagent Consumption'!P10 -> 250 | AD10: ='Reagent Consumption'!R10 -> 0 | AE10: ='Reagent Consumption'!S10 -> 0 | AF10: ='Reagent Consumption'!T10 -> 0 | AG10: ='Fuel Consumption'!F7 -> 0 | AS10: Ops Time Ballmill
B11: 46252 | C11: =Crushing!N14 -> 37.9192 | D11: =D10+C11 -> 291.6652 | E11: =C11/I11 -> 18.648787 | F11: 0.77 | G11: =F11*C11 -> 29.197784 | H11: =G11/1000 -> 0.029197784 | I11: ='Crushing Down Time Hours'!L6 -> 2.0333333 | J11: 0 | K11: ='Crushing Down Time Hours'!M6 -> 0.16944444 | L11: =J11/24 -> 0 | M11: 1 | N11: =IF(L11=100%,I11/24*100%,L11) -> 0 | T11: =(P11*R11)-(S11*P11) -> 0 | U11: =((Q12-S11)/Q12) -> #DIV/0! | Z11: ='Reagent Consumption'!O11 -> 225 | AA11: ='Fuel Consumption'!F8 -> 0 | AB11: ='Reagent Consumption'!Q11 -> 1000 | AC11: ='Reagent Consumption'!P11 -> 1250 | AD11: ='Reagent Consumption'!R11 -> 0 | AE11: ='Reagent Consumption'!S11 -> 0 | AF11: ='Reagent Consumption'!T11 -> 25 | AG11: ='Fuel Consumption'!F8 -> 0 | AS11: Grinding Ball Consumption
B12: 46253 | C12: =Crushing!N16 -> 283.1708 | D12: =D11+C12 -> 574.836 | E12: =C12/I12 -> 25.665027 | F12: 1.021 | G12: =F12*C12 -> 289.11739 | H12: =G12/1000 -> 0.28911739 | I12: ='Crushing Down Time Hours'!L7 -> 11.033333 | J12: 0 | K12: ='Crushing Down Time Hours'!M7 -> 0.91944444 | L12: =J12/24 -> 0 | M12: 1 | N12: =IF(L12=100%,I12/24*100%,L12) -> 0 | T12: =(P12*R12)-(S12*P12) -> 0 | U12: =((Q13-S12)/Q13) -> #DIV/0! | Z12: ='Reagent Consumption'!O13 -> 275 | AA12: ='Fuel Consumption'!F9 -> 0 | AB12: ='Reagent Consumption'!Q13 -> 1000 | AC12: ='Reagent Consumption'!P13 -> 0 | AD12: ='Reagent Consumption'!R13 -> 0 | AE12: ='Reagent Consumption'!S13 -> 0 | AF12: ='Reagent Consumption'!T13 -> 25 | AG12: ='Fuel Consumption'!F9 -> 0 | AS12: Kwh
B13: 46254 | C13: =Crushing!N18 -> 337.1445 | D13: =D12+C13 -> 911.9805 | E13: =C13/I13 -> 33.658353 | F13: 0.604 | G13: =F13*C13 -> 203.63528 | H13: =G13/1000 -> 0.20363528 | I13: ='Crushing Down Time Hours'!L12 -> 10.016667 | J13: 0 | K13: ='Crushing Down Time Hours'!M8 -> 0.91944444 | L13: =J13/24 -> 0 | M13: 1 | N13: =IF(L13=100%,I13/24*100%,L13) -> 0 | T13: =(P13*R13)-(S13*P13) -> 0 | U13: =((Q14-S13)/Q14) -> #DIV/0! | Z13: ='Reagent Consumption'!O15 -> 100 | AA13: ='Fuel Consumption'!F10 -> 0 | AB13: ='Reagent Consumption'!Q15 -> 0 | AC13: ='Reagent Consumption'!P15 -> 0 | AD13: ='Reagent Consumption'!R15 -> 0 | AE13: ='Reagent Consumption'!S15 -> 0 | AF13: ='Reagent Consumption'!T15 -> 0 | AG13: ='Fuel Consumption'!F10 -> 0 | AS13: Flocculant Consumption
B14: 46255 | C14: =Crushing!N20 -> 287.1045 | D14: =D13+C14 -> 1199.085 | E14: =C14/I14 -> 30.435106 | F14: 0.442 | G14: =F14*C14 -> 126.90019 | H14: =G14/1000 -> 0.12690019 | I14: ='Crushing Down Time Hours'!L9 -> 9.4333333 | J14: 0 | K14: ='Crushing Down Time Hours'!M9 -> 0.78611111 | L14: =J14/24 -> 0 | M14: 1 | N14: =IF(L14=100%,I14/24*100%,L14) -> 0 | T14: =(P14*R14)-(S14*P14) -> 0 | U14: =((R14-S14)/R14) -> #DIV/0! | Z14: ='Reagent Consumption'!O16 -> 0 | AA14: ='Fuel Consumption'!F11 -> 0 | AB14: ='Reagent Consumption'!Q16 -> 0 | AC14: ='Reagent Consumption'!P16 -> 0 | AD14: ='Reagent Consumption'!R16 -> 0 | AE14: ='Reagent Consumption'!S16 -> 0 | AF14: ='Reagent Consumption'!T16 -> 0 | AG14: ='Fuel Consumption'!F11 -> 0 | AS14: Cyanide Consumption
B15: 46256 | C15: =Crushing!N22 -> 197.0325 | D15: =D14+C15 -> 1396.1175 | E15: =C15/I15 -> 21.852033 | F15: =AVERAGE('Rom File Inventory'!T93:T101) -> 0.62933333 | G15: =F15*C15 -> 123.99912 | H15: =G15/1000 -> 0.12399912 | I15: ='Crushing Down Time Hours'!L10 -> 9.0166667 | J15: 0 | K15: ='Crushing Down Time Hours'!M10 -> 0.75138889 | L15: =J15/24 -> 0 | M15: 1 | N15: =IF(L15=100%,I15/24*100%,L15) -> 0 | T15: =(P15*R15)-(S15*P15) -> 0 | U15: =((R15-S15)/R15) -> #DIV/0! | Z15: ='Reagent Consumption'!O17 -> 50 | AA15: ='Fuel Consumption'!F12 -> 0 | AB15: ='Reagent Consumption'!Q17 -> 0 | AC15: ='Reagent Consumption'!P17 -> 0 | AD15: ='Reagent Consumption'!R17 -> 0 | AE15: ='Reagent Consumption'!S17 -> 0 | AF15: ='Reagent Consumption'!T17 -> 0 | AG15: ='Fuel Consumption'!F12 -> 0 | AS15: Lime Consumption
B16: 46257 | C16: =Crushing!N24 -> 0 | D16: =D15+C16 -> 1396.1175 | E16: =C16/I16 -> 0 | G16: =F16*C16 -> 0 | H16: =G16/1000 -> 0 | I16: ='Crushing Down Time Hours'!L11 -> 0.033333333 | J16: 0 | K16: ='Crushing Down Time Hours'!M11 -> 0.0027777778 | L16: =J16/24 -> 0 | M16: 1 | N16: =IF(L16=100%,I16/24*100%,L16) -> 0 | T16: =(P16*R16)-(S16*P16) -> 0 | U16: =((R16-S16)/R16) -> #DIV/0! | Z16: ='Reagent Consumption'!O18 -> 175 | AA16: ='Fuel Consumption'!F13 -> 0 | AB16: ='Reagent Consumption'!Q18 -> 0 | AC16: ='Reagent Consumption'!P18 -> 500 | AD16: ='Reagent Consumption'!R18 -> 0 | AE16: ='Reagent Consumption'!S18 -> 0 | AF16: ='Reagent Consumption'!T18 -> 0 | AG16: ='Fuel Consumption'!F13 -> 0 | AS16: Carbon Consumption
B17: 46258 | C17: =Crushing!N26 -> 162.0045 | D17: =D16+C17 -> 1558.122 | E17: =C17/I17 -> 16.173494 | F17: =AVERAGE('Rom File Inventory'!T102:T110) -> 1.0302222 | G17: =F17*C17 -> 166.90064 | H17: =G17/1000 -> 0.16690064 | I17: ='Crushing Down Time Hours'!L12 -> 10.016667 | J17: 0 | K17: ='Crushing Down Time Hours'!M12 -> 0.83472222 | L17: =J17/24 -> 0 | M17: 1 | N17: =IF(L17=100%,I17/24*100%,L17) -> 0 | T17: =(P17*R17)-(S17*P17) -> 0 | U17: =((R17-S17)/R17) -> #DIV/0! | Z17: ='Reagent Consumption'!O19 -> 150 | AA17: ='Fuel Consumption'!F14 -> 0 | AB17: ='Reagent Consumption'!Q19 -> 0 | AC17: ='Reagent Consumption'!P19 -> 250 | AD17: ='Reagent Consumption'!R19 -> 0 | AE17: ='Reagent Consumption'!S19 -> 0 | AF17: ='Reagent Consumption'!T19 -> 0 | AG17: ='Fuel Consumption'!F14 -> 0
B18: 46259 | C18: =Crushing!N28 -> 0 | D18: =D17+C18 -> 1558.122 | E18: =C18/I18 -> 0 | G18: =F18*C18 -> 0 | H18: =G18/1000 -> 0 | I18: ='Crushing Down Time Hours'!L13 -> 0.033333333 | J18: 0 | K18: ='Crushing Down Time Hours'!M13 -> 0.0027777778 | L18: =J18/24 -> 0 | M18: 1 | N18: =IF(L18=100%,I18/24*100%,L18) -> 0 | T18: =(P18*R18)-(S18*P18) -> 0 | U18: =((R18-S18)/R18) -> #DIV/0! | Z18: ='Reagent Consumption'!O21 -> 0 | AA18: ='Fuel Consumption'!F15 -> 0 | AB18: ='Reagent Consumption'!Q21 -> 0 | AC18: ='Reagent Consumption'!P21 -> 0 | AD18: ='Reagent Consumption'!R21 -> 0 | AE18: ='Reagent Consumption'!S21 -> 0 | AF18: ='Reagent Consumption'!T21 -> 0 | AG18: ='Fuel Consumption'!F15 -> 0
B19: 46260 | C19: 0 | D19: =D18+C19 -> 1558.122 | E19: =C19/I19 -> 0 | G19: =F19*C19 -> 0 | H19: =G19/1000 -> 0 | I19: ='Crushing Down Time Hours'!L14 -> 0.033333333 | J19: 0 | K19: ='Crushing Down Time Hours'!M14 -> 0.0027777778 | L19: =J19/24 -> 0 | M19: ='Milling Down Time Hours'!N5 -> 0.93472222 | N19: =IF(L19=100%,I19/24*100%,L19) -> 0 | T19: =(P19*R19)-(S19*P19) -> 0 | U19: =((R19-S19)/R19) -> #DIV/0! | Z19: ='Reagent Consumption'!O22 -> 0 | AA19: ='Fuel Consumption'!F16 -> 0 | AB19: ='Reagent Consumption'!Q22 -> 0 | AC19: ='Reagent Consumption'!P22 -> 0 | AD19: ='Reagent Consumption'!R22 -> 0 | AE19: ='Reagent Consumption'!S22 -> 0 | AF19: ='Reagent Consumption'!T22 -> 0 | AG19: ='Fuel Consumption'!F16 -> 0
B20: 46261 | C20: =Crushing!N32 -> 124.9471 | D20: =D19+C20 -> 1683.0691 | E20: =C20/I20 -> 23.724133 | F20: =AVERAGE('Rom File Inventory'!T111:T117) -> 0.75114286 | G20: =F20*C20 -> 93.853122 | H20: =G20/1000 -> 0.093853122 | I20: ='Crushing Down Time Hours'!L15 -> 5.2666667 | J20: 0 | K20: ='Crushing Down Time Hours'!M15 -> 0.43888889 | L20: =J20/24 -> 0 | M20: ='Milling Down Time Hours'!N6 -> 0.95416667 | N20: =IF(L20=100%,I20/24*100%,L20) -> 0 | T20: =(P20*R20)-(S20*P20) -> 0 | U20: =((R20-S20)/R20) -> #DIV/0! | Z20: ='Reagent Consumption'!O23 -> 0 | AA20: ='Fuel Consumption'!F17 -> 0 | AB20: ='Reagent Consumption'!Q23 -> 0 | AC20: ='Reagent Consumption'!P23 -> 0 | AD20: ='Reagent Consumption'!R23 -> 0 | AE20: ='Reagent Consumption'!S23 -> 0 | AF20: ='Reagent Consumption'!T23 -> 0 | AG20: ='Fuel Consumption'!F17 -> 0
B21: 46262 | C21: =Crushing!N34 -> 167.765 | D21: =D20+C21 -> 1850.8341 | E21: =C21/I21 -> 20.927027 | F21: =AVERAGE('Rom File Inventory'!T118:T126) -> 0.66411111 | G21: =F21*C21 -> 111.4146 | H21: =G21/1000 -> 0.1114146 | I21: ='Crushing Down Time Hours'!L16 -> 8.0166667 | J21: 0 | K21: ='Crushing Down Time Hours'!M16 -> 0.66805556 | L21: =J21/24 -> 0 | M21: ='Milling Down Time Hours'!N7 -> 0.91666667 | N21: =IF(L21=100%,I21/24*100%,L21) -> 0 | T21: =(P21*R21)-(S21*P21) -> 0 | U21: =((R21-S21)/R21) -> #DIV/0! | Z21: ='Reagent Consumption'!O24 -> 0 | AA21: ='Fuel Consumption'!F18 -> 0 | AB21: ='Reagent Consumption'!Q24 -> 0 | AC21: ='Reagent Consumption'!P24 -> 0 | AD21: ='Reagent Consumption'!R24 -> 0 | AE21: ='Reagent Consumption'!S24 -> 0 | AF21: ='Reagent Consumption'!T24 -> 0 | AG21: ='Fuel Consumption'!F18 -> 0
B22: 46263 | C22: =Crushing!N36 -> 240.435 | D22: =D21+C22 -> 2091.2691 | E22: =C22/I22 -> 24.003494 | F22: =AVERAGE('Rom File Inventory'!T127:T137) -> 0.872 | G22: =F22*C22 -> 209.65932 | H22: =G22/1000 -> 0.20965932 | I22: ='Crushing Down Time Hours'!L17 -> 10.016667 | J22: 0 | K22: ='Crushing Down Time Hours'!M17 -> 0.83472222 | L22: =J22/24 -> 0 | M22: ='Milling Down Time Hours'!N8 -> 0.45902778 | N22: =IF(L22=100%,I22/24*100%,L22) -> 0 | T22: =(P22*R22)-(S22*P22) -> 0 | U22: =((R22-S22)/R22) -> #DIV/0! | Z22: ='Reagent Consumption'!O25 -> 0 | AA22: ='Fuel Consumption'!F19 -> 0 | AB22: ='Reagent Consumption'!Q25 -> 0 | AC22: ='Reagent Consumption'!P25 -> 0 | AD22: ='Reagent Consumption'!R25 -> 0 | AE22: ='Reagent Consumption'!S25 -> 0 | AF22: ='Reagent Consumption'!T25 -> 0 | AG22: ='Fuel Consumption'!F19 -> 0
B23: 46264 | C23: =Crushing!N38 -> 53.82 | D23: =D22+C23 -> 2145.0891 | E23: =C23/I23 -> 26.468852 | F23: =AVERAGE('Rom File Inventory'!T138:T141) -> 0.989 | G23: =F23*C23 -> 53.22798 | H23: =G23/1000 -> 0.05322798 | I23: ='Crushing Down Time Hours'!L18 -> 2.0333333 | J23: 0 | K23: ='Crushing Down Time Hours'!M18 -> 0.16944444 | L23: =J23/24 -> 0 | M23: ='Milling Down Time Hours'!N9 -> 0.0013888889 | N23: =IF(L23=100%,I23/24*100%,L23) -> 0 | T23: =(P23*R23)-(S23*P23) -> 0 | U23: =((R23-S23)/R23) -> #DIV/0! | Z23: ='Reagent Consumption'!O26 -> 0 | AA23: ='Fuel Consumption'!F20 -> 0 | AB23: ='Reagent Consumption'!Q26 -> 0 | AC23: ='Reagent Consumption'!P26 -> 0 | AD23: ='Reagent Consumption'!R26 -> 0 | AE23: ='Reagent Consumption'!S26 -> 0 | AF23: ='Reagent Consumption'!T26 -> 0 | AG23: ='Fuel Consumption'!F20 -> 0
B24: 46265 | C24: 0 | D24: =D23+C24 -> 2145.0891 | E24: =C24/I24 -> #DIV/0! | G24: =F24*C24 -> 0 | H24: =G24/1000 -> 0 | I24: ='Crushing Down Time Hours'!L19 -> 0 | J24: ='Milling Down Time Hours'!M5 -> 22.433333 | K24: ='Crushing Down Time Hours'!M24 -> 0 | L24: =J24/24 -> 0.93472222 | M24: ='Milling Down Time Hours'!N10 -> 0.45902778 | N24: =IF(L24=100%,I24/24*100%,L24) -> 0.93472222 | T24: =(P24*R24)-(S24*P24) -> 0 | U24: =((R24-S24)/R24) -> #DIV/0! | Z24: ='Reagent Consumption'!O27 -> 0 | AA24: ='Fuel Consumption'!F21 -> 0 | AB24: ='Reagent Consumption'!Q27 -> 0 | AC24: ='Reagent Consumption'!P27 -> 0 | AD24: ='Reagent Consumption'!R27 -> 0 | AE24: ='Reagent Consumption'!S27 -> 0 | AF24: ='Reagent Consumption'!T27 -> 0 | AG24: ='Fuel Consumption'!F21 -> 0
B25: 46266 | C25: 0 | D25: =D24+C25 -> 2145.0891 | E25: =C25/I25 -> #DIV/0! | G25: =F25*C25 -> 0 | H25: =G25/1000 -> 0 | I25: ='Crushing Down Time Hours'!L20 -> 0 | J25: ='Milling Down Time Hours'!M6 -> 22.9 | K25: ='Crushing Down Time Hours'!M25 -> 0 | L25: =J25/24 -> 0.95416667 | M25: ='Milling Down Time Hours'!N11 -> 0.90972222 | N25: =IF(L25=100%,I25/24*100%,L25) -> 0.95416667 | T25: =(P25*R25)-(S25*P25) -> 0 | U25: =((R25-S25)/R25) -> #DIV/0! | Z25: ='Reagent Consumption'!O28 -> 0 | AA25: ='Fuel Consumption'!F22 -> 0 | AB25: ='Reagent Consumption'!Q28 -> 0 | AC25: ='Reagent Consumption'!P28 -> 0 | AD25: ='Reagent Consumption'!R28 -> 0 | AE25: ='Reagent Consumption'!S28 -> 0 | AF25: ='Reagent Consumption'!T28 -> 0 | AG25: ='Fuel Consumption'!F22 -> 0
B26: 46267 | C26: =Crushing!N25 -> 0 | D26: =D25+C26 -> 2145.0891 | E26: =C26/I26 -> #DIV/0! | G26: =F26*C26 -> 0 | H26: =G26/1000 -> 0 | I26: ='Crushing Down Time Hours'!L21 -> 0 | J26: ='Milling Down Time Hours'!M7 -> 22 | K26: ='Crushing Down Time Hours'!M26 -> 0 | L26: =J26/24 -> 0.91666667 | M26: ='Milling Down Time Hours'!N12 -> 0.93541667 | N26: =IF(L26=100%,I26/24*100%,L26) -> 0.91666667 | T26: =(P26*R26)-(S26*P26) -> 0 | U26: =((R26-S26)/R26) -> #DIV/0! | Z26: ='Reagent Consumption'!O29 -> 0 | AA26: ='Fuel Consumption'!F23 -> 0 | AB26: ='Reagent Consumption'!Q29 -> 0 | AC26: ='Reagent Consumption'!P29 -> 0 | AD26: ='Reagent Consumption'!R29 -> 0 | AE26: ='Reagent Consumption'!S29 -> 0 | AF26: ='Reagent Consumption'!T29 -> 0 | AG26: ='Fuel Consumption'!F23 -> 0
B27: 46268 | C27: 0 | D27: =D26+C27 -> 2145.0891 | E27: =C27/I27 -> #DIV/0! | G27: =F27*C27 -> 0 | H27: =G27/1000 -> 0 | I27: ='Crushing Down Time Hours'!L22 -> 0 | J27: ='Milling Down Time Hours'!M8 -> 11.016667 | K27: ='Crushing Down Time Hours'!M27 -> 0 | L27: =J27/24 -> 0.45902778 | M27: ='Milling Down Time Hours'!N13 -> 0.98680556 | N27: =IF(L27=100%,I27/24*100%,L27) -> 0.45902778 | T27: =(P27*R27)-(S27*P27) -> 0 | U27: =((R27-S27)/R27) -> #DIV/0! | Z27: ='Reagent Consumption'!O30 -> 0 | AA27: ='Fuel Consumption'!F24 -> 0 | AB27: ='Reagent Consumption'!Q30 -> 0 | AC27: ='Reagent Consumption'!P30 -> 0 | AD27: ='Reagent Consumption'!R30 -> 0 | AE27: ='Reagent Consumption'!S30 -> 0 | AF27: ='Reagent Consumption'!T30 -> 0 | AG27: ='Fuel Consumption'!F24 -> 0
B28: 46269 | C28: =Crushing!N27 -> 0 | D28: =D27+C28 -> 2145.0891 | E28: =C28/I28 -> #DIV/0! | G28: =F28*C28 -> 0 | H28: =G28/1000 -> 0 | I28: ='Crushing Down Time Hours'!L23 -> 0 | J28: ='Milling Down Time Hours'!M9 -> 0.033333333 | K28: ='Crushing Down Time Hours'!M28 -> 0 | L28: =J28/24 -> 0.0013888889 | M28: ='Milling Down Time Hours'!N14 -> 0.94861111 | N28: =IF(L28=100%,I28/24*100%,L28) -> 0.0013888889 | T28: =(P28*R28)-(S28*P28) -> 0 | U28: =((R28-S28)/R28) -> #DIV/0! | Z28: ='Reagent Consumption'!O31 -> 0 | AA28: ='Fuel Consumption'!F25 -> 0 | AB28: ='Reagent Consumption'!Q31 -> 0 | AC28: ='Reagent Consumption'!P31 -> 0 | AD28: ='Reagent Consumption'!R31 -> 0 | AE28: ='Reagent Consumption'!S31 -> 0 | AF28: ='Reagent Consumption'!T31 -> 0 | AG28: ='Fuel Consumption'!F25 -> 0
B29: 46270 | C29: 0 | D29: =D28+C29 -> 2145.0891 | E29: =C29/I29 -> #DIV/0! | G29: =F29*C29 -> 0 | H29: =G29/1000 -> 0 | I29: ='Crushing Down Time Hours'!L24 -> 0 | J29: ='Milling Down Time Hours'!M10 -> 11.016667 | K29: ='Crushing Down Time Hours'!M29 -> 0 | L29: =J29/24 -> 0.45902778 | M29: ='Milling Down Time Hours'!N15 -> 0.93055556 | N29: =IF(L29=100%,I29/24*100%,L29) -> 0.45902778 | T29: =(P29*R29)-(S29*P29) -> 0 | U29: =((R29-S29)/R29) -> #DIV/0! | Z29: ='Reagent Consumption'!O32 -> 0 | AA29: ='Fuel Consumption'!F26 -> 0 | AB29: ='Reagent Consumption'!Q32 -> 0 | AC29: ='Reagent Consumption'!P32 -> 0 | AD29: ='Reagent Consumption'!R32 -> 0 | AE29: ='Reagent Consumption'!S32 -> 0 | AF29: ='Reagent Consumption'!T32 -> 0 | AG29: ='Fuel Consumption'!F26 -> 0
B30: 46271 | C30: =Crushing!N52 -> 0 | D30: =D29+C30 -> 2145.0891 | E30: =C30/I30 -> #DIV/0! | G30: =F30*C30 -> 0 | H30: =G30/1000 -> 0 | I30: ='Crushing Down Time Hours'!L25 -> 0 | J30: ='Milling Down Time Hours'!M11 -> 21.833333 | K30: ='Crushing Down Time Hours'!M30 -> 0 | L30: =J30/24 -> 0.90972222 | M30: ='Milling Down Time Hours'!N17 -> 1 | N30: =IF(L30=100%,I30/24*100%,L30) -> 0.90972222 | T30: =(P30*R30)-(S30*P30) -> 0 | U30: =((R30-S30)/R30) -> #DIV/0! | Z30: ='Reagent Consumption'!O33 -> 0 | AA30: ='Fuel Consumption'!F27 -> 0 | AB30: ='Reagent Consumption'!Q33 -> 0 | AC30: ='Reagent Consumption'!P33 -> 0 | AD30: ='Reagent Consumption'!R33 -> 0 | AE30: ='Reagent Consumption'!S33 -> 0 | AF30: ='Reagent Consumption'!T33 -> 0 | AG30: ='Fuel Consumption'!F27 -> 0
B31: 46272 | C31: =Crushing!N30 -> 0 | D31: =D30+C31 -> 2145.0891 | E31: =C31/I31 -> #DIV/0! | G31: =F31*C31 -> 0 | H31: =G31/1000 -> 0 | I31: ='Crushing Down Time Hours'!L26 -> 0 | J31: ='Milling Down Time Hours'!M12 -> 22.45 | K31: ='Crushing Down Time Hours'!M31 -> 0 | L31: =J31/24 -> 0.93541667 | M31: ='Milling Down Time Hours'!N18 -> 1 | N31: =IF(L31=100%,I31/24*100%,L31) -> 0.93541667 | T31: =(P31*R31)-(S31*P31) -> 0 | U31: =((R31-S31)/R31) -> #DIV/0! | Z31: ='Reagent Consumption'!O34 -> 0 | AA31: ='Fuel Consumption'!F28 -> 0 | AB31: ='Reagent Consumption'!Q34 -> 0 | AC31: ='Reagent Consumption'!P34 -> 0 | AD31: ='Reagent Consumption'!R34 -> 0 | AE31: ='Reagent Consumption'!S34 -> 0 | AF31: ='Reagent Consumption'!T34 -> 0 | AG31: ='Fuel Consumption'!F28 -> 0
B32: 46273 | C32: =Crushing!N31 -> 0 | D32: =D31+C32 -> 2145.0891 | E32: =C32/I32 -> #DIV/0! | G32: =F32*C32 -> 0 | H32: =G32/1000 -> 0 | I32: ='Crushing Down Time Hours'!L27 -> 0 | J32: ='Milling Down Time Hours'!M13 -> 23.683333 | K32: ='Crushing Down Time Hours'!M32 -> 0 | L32: =J32/24 -> 0.98680556 | M32: 1 | N32: =IF(L32=100%,I32/24*100%,L32) -> 0.98680556 | T32: =(P32*R32)-(S32*P32) -> 0 | U32: =((R32-S32)/R32) -> #DIV/0! | Z32: ='Reagent Consumption'!O35 -> 0 | AA32: ='Fuel Consumption'!F29 -> 0 | AB32: ='Reagent Consumption'!Q35 -> 0 | AC32: ='Reagent Consumption'!P35 -> 0 | AD32: ='Reagent Consumption'!R35 -> 0 | AE32: ='Reagent Consumption'!S35 -> 0 | AF32: ='Reagent Consumption'!T35 -> 0 | AG32: ='Fuel Consumption'!F29 -> 0
B33: 46274 | C33: =Crushing!N58 -> 0 | D33: =D32+C33 -> 2145.0891 | E33: =C33/I33 -> #DIV/0! | G33: =F33*C33 -> 0 | H33: =G33/1000 -> 0 | I33: ='Crushing Down Time Hours'!L28 -> 0 | J33: ='Milling Down Time Hours'!M14 -> 22.766667 | K33: ='Crushing Down Time Hours'!M33 -> 0 | L33: =J33/24 -> 0.94861111 | M33: 1 | N33: =IF(L33=100%,I33/24*100%,L33) -> 0.94861111 | T33: =(P33*R33)-(S33*P33) -> 0 | U33: =((R33-S33)/R33) -> #DIV/0! | Z33: ='Reagent Consumption'!O36 -> 0 | AA33: ='Fuel Consumption'!F30 -> 0 | AB33: ='Reagent Consumption'!Q36 -> 0 | AC33: ='Reagent Consumption'!P36 -> 0 | AD33: ='Reagent Consumption'!R36 -> 0 | AE33: ='Reagent Consumption'!S36 -> 0 | AF33: ='Reagent Consumption'!T36 -> 0 | AG33: ='Fuel Consumption'!F30 -> 0
B34: 46275 | C34: =Crushing!N33 -> 0 | D34: =D33+C34 -> 2145.0891 | E34: =C34/I34 -> #DIV/0! | G34: =F34*C34 -> 0 | H34: =G34/1000 -> 0 | I34: ='Crushing Down Time Hours'!L29 -> 0 | J34: ='Milling Down Time Hours'!M15 -> 22.333333 | K34: ='Crushing Down Time Hours'!M34 -> 0 | L34: =J34/24 -> 0.93055556 | M34: 1 | N34: =IF(L34=100%,I34/24*100%,L34) -> 0.93055556 | T34: =(P34*R34)-(S34*P34) -> 0 | U34: =((R34-S34)/R34) -> #DIV/0! | Z34: ='Reagent Consumption'!O37 -> 0 | AA34: ='Fuel Consumption'!F31 -> 0 | AB34: ='Reagent Consumption'!Q37 -> 0 | AC34: ='Reagent Consumption'!P37 -> 0 | AD34: ='Reagent Consumption'!R37 -> 0 | AE34: ='Reagent Consumption'!S37 -> 0 | AF34: ='Reagent Consumption'!T37 -> 0 | AG34: ='Fuel Consumption'!F31 -> 0
B35: 46276 | D35: =D34+C35 -> 2145.0891 | E35: =C35/I35 -> #DIV/0! | G35: =F35*C35 -> 0 | H35: =G35/1000 -> 0 | I35: ='Crushing Down Time Hours'!L30 -> 0 | J35: ='Milling Down Time Hours'!M17 -> 24 | K35: ='Crushing Down Time Hours'!M35 -> 0 | L35: =J35/24 -> 1 | M35: 1 | N35: =IF(L35=100%,I35/24*100%,L35) -> 0 | T35: =(P35*R35)-(S35*P35) -> 0 | U35: =((R35-S35)/R35) -> #DIV/0! | Z35: ='Reagent Consumption'!O38 -> 0 | AA35: ='Fuel Consumption'!F32 -> 0 | AB35: ='Reagent Consumption'!Q38 -> 0 | AC35: ='Reagent Consumption'!P38 -> 0 | AD35: ='Reagent Consumption'!R38 -> 0 | AE35: ='Reagent Consumption'!S38 -> 0 | AF35: ='Reagent Consumption'!T38 -> 0 | AG35: ='Fuel Consumption'!F32 -> 0
B36: 46277 | C36: =Crushing!N35 -> 0 | D36: =D35+C36 -> 2145.0891 | E36: =C36/I36 -> #DIV/0! | G36: =F36*C36 -> 0 | H36: =G36/1000 -> 0 | I36: ='Crushing Down Time Hours'!L31 -> 0 | J36: ='Milling Down Time Hours'!M18 -> 24 | K36: ='Crushing Down Time Hours'!M36 -> 0 | L36: =J36/24 -> 1 | M36: 1 | N36: =IF(L36=100%,I36/24*100%,L36) -> 0 | T36: =(P36*R36)-(S36*P36) -> 0 | U36: =((R36-S36)/R36) -> #DIV/0! | Z36: ='Reagent Consumption'!O39 -> 0 | AA36: ='Fuel Consumption'!F33 -> 0 | AB36: ='Reagent Consumption'!Q39 -> 0 | AC36: ='Reagent Consumption'!P39 -> 0 | AD36: ='Reagent Consumption'!R39 -> 0 | AE36: ='Reagent Consumption'!S39 -> 0 | AF36: ='Reagent Consumption'!T39 -> 0 | AG36: ='Fuel Consumption'!F33 -> 0
B37: 46278 | C37: =Crushing!N66 -> 0 | D37: =D36+C37 -> 2145.0891 | E37: =C37/I37 -> #DIV/0! | G37: =F37*C37 -> 0 | H37: =G37/1000 -> 0 | I37: ='Crushing Down Time Hours'!L32 -> 0 | J37: ='Milling Down Time Hours'!M19 -> 24 | K37: ='Crushing Down Time Hours'!M37 -> 0 | L37: =J37/24 -> 1 | M37: 1 | N37: =IF(L37=100%,I37/24*100%,L37) -> 0 | T37: =(P37*R37)-(S37*P37) -> 0 | U37: =((R37-S37)/R37) -> #DIV/0! | Z37: ='Reagent Consumption'!O40 -> 0 | AA37: ='Fuel Consumption'!F34 -> 0 | AB37: ='Reagent Consumption'!Q40 -> 0 | AC37: ='Reagent Consumption'!P40 -> 0 | AD37: ='Reagent Consumption'!R40 -> 0 | AE37: ='Reagent Consumption'!S40 -> 0 | AF37: ='Reagent Consumption'!T40 -> 0 | AG37: ='Fuel Consumption'!F34 -> 0
B38: 46279 | C38: =Crushing!N68 -> 0 | D38: =D37+C38 -> 2145.0891 | E38: =C38/I38 -> #DIV/0! | G38: =F38*C38 -> 0 | H38: =G38/1000 -> 0 | I38: ='Crushing Down Time Hours'!L33 -> 0 | J38: ='Milling Down Time Hours'!M20 -> 24 | K38: ='Crushing Down Time Hours'!M38 -> 0 | L38: =J38/24 -> 1 | M38: 2 | N38: =IF(L38=100%,I38/24*100%,L38) -> 0 | Z38: ='Reagent Consumption'!O41 -> 0 | AA38: ='Fuel Consumption'!F35 -> 0 | AB38: ='Reagent Consumption'!Q41 -> 0 | AC38: ='Reagent Consumption'!P41 -> 0 | AD38: ='Reagent Consumption'!R41 -> 0 | AE38: ='Reagent Consumption'!S41 -> 0 | AF38: ='Reagent Consumption'!T41 -> 0 | AG38: ='Fuel Consumption'!F35 -> 0
B39: 46280 | D39: =D38+C39 -> 2145.0891 | E39: =C39/I39 -> #DIV/0! | G39: =F39*C39 -> 0 | H39: =G39/1000 -> 0 | I39: ='Crushing Down Time Hours'!L34 -> 0 | J39: ='Milling Down Time Hours'!M21 -> 24 | K39: ='Crushing Down Time Hours'!M39 -> 0 | L39: =J39/24 -> 1 | M39: 3 | N39: =IF(L39=100%,I39/24*100%,L39) -> 0 | Z39: ='Reagent Consumption'!O42 -> 0 | AA39: ='Fuel Consumption'!F36 -> 0 | AB39: ='Reagent Consumption'!Q42 -> 0 | AC39: ='Reagent Consumption'!P42 -> 0 | AD39: ='Reagent Consumption'!R42 -> 0 | AE39: ='Reagent Consumption'!S42 -> 0 | AF39: ='Reagent Consumption'!T42 -> 0 | AG39: ='Fuel Consumption'!F36 -> 0
B40: 46281 | C40: =Crushing!N39 -> 0 | D40: =D39+C40 -> 2145.0891 | E40: =C40/I40 -> #DIV/0! | G40: =F40*C40 -> 0 | H40: =G40/1000 -> 0 | I40: ='Crushing Down Time Hours'!L35 -> 0 | J40: ='Milling Down Time Hours'!M22 -> 24 | K40: ='Crushing Down Time Hours'!M40 -> 0 | L40: =J40/24 -> 1 | M40: 4 | N40: =IF(L40=100%,I40/24*100%,L40) -> 0 | Z40: ='Reagent Consumption'!O43 -> 0 | AA40: ='Fuel Consumption'!F37 -> 0 | AB40: ='Reagent Consumption'!Q43 -> 0 | AC40: ='Reagent Consumption'!P43 -> 0 | AD40: ='Reagent Consumption'!R43 -> 0 | AE40: ='Reagent Consumption'!S43 -> 0 | AF40: ='Reagent Consumption'!T43 -> 0 | AG40: ='Fuel Consumption'!F37 -> 0
B41: 46282 | C41: =Crushing!N40 -> 0 | D41: =D40+C41 -> 2145.0891 | E41: =C41/I41 -> #DIV/0! | G41: =F41*C41 -> 0 | H41: =G41/1000 -> 0 | I41: ='Crushing Down Time Hours'!L36 -> 0 | J41: ='Milling Down Time Hours'!M23 -> 24 | K41: ='Crushing Down Time Hours'!M41 -> 0 | L41: =J41/24 -> 1 | M41: 5 | N41: =IF(L41=100%,I41/24*100%,L41) -> 0 | Z41: ='Reagent Consumption'!O44 -> 0 | AA41: ='Fuel Consumption'!F38 -> 0 | AB41: ='Reagent Consumption'!Q44 -> 0 | AC41: ='Reagent Consumption'!P44 -> 0 | AD41: ='Reagent Consumption'!R44 -> 0 | AE41: ='Reagent Consumption'!S44 -> 0 | AF41: ='Reagent Consumption'!T44 -> 0 | AG41: ='Fuel Consumption'!F38 -> 0
B42: 46283 | C42: =Crushing!N41 -> 0 | D42: =D41+C42 -> 2145.0891 | E42: =C42/I42 -> #DIV/0! | G42: =F42*C42 -> 0 | H42: =G42/1000 -> 0 | I42: ='Crushing Down Time Hours'!L37 -> 0 | J42: ='Milling Down Time Hours'!M24 -> 24 | K42: ='Crushing Down Time Hours'!M42 -> 0 | L42: =J42/24 -> 1 | M42: 6 | N42: =IF(L42=100%,I42/24*100%,L42) -> 0 | Z42: ='Reagent Consumption'!O45 -> 0 | AA42: ='Fuel Consumption'!F39 -> 0 | AB42: ='Reagent Consumption'!Q45 -> 0 | AC42: ='Reagent Consumption'!P45 -> 0 | AD42: ='Reagent Consumption'!R45 -> 0 | AE42: ='Reagent Consumption'!S45 -> 0 | AF42: ='Reagent Consumption'!T45 -> 0 | AG42: ='Fuel Consumption'!F39 -> 0
...

Sheet AAS lab Crushing Daily 
C3: Assay Lab Result | L3: Assay Lab Result
C4: No | D4: Id Sampel | E4: Date | F4: Au (g/t) | G4: Ag (g/t) | H4: Cu (g/t) | L4: No | M4: Id Sampel | N4: Date | O4: Au (g/t) | P4: Ag (g/t) | Q4: Cu (g/t)
C5: 1 | D5: SR COM 24/06/2026 1 | E5: 46197 | F5: 0.546 | L5: 51 | M5: Crusher 11:00 | N5: 46253 | O5: 0.673
C6: 2 | D6: SR COM 24/06/2026 2 | E6: 46197 | F6: 0.576 | L6: 52 | M6: Crusher 11:30 | N6: 46253 | O6: 0.662
C7: 3 | D7: SR COM 24/06/2026 3 | E7: 46197 | F7: 0.839 | L7: 53 | M7: Crusher 13:00 | N7: 46253 | O7: 0.555
C8: 4 | D8: SR COM 24/06/2026 4 | E8: 46197 | F8: 2.011 | L8: 54 | M8: Crusher 13:30 | N8: 46253 | O8: 0.813
C9: 5 | D9: SR COM 24/06/2026 5 | E9: 46197 | F9: 0.944 | L9: 55 | M9: Crusher 14:00 | N9: 46253 | O9: 1.147
C10: 6 | D10: SR COM 24/06/2026 6 | E10: 46197 | F10: 0.702 | L10: 56 | M10: Crusher 14:30 | N10: 46253 | O10: 1.941
C11: 7 | D11: SR COM 24/06/2026 7 | E11: 46197 | F11: 3.216 | L11: 57 | M11: Crusher 15:00 | N11: 46253 | O11: 0.489
C12: 8 | D12: SR COM 24/06/2026 8 | E12: 46197 | F12: 0.562 | L12: 58 | M12: Crusher 15:30 | N12: 46253 | O12: 0.556
C13: 9 | D13: SR COM 24/06/2026 9 | E13: 46197 | F13: 0.79 | L13: 59 | M13: Crusher 16:00 | N13: 46253 | O13: 3.032
C14: 10 | D14: SR COM 24/06/2026 10 | E14: 46197 | F14: 1.583 | L14: 60 | M14: Crusher 16:30 | N14: 46253 | O14: 0.632
C15: 11 | D15: Clay and Sandly 1 | E15: 46181 | F15: 1.963 | L15: 61 | M15: Crusher 17:00 | N15: 46253 | O15: 1.043
C16: 12 | D16: Clay and Sandly 2 | E16: 46181 | F16: 0.735 | L16: 62 | M16: Crusher 17:30 | N16: 46253 | O16: 1.59
... C54: 50 | D54: Crusher 10:30 | E54: 46253 | F54: 0.506 | L54: 100 | M54: Crusher 15:00 | N54: 46258 | O54: 0.326
L55: 101 | M55: Crusher 16:00 | N55: 46258 | O55: 0.24
L56: 102 | M56: Crusher 17:00 | N56: 46258 | O56: 1.077
L57: 103 | M57: Crusher 13:00 | N57: 46261 | O57: 0.253
L58: 104 | M58: Crusher 14:00 | N58: 46261 | O58: 0.732
L59: 105 | M59: Crusher 15:00 | N59: 46261 | O59: 0.454
L60: 106 | M60: Crusher 16:00 | N60: 46261 | O60: 0.616
L61: 107 | M61: Crusher 17:00 | N61: 46261 | O61: 0.242
L62: 108 | M62: Crusher 18:00 | N62: 46261 | O62: 2.098
L63: 109 | M63: Crusher 19:00 | N63: 46261 | O63: 0.863

Sheet Reagent Consumption
B1: Data Reagent Additional and Reagent Consumption Processing Plant | T1: =125+150 -> 275
B2: PT Bulawan Daya Lestari
B3: Metalurgi PT BDL, PIC DYAN RAMDHANI
A5: Data ragents consumption | D5: Leaching | G5: Goldroom | J5: Thickener Tank | L5: Crushing | U5: Gold Rom
A6: Date | B6: Shift | C6: PIC | D6: Sandios (kg) : | E6: Lime (kg) : | F6: Carbon (kg) : | G6: Sandios (kg) : | H6: NaOH (kg) : | I6: HCL (Jerigen) : | J6: Lime (kg) : | K6: Floculant (kg) : | L6: Cement (kg) | N6: Date | O6: Sandios (kg) : | P6: Lime (kg) : | Q6: Carbon (kg) : | R6: NaOH (kg) : | S6: HCL (Jerigen) : | T6: Floculant (kg) : | U6: Sandios (kg) : | V6: HCL (jerigen) | X6: Reagent Additional (kg)
A7: 46262 | B7: Day | C7: Hadi/Yan | N7: 46262 | O7: =SUMIF(A$7:A$40,N7,D$7:D$40)+SUMIF(A$7:A$40,N7,G$7:G$40) -> 0 | P7: =SUMIF(A$7:A$40,N7,E$7:E$40)+SUMIF(A$7:A$40,N7,J$7:J$40) -> 0 | Q7: =SUMIF(A$7:A$40,N7,F$7:F$40) -> 0 | R7: =SUMIF(A$7:A$53,N7,H$7:H$54) -> 0 | S7: =SUMIF(A$7:A$53,N7,I$7:I$53) -> 0 | T7: =SUMIF(A$7:A$40,N7,K$7:K$40) -> 0 | U7: =SUMIF(A$7:A$54,N7,G$7:G$54) -> 0 | V7: =SUMIF(A$7:A$54,N7,I$7:I$54) -> 0 | X7: Sandios (kg) | Y7: Lime (kg) | Z7: Carbon (kg) | AA7: Floculant (kg) | AB7: NaOH (kg) | AC7: Hcl (jerigen)
A8: 46263 | N8: 46263 | O8: =SUMIF(A$7:A$40,N8,D$7:D$40)+SUMIF(A$7:A$40,N8,G$7:G$40) -> 0 | P8: =SUMIF(A$7:A$40,N8,E$7:E$40)+SUMIF(A$7:A$40,N8,J$7:J$40) -> 0 | Q8: =SUMIF(A$7:A$40,N8,F$7:F$40) -> 0 | R8: =SUMIF(A$7:A$53,N8,H$7:H$54) -> 0 | S8: =SUMIF(A$7:A$53,N8,I$7:I$53) -> 0 | T8: =SUMIF(A$7:A$40,N8,K$7:K$40) -> 0 | U8: =SUMIF(A$7:A$54,N8,G$7:G$54) -> 0 | V8: =SUMIF(A$7:A$54,N8,I$7:I$54) -> 0 | X8: =O54+U54 -> 1125 | Y8: =P54 -> 2250 | Z8: =Q54 -> 2000 | AA8: =T54 -> 50 | AB8: =R54 -> 0 | AC8: =V54 -> 0
A9: 46264 | N9: 46264 | O9: =SUMIF(A$7:A$40,N9,D$7:D$40)+SUMIF(A$7:A$40,N9,G$7:G$40) -> 0 | P9: =SUMIF(A$7:A$40,N9,E$7:E$40)+SUMIF(A$7:A$40,N9,J$7:J$40) -> 0 | Q9: =SUMIF(A$7:A$40,N9,F$7:F$40) -> 0 | R9: =SUMIF(A$7:A$53,N9,H$7:H$54) -> 0 | S9: =SUMIF(A$7:A$53,N9,I$7:I$53) -> 0 | T9: =SUMIF(A$7:A$40,N9,K$7:K$40) -> 0 | U9: =SUMIF(A$7:A$54,N9,G$7:G$54) -> 0 | V9: =SUMIF(A$7:A$54,N9,I$7:I$54) -> 0 | AP9: =30/1.16 -> 25.862069
A10: 46265 | B10: Day | C10: Hadi/Yan | D10: 150 | E10: 250 | N10: 46265 | O10: =SUMIF(A$7:A$40,N10,D$7:D$40)+SUMIF(A$7:A$40,N10,G$7:G$40) -> 150 | P10: =SUMIF(A$7:A$40,N10,E$7:E$40)+SUMIF(A$7:A$40,N10,J$7:J$40) -> 250 | Q10: =SUMIF(A$7:A$40,N10,F$7:F$40) -> 0 | R10: =SUMIF(A$7:A$53,N10,H$7:H$54) -> 0 | S10: =SUMIF(A$7:A$53,N10,I$7:I$53) -> 0 | T10: =SUMIF(A$7:A$40,N10,K$7:K$40) -> 0 | U10: =SUMIF(A$7:A$54,N10,G$7:G$54) -> 0 | V10: =SUMIF(A$7:A$54,N10,I$7:I$54) -> 0 | X10: Reagent Consumption
A11: 46266 | B11: Day | C11: Yanli/Hadi | D11: 100 | E11: 1250 | F11: 1000 | K11: 25 | N11: 46266 | O11: =SUMIF(A$7:A$40,N11,D$7:D$40)+SUMIF(A$7:A$40,N11,G$7:G$40) -> 225 | P11: =SUMIF(A$7:A$40,N11,E$7:E$40)+SUMIF(A$7:A$40,N11,J$7:J$40) -> 1250 | Q11: =SUMIF(A$7:A$40,N11,F$7:F$40) -> 1000 | R11: =SUMIF(A$7:A$53,N11,H$7:H$54) -> 0 | S11: =SUMIF(A$7:A$53,N11,I$7:I$53) -> 0 | T11: =SUMIF(A$7:A$40,N11,K$7:K$40) -> 25 | U11: =SUMIF(A$7:A$54,N11,G$7:G$54) -> 0 | V11: =SUMIF(A$7:A$54,N11,I$7:I$54) -> 0 | X11: =X8/'Au Cal Leaching Tank'!K61 -> 1.1551942 | Y11: =P54/'Au Cal Leaching Tank'!K61 -> 2.3103884 | Z11: =Z8/'Au Cal Leaching Tank'!K61 -> 2.0536785 | AA11: =AA8/'Au Cal Leaching Tank'!K61 -> 0.051341963 | AB11: =AB8/'Au Cal Leaching Tank'!K61 -> 0 | AC11: =(AC8*25)/'Au Cal Leaching Tank'!K61 -> 0
A12: 46266 | B12: Night | C12: Kristo/Ulan | D12: 125
A13: 46267 | B13: Day | C13: Yanli/Hadi | D13: 150 | K13: 25 | N13: 46267 | O13: 275 | P13: =SUMIF(A$7:A$40,N13,E$7:E$40)+SUMIF(A$7:A$40,N13,J$7:J$40) -> 0 | Q13: =SUMIF(A$7:A$40,N13,F$7:F$40) -> 1000 | R13: =SUMIF(A$7:A$53,N13,H$7:H$54) -> 0 | S13: =SUMIF(A$7:A$53,N13,I$7:I$53) -> 0 | T13: =SUMIF(A$7:A$40,N13,K$7:K$40) -> 25 | U13: =SUMIF(A$7:A$54,N13,G$7:G$54) -> 0 | V13: =SUMIF(A$7:A$54,N13,I$7:I$54) -> 0 | X13: Sandios (kg/t) | Y13: Lime (kg/t) | Z13: Carbon (kg/t) | AA13: Floculant (kg/t) | AB13: NaOH (kg/t) | AC13: HCL (L/t)
A14: 46267 | B14: Night | C14: Kristo/Ulan | D14: 125 | F14: 1000
A15: 46268 | B15: Day | C15: Yanli/Hadi | D15: 100 | N15: 46268 | O15: =SUMIF(A$7:A$40,N15,D$7:D$40)+SUMIF(A$7:A$40,N15,G$7:G$40) -> 100 | P15: =SUMIF(A$7:A$40,N15,E$7:E$40)+SUMIF(A$7:A$40,N15,J$7:J$40) -> 0 | Q15: =SUMIF(A$7:A$40,N15,F$7:F$40) -> 0 | R15: =SUMIF(A$7:A$53,N15,H$7:H$54) -> 0 | S15: =SUMIF(A$7:A$53,N15,I$7:I$53) -> 0 | T15: =SUMIF(A$7:A$40,N15,K$7:K$40) -> 0 | U15: =SUMIF(A$7:A$54,N15,G$7:G$54) -> 0 | V15: =SUMIF(A$7:A$54,N15,I$7:I$54) -> 0
A16: 46269 | N16: 46269 | O16: =SUMIF(A$7:A$40,N16,D$7:D$40)+SUMIF(A$7:A$40,N16,G$7:G$40) -> 0 | P16: =SUMIF(A$7:A$40,N16,E$7:E$40)+SUMIF(A$7:A$40,N16,J$7:J$40) -> 0 | Q16: =SUMIF(A$7:A$40,N16,F$7:F$40) -> 0 | R16: =SUMIF(A$7:A$53,N16,H$7:H$54) -> 0 | S16: =SUMIF(A$7:A$53,N16,I$7:I$53) -> 0 | T16: =SUMIF(A$7:A$40,N16,K$7:K$40) -> 0 | U16: =SUMIF(A$7:A$54,N16,G$7:G$54) -> 0 | V16: =SUMIF(A$7:A$54,N16,I$7:I$54) -> 0
A17: 46270 | B17: Night | C17: Kristo/Ulan | D17: 50 | N17: 46270 | O17: =SUMIF(A$7:A$40,N17,D$7:D$40)+SUMIF(A$7:A$40,N17,G$7:G$40) -> 50 | P17: =SUMIF(A$7:A$40,N17,E$7:E$40)+SUMIF(A$7:A$40,N17,J$7:J$40) -> 0 | Q17: =SUMIF(A$7:A$40,N17,F$7:F$40) -> 0 | R17: =SUMIF(A$7:A$53,N17,H$7:H$54) -> 0 | S17: =SUMIF(A$7:A$53,N17,I$7:I$53) -> 0 | T17: =SUMIF(A$7:A$40,N17,K$7:K$40) -> 0 | U17: =SUMIF(A$7:A$54,N17,G$7:G$54) -> 0 | V17: =SUMIF(A$7:A$54,N17,I$7:I$54) -> 0
A18: 46271 | B18: Day | C18: Yanli/Hadi | D18: 175 | E18: 500 | N18: 46271 | O18: =SUMIF(A$7:A$40,N18,D$7:D$40)+SUMIF(A$7:A$40,N18,G$7:G$40) -> 175 | P18: =SUMIF(A$7:A$40,N18,E$7:E$40)+SUMIF(A$7:A$40,N18,J$7:J$40) -> 500 | Q18: =SUMIF(A$7:A$40,N18,F$7:F$40) -> 0 | R18: =SUMIF(A$7:A$53,N18,H$7:H$54) -> 0 | S18: =SUMIF(A$7:A$53,N18,I$7:I$53) -> 0 | T18: =SUMIF(A$7:A$40,N18,K$7:K$40) -> 0 | U18: =SUMIF(A$7:A$54,N18,G$7:G$54) -> 0 | V18: =SUMIF(A$7:A$54,N18,I$7:I$54) -> 0
A19: 46272 | B19: Day | C19: Ulan | D19: 150 | E19: 250 | N19: 46272 | O19: =SUMIF(A$7:A$40,N19,D$7:D$40)+SUMIF(A$7:A$40,N19,G$7:G$40) -> 150 | P19: =SUMIF(A$7:A$40,N19,E$7:E$40)+SUMIF(A$7:A$40,N19,J$7:J$40) -> 250 | Q19: =SUMIF(A$7:A$40,N19,F$7:F$40) -> 0 | R19: =SUMIF(A$7:A$53,N19,H$7:H$54) -> 0 | S19: =SUMIF(A$7:A$53,N19,I$7:I$53) -> 0 | T19: =SUMIF(A$7:A$40,N19,K$7:K$40) -> 0 | U19: =SUMIF(A$7:A$54,N19,G$7:G$54) -> 0 | V19: =SUMIF(A$7:A$54,N19,I$7:I$54) -> 0 | X19: hcl 1 file 35 kg/30 Liter
A20: 46272 | B20: Night
A21: 46273 | N21: 46273 | O21: =SUMIF(A$7:A$40,N21,D$7:D$40)+SUMIF(A$7:A$40,N21,G$7:G$40) -> 0 | P21: =SUMIF(A$7:A$40,N21,E$7:E$40)+SUMIF(A$7:A$40,N21,J$7:J$40) -> 0 | Q21: =SUMIF(A$7:A$40,N21,F$7:F$40) -> 0 | R21: =SUMIF(A$7:A$53,N21,H$7:H$54) -> 0 | S21: =SUMIF(A$7:A$53,N21,I$7:I$53) -> 0 | T21: =SUMIF(A$7:A$40,N21,K$7:K$40) -> 0 | U21: =SUMIF(A$7:A$54,N21,G$7:G$54) -> 0 | V21: =SUMIF(A$7:A$54,N21,I$7:I$54) -> 0 | X21: Sandios | Y21: Lime | Z21: Floculant | AA21: Carbon
A22: 46274 | N22: 46274 | O22: =SUMIF(A$7:A$40,N22,D$7:D$40)+SUMIF(A$7:A$40,N22,G$7:G$40) -> 0 | P22: =SUMIF(A$7:A$40,N22,E$7:E$40)+SUMIF(A$7:A$40,N22,J$7:J$40) -> 0 | Q22: =SUMIF(A$7:A$40,N22,F$7:F$40) -> 0 | R22: =SUMIF(A$7:A$53,N22,H$7:H$54) -> 0 | S22: =SUMIF(A$7:A$53,N22,I$7:I$53) -> 0 | T22: =SUMIF(A$7:A$40,N22,K$7:K$40) -> 0 | U22: =SUMIF(A$7:A$54,N22,G$7:G$54) -> 0 | V22: =SUMIF(A$7:A$54,N22,I$7:I$54) -> 0 | X22: 48000 | Y22: 2300 | Z22: 30000 | AA22: 44000
A23: 46275 | N23: 46275 | O23: =SUMIF(A$7:A$40,N23,D$7:D$40)+SUMIF(A$7:A$40,N23,G$7:G$40) -> 0 | P23: =SUMIF(A$7:A$40,N23,E$7:E$40)+SUMIF(A$7:A$40,N23,J$7:J$40) -> 0 | Q23: =SUMIF(A$7:A$40,N23,F$7:F$40) -> 0 | R23: =SUMIF(A$7:A$53,N23,H$7:H$54) -> 0 | S23: =SUMIF(A$7:A$53,N23,I$7:I$53) -> 0 | T23: =SUMIF(A$7:A$40,N23,K$7:K$40) -> 0 | U23: =SUMIF(A$7:A$54,N23,G$7:G$54) -> 0 | V23: =SUMIF(A$7:A$54,N23,I$7:I$54) -> 0
A24: 46276 | N24: 46276 | O24: =SUMIF(A$7:A$40,N24,D$7:D$40)+SUMIF(A$7:A$40,N24,G$7:G$40) -> 0 | P24: =SUMIF(A$7:A$40,N24,E$7:E$40)+SUMIF(A$7:A$40,N24,J$7:J$40) -> 0 | Q24: =SUMIF(A$7:A$40,N24,F$7:F$40) -> 0 | R24: =SUMIF(A$7:A$53,N24,H$7:H$54) -> 0 | S24: =SUMIF(A$7:A$53,N24,I$7:I$53) -> 0 | T24: =SUMIF(A$7:A$40,N24,K$7:K$40) -> 0 | U24: =SUMIF(A$7:A$54,N24,G$7:G$54) -> 0 | V24: =SUMIF(A$7:A$54,N24,I$7:I$54) -> 0 | X24: =X22*O54 -> 54000000 | Y24: =P54*Y22 -> 5175000 | Z24: =Z22*T54 -> 1500000 | AA24: =AA22*Q54 -> 88000000
A25: 46277 | N25: 46277 | O25: =SUMIF(A$7:A$40,N25,D$7:D$40)+SUMIF(A$7:A$40,N25,G$7:G$40) -> 0 | P25: =SUMIF(A$7:A$40,N25,E$7:E$40)+SUMIF(A$7:A$40,N25,J$7:J$40) -> 0 | Q25: =SUMIF(A$7:A$40,N25,F$7:F$40) -> 0 | R25: =SUMIF(A$7:A$53,N25,H$7:H$54) -> 0 | S25: =SUMIF(A$7:A$53,N25,I$7:I$53) -> 0 | T25: =SUMIF(A$7:A$40,N25,K$7:K$40) -> 0 | U25: =SUMIF(A$7:A$54,N25,G$7:G$54) -> 0 | V25: =SUMIF(A$7:A$54,N25,I$7:I$54) -> 0
A26: 46278 | N26: 46278 | O26: =SUMIF(A$7:A$40,N26,D$7:D$40)+SUMIF(A$7:A$40,N26,G$7:G$40) -> 0 | P26: =SUMIF(A$7:A$40,N26,E$7:E$40)+SUMIF(A$7:A$40,N26,J$7:J$40) -> 0 | Q26: =SUMIF(A$7:A$40,N26,F$7:F$40) -> 0 | R26: =SUMIF(A$7:A$53,N26,H$7:H$54) -> 0 | S26: =SUMIF(A$7:A$53,N26,I$7:I$53) -> 0 | T26: =SUMIF(A$7:A$40,N26,K$7:K$40) -> 0 | U26: =SUMIF(A$7:A$54,N26,G$7:G$54) -> 0 | V26: =SUMIF(A$7:A$54,N26,I$7:I$54) -> 0
A27: 46279 | N27: 46279 | O27: =SUMIF(A$7:A$40,N27,D$7:D$40)+SUMIF(A$7:A$40,N27,G$7:G$40) -> 0 | P27: =SUMIF(A$7:A$40,N27,E$7:E$40)+SUMIF(A$7:A$40,N27,J$7:J$40) -> 0 | Q27: =SUMIF(A$7:A$40,N27,F$7:F$40) -> 0 | R27: =SUMIF(A$7:A$53,N27,H$7:H$54) -> 0 | S27: =SUMIF(A$7:A$53,N27,I$7:I$53) -> 0 | T27: =SUMIF(A$7:A$40,N27,K$7:K$40) -> 0 | U27: =SUMIF(A$7:A$54,N27,G$7:G$54) -> 0 | V27: =SUMIF(A$7:A$54,N27,I$7:I$54) -> 0
A28: 46280 | N28: 46280 | O28: =SUMIF(A$7:A$40,N28,D$7:D$40)+SUMIF(A$7:A$40,N28,G$7:G$40) -> 0 | P28: =SUMIF(A$7:A$40,N28,E$7:E$40)+SUMIF(A$7:A$40,N28,J$7:J$40) -> 0 | Q28: =SUMIF(A$7:A$40,N28,F$7:F$40) -> 0 | R28: =SUMIF(A$7:A$53,N28,H$7:H$54) -> 0 | S28: =SUMIF(A$7:A$53,N28,I$7:I$53) -> 0 | T28: =SUMIF(A$7:A$40,N28,K$7:K$40) -> 0 | U28: =SUMIF(A$7:A$54,N28,G$7:G$54) -> 0 | V28: =SUMIF(A$7:A$54,N28,I$7:I$54) -> 0
A29: 46281 | N29: 46281 | O29: =SUMIF(A$7:A$40,N29,D$7:D$40)+SUMIF(A$7:A$40,N29,G$7:G$40) -> 0 | P29: =SUMIF(A$7:A$40,N29,E$7:E$40)+SUMIF(A$7:A$40,N29,J$7:J$40) -> 0 | Q29: =SUMIF(A$7:A$40,N29,F$7:F$40) -> 0 | R29: =SUMIF(A$7:A$53,N29,H$7:H$54) -> 0 | S29: =SUMIF(A$7:A$53,N29,I$7:I$53) -> 0 | T29: =SUMIF(A$7:A$40,N29,K$7:K$40) -> 0 | U29: =SUMIF(A$7:A$54,N29,G$7:G$54) -> 0 | V29: =SUMIF(A$7:A$54,N29,I$7:I$54) -> 0
A30: 46282 | N30: 46282 | O30: =SUMIF(A$7:A$40,N30,D$7:D$40)+SUMIF(A$7:A$40,N30,G$7:G$40) -> 0 | P30: =SUMIF(A$7:A$40,N30,E$7:E$40)+SUMIF(A$7:A$40,N30,J$7:J$40) -> 0 | Q30: =SUMIF(A$7:A$40,N30,F$7:F$40) -> 0 | R30: =SUMIF(A$7:A$53,N30,H$7:H$54) -> 0 | S30: =SUMIF(A$7:A$53,N30,I$7:I$53) -> 0 | T30: =SUMIF(A$7:A$40,N30,K$7:K$40) -> 0 | U30: =SUMIF(A$7:A$54,N30,G$7:G$54) -> 0 | V30: =SUMIF(A$7:A$54,N30,I$7:I$54) -> 0
A31: 46283 | N31: 46283 | O31: =SUMIF(A$7:A$40,N31,D$7:D$40)+SUMIF(A$7:A$40,N31,G$7:G$40) -> 0 | P31: =SUMIF(A$7:A$40,N31,E$7:E$40)+SUMIF(A$7:A$40,N31,J$7:J$40) -> 0 | Q31: =SUMIF(A$7:A$40,N31,F$7:F$40) -> 0 | R31: =SUMIF(A$7:A$53,N31,H$7:H$54) -> 0 | S31: =SUMIF(A$7:A$53,N31,I$7:I$53) -> 0 | T31: =SUMIF(A$7:A$40,N31,K$7:K$40) -> 0 | U31: =SUMIF(A$7:A$54,N31,G$7:G$54) -> 0 | V31: =SUMIF(A$7:A$54,N31,I$7:I$54) -> 0
