Workbook

Sheet Closure Summary
A2: Rev.2X-A36 Closure Summary
A3: Current gate: actual supplier properties and guaranteed numerical fits. Detailed CAD remains blocked until A36R1 and A37.
A5: Project assembly | B5: Full Integration Assembly Rev.2U-A8.SLDASM
A6: Configuration | B6: Default, 7/7 resolved
A7: Selected architecture | B7: D6 round + D6 diamond/relieved pull dowel, PCD58
A8: Current overall result | B8: =IF(COUNTIF('Supplier Inputs'!D68:F68,"PASS")>0,"PASS candidate available",IF(COUNTIF('Supplier Inputs'!D68:F68,"FAIL")>0,"Candidate failed; revise or reject","HOLD - enter supplier evidence")) -> HOLD - enter supplier evidence
A11: Gate | B11: Acceptance basis | C11: Supplier A | D11: Supplier B | E11: Supplier C
A12: Supplier | B12: Name entered on input sheet | C12: =IF('Supplier Inputs'!D6="","Supplier A",'Supplier Inputs'!D6) -> Supplier A | D12: =IF('Supplier Inputs'!E6="","Supplier B",'Supplier Inputs'!E6) -> Supplier B | E12: =IF('Supplier Inputs'!F6="","Supplier C",'Supplier Inputs'!F6) -> Supplier C
A13: Insert property | B13: Certified Sy >= 379.310 MPa | C13: ='Supplier Inputs'!D15 -> HOLD | D13: ='Supplier Inputs'!E15 -> HOLD | E13: ='Supplier Inputs'!F15 -> HOLD
A14: Pin tensile property | B14: Certified Sy >= 1,046.259 MPa | C14: ='Supplier Inputs'!D24 -> HOLD | D14: ='Supplier Inputs'!E24 -> HOLD | E14: ='Supplier Inputs'!F24 -> HOLD
A15: Pin shear property | B15: Available shear yield >= 603.691 MPa | C15: ='Supplier Inputs'!D25 -> HOLD | D15: ='Supplier Inputs'!E25 -> HOLD | E15: ='Supplier Inputs'!F25 -> HOLD
A16: Supplier-property gate | B16: All property checks PASS | C16: ='Supplier Inputs'!D26 -> HOLD | D16: ='Supplier Inputs'!E26 -> HOLD | E16: ='Supplier Inputs'!F26 -> HOLD
A17: Retention fit | B17: Authorized positive interference band | C17: ='Supplier Inputs'!D37 -> HOLD | D17: ='Supplier Inputs'!E37 -> HOLD | E17: ='Supplier Inputs'!F37 -> HOLD
A18: Round working fit | B18: Guaranteed clearance 0.000 to 0.050 mm | C18: ='Supplier Inputs'!D46 -> HOLD | D18: ='Supplier Inputs'!E46 -> HOLD | E18: ='Supplier Inputs'!F46 -> HOLD
A19: Diamond tangential fit | B19: Guaranteed clearance 0.000 to 0.050 mm | C19: ='Supplier Inputs'!D58 -> HOLD | D19: ='Supplier Inputs'!E58 -> HOLD | E19: ='Supplier Inputs'!F58 -> HOLD
A20: Diamond radial relief | B20: >= 0.100 mm | C20: ='Supplier Inputs'!D59 -> HOLD | D20: ='Supplier Inputs'!E59 -> HOLD | E20: ='Supplier Inputs'!F59 -> HOLD
A21: Position | B21: Worst pin-axis error <= 0.050 mm | C21: ='Supplier Inputs'!D63 -> HOLD | D21: ='Supplier Inputs'!E63 -> HOLD | E21: ='Supplier Inputs'!F63 -> HOLD
A22: Pull service | B22: Controlled feature and tool OD <= 12 mm | C22: ='Supplier Inputs'!D66 -> HOLD | D22: ='Supplier Inputs'!E66 -> HOLD | E22: ='Supplier Inputs'!F66 -> HOLD
A23: Numerical-fit gate | B23: All fit checks PASS | C23: ='Supplier Inputs'!D67 -> HOLD | D23: ='Supplier Inputs'!E67 -> HOLD | E23: ='Supplier Inputs'!F67 -> HOLD
A24: A36 closure | B24: Property and numerical-fit gates PASS | C24: ='Supplier Inputs'!D68 -> HOLD | D24: ='Supplier Inputs'!E68 -> HOLD | E24: ='Supplier Inputs'!F68 -> HOLD
A25: Mechanical release | B25: A36 plus corrosion, wear and approvals | C25: ='Supplier Inputs'!D77 -> HOLD | D25: ='Supplier Inputs'!E77 -> HOLD | E25: ='Supplier Inputs'!F77 -> HOLD
A26: Next action | B26: Action generated from candidate status | C26: ='Supplier Inputs'!D78 -> Obtain missing certificate and guaranteed drawing inputs | D26: ='Supplier Inputs'!E78 -> Obtain missing certificate and guaranteed drawing inputs | E26: ='Supplier Inputs'!F78 -> Obtain missing certificate and guaranteed drawing inputs
A29: Locked limits | B29: Value | C29: Unit | D29: Notes
A30: Insert certified yield floor | B30: 379.31 | C30: MPa | D30: A35 environmental-debited requirement
A31: Pin tensile yield floor | B31: 1046.259 | C31: MPa | D31: Equivalent to the required shear floor
A32: Pin shear-yield floor | B32: 603.691 | C32: MPa | D32: No equal-load sharing credited
A34: Working clearance ceiling | B34: 0.05 | C34: mm | D34: Round and diamond tangential fits
A35: Diamond radial-relief minimum | B35: 0.1 | C35: mm | D35: Guaranteed minimum
A36: Pin-axis position-error ceiling | B36: 0.05 | C36: mm | D36: Worst one-sided linear error at PCD58
A37: Individual pull-tool OD ceiling | B37: 12 | C37: mm | D37: Combined D70 envelope retains 53 mm radial gap
A40: Release rule
A41: A36 HOLD | B41: Collect certified supplier properties, guaranteed dimensions and authorized interference limits. Do not create detailed CAD.
A42: A36 PASS | B42: Prepare A36R1 report, then proceed to A37 controlled drawing-input release. Galvanic and wear evidence remains mandatory.

Sheet Supplier Inputs
A2: Rev.2X-A36 Supplier Data and Fit Closure
A3: Source: Rev.2X-A35 and Rev.2X-A36 reports dated 2026-09-13. Enter guaranteed drawing limits and certified minimum properties only.
A5: Field | B5: Unit | C5: Requirement / acceptance | D5: Supplier A | E5: Supplier B | F5: Supplier C
A6: Supplier name | B6: text | C6: Required
A7: Quote or drawing reference | B7: text | C7: Required
A8: Offer date | B8: date | C8: Required
A9: Supplier contact | B9: text | C9: Required
A10: INSERT MATERIAL | C10: High-strength nickel-aluminum bronze family
A11: Insert grade and governing specification | B11: text | C11: Exact grade and material specification
A12: Insert heat or temper condition | B12: text | C12: Exact supplied condition
A13: Insert material certificate ID | B13: text | C13: Heat-lot traceable certificate
A14: Insert certified minimum yield strength | B14: MPa | C14: >= 379.310
A15: Insert property status | B15: status | C15: Certified minimum Sy >= 379.310 MPa | D15: =IF(OR(D6="",D11="",D12="",D13="",D14=""),"HOLD",IF(D14>=379.31,"PASS","FAIL")) -> HOLD | E15: =IF(OR(E6="",E11="",E12="",E13="",E14=""),"HOLD",IF(E14>=379.31,"PASS","FAIL")) -> HOLD | F15: =IF(OR(F6="",F11="",F12="",F13="",F14=""),"HOLD",IF(F14>=379.31,"PASS","FAIL")) -> HOLD
A17: PIN MATERIAL | C17: Nickel-base 718-type family; PH stainless remains reserve
A18: Pin grade and governing specification | B18: text | C18: Exact grade and material specification
A19: Pin heat-treatment condition | B19: text | C19: Exact supplied condition
A20: Pin material certificate ID | B20: text | C20: Heat-lot traceable certificate
A21: Pin certified minimum tensile yield strength | B21: MPa | C21: >= 1,046.259
A22: Pin direct certified shear yield | B22: MPa | C22: Optional; leave blank if unavailable
A23: Pin available shear yield | B23: MPa | C23: Direct value, otherwise 0.577 x tensile Sy | D23: =IF(D22<>"",D22,IF(D21<>"",0.577*D21,"")) | E23: =IF(E22<>"",E22,IF(E21<>"",0.577*E21,"")) | F23: =IF(F22<>"",F22,IF(F21<>"",0.577*F21,""))
A24: Pin tensile property status | B24: status | C24: Certified minimum tensile Sy >= 1,046.259 MPa | D24: =IF(OR(D6="",D18="",D19="",D20="",D21=""),"HOLD",IF(D21>=1046.259,"PASS","FAIL")) -> HOLD | E24: =IF(OR(E6="",E18="",E19="",E20="",E21=""),"HOLD",IF(E21>=1046.259,"PASS","FAIL")) -> HOLD | F24: =IF(OR(F6="",F18="",F19="",F20="",F21=""),"HOLD",IF(F21>=1046.259,"PASS","FAIL")) -> HOLD
A25: Pin shear property status | B25: status | C25: Available shear yield >= 603.691 MPa | D25: =IF(D23="","HOLD",IF(D23>=603.691,"PASS","FAIL")) -> HOLD | E25: =IF(E23="","HOLD",IF(E23>=603.691,"PASS","FAIL")) -> HOLD | F25: =IF(F23="","HOLD",IF(F23>=603.691,"PASS","FAIL")) -> HOLD
A26: Supplier-property gate | B26: status | C26: Insert, pin tensile and pin shear all PASS | D26: =IF(OR(D15="HOLD",D24="HOLD",D25="HOLD"),"HOLD",IF(AND(D15="PASS",D24="PASS",D25="PASS"),"PASS","FAIL")) -> HOLD | E26: =IF(OR(E15="HOLD",E24="HOLD",E25="HOLD"),"HOLD",IF(AND(E15="PASS",E24="PASS",E25="PASS"),"PASS","FAIL")) -> HOLD | F26: =IF(OR(F15="HOLD",F24="HOLD",F25="HOLD"),"HOLD",IF(AND(F15="PASS",F24="PASS",F25="PASS"),"PASS","FAIL")) -> HOLD
A28: ADAPTER BLIND-SEAT RETENTION FIT | C28: D6 shank retained in adapter blind seat
A29: Retention shank minimum diameter | B29: mm | C29: Guaranteed supplier limit
A30: Retention shank maximum diameter | B30: mm | C30: Guaranteed supplier limit
A31: Adapter blind-bore minimum diameter | B31: mm | C31: Manufacturing drawing limit
A32: Adapter blind-bore maximum diameter | B32: mm | C32: Manufacturing drawing limit
A33: Authorized minimum interference | B33: mm | C33: Must be > 0 and approved after local-stress review
A34: Authorized maximum interference | B34: mm | C34: Supplier and design authorization required
A35: Calculated minimum interference | B35: mm | C35: Shank min - bore max | D35: =IF(COUNT(D29:D34)<6,"",D29-D32) | E35: =IF(COUNT(E29:E34)<6,"",E29-E32) | F35: =IF(COUNT(F29:F34)<6,"",F29-F32)
A36: Calculated maximum interference | B36: mm | C36: Shank max - bore min | D36: =IF(COUNT(D29:D34)<6,"",D30-D31) | E36: =IF(COUNT(E29:E34)<6,"",E30-E31) | F36: =IF(COUNT(F29:F34)<6,"",F30-F31)
A37: Retention-fit status | B37: status | C37: Calculated range within authorized interference range | D37: =IF(COUNT(D29:D34)<6,"HOLD",IF(AND(D29<=D30,D31<=D32,D33<=D34,D35>0,D35>=D33,D36<=D34),"PASS","FAIL")) -> HOLD | E37: =IF(COUNT(E29:E34)<6,"HOLD",IF(AND(E29<=E30,E31<=E32,E33<=E34,E35>0,E35>=E33,E36<=E34),"PASS","FAIL")) -> HOLD | F37: =IF(COUNT(F29:F34)<6,"HOLD",IF(AND(F29<=F30,F31<=F32,F33<=F34,F35>0,F35>=F33,F36<=F34),"PASS","FAIL")) -> HOLD
A39: ROUND-PIN WORKING FIT | C39: Primary radial and tangential location in D70 insert flange
A40: Round working-pin minimum diameter | B40: mm | C40: Guaranteed supplier limit
A41: Round working-pin maximum diameter | B41: mm | C41: Guaranteed supplier limit
A42: Round flange-bore minimum diameter | B42: mm | C42: Manufacturing drawing limit
A43: Round flange-bore maximum diameter | B43: mm | C43: Manufacturing drawing limit
A44: Calculated minimum round clearance | B44: mm | C44: Bore min - pin max | D44: =IF(COUNT(D40:D43)<4,"",D42-D41) | E44: =IF(COUNT(E40:E43)<4,"",E42-E41) | F44: =IF(COUNT(F40:F43)<4,"",F42-F41)
A45: Calculated maximum round clearance | B45: mm | C45: Bore max - pin min | D45: =IF(COUNT(D40:D43)<4,"",D43-D40) | E45: =IF(COUNT(E40:E43)<4,"",E43-E40) | F45: =IF(COUNT(F40:F43)<4,"",F43-F40)
...
