Workbook

Sheet AAS lab Crushing Daily 
C3: Assay Lab Result | L3: Assay Lab Result
C4: No | D4: Id Sampel | E4: Date | F4: Au (g/t) | G4: Ag (g/t) | H4: Cu (g/t) | L4: No | M4: Id Sampel | N4: Date | O4: Au (g/t) | P4: Ag (g/t) | Q4: Cu (g/t)
C5: 1 | D5: SR COM 24/06/2026 1 | E5: 46197 | F5: 0.546 | L5: 51 | M5: Crusher 11:00 | N5: 46253 | O5: 0.673
C6: 2 | D6: SR COM 24/06/2026 2 | E6: 46197 | F6: 0.576 | L6: 52 | M6: Crusher 11:30 | N6: 46253 | O6: 0.662
C7: 3 | D7: SR COM 24/06/2026 3 | E7: 46197 | F7: 0.839 | L7: 53 | M7: Crusher 13:00 | N7: 46253 | O7: 0.555
C8: 4 | D8: SR COM 24/06/2026 4 | E8: 46197 | F8: 2.011 | L8: 54 | M8: Crusher 13:30 | N8: 46253 | O8: 0.813
C9: 5 | D9: SR COM 24/06/2026 5 | E9: 46197 | F9: 0.944 | L9: 55 | M9: Crusher 14:00 | N9: 46253 | O9: 1.147
C10: 6 | D10: SR COM 24/06/2026 6 | E10: 46197 | F10: 0.702 | L10: 56 | M10: Crusher 14:30 | N10: 46253 | O10: 1.941
C11: 7 | D11: SR COM 24/06/2026 7 | E11: 46197 | F11: 3.216 | L11: 57 | M11: Crusher 15:00 | N11: 46253 | O11: 0.489
C12: 8 | D12: SR COM 24/06/2026 8 | E12: 46197 | F12: 0.562 | L12: 58 | M12: Crusher 15:30 | N12: 46253 | O12: 0.556
C13: 9 | D13: SR COM 24/06/2026 9 | E13: 46197 | F13: 0.79 | L13: 59 | M13: Crusher 16:00 | N13: 46253 | O13: 3.032
C14: 10 | D14: SR COM 24/06/2026 10 | E14: 46197 | F14: 1.583 | L14: 60 | M14: Crusher 16:30 | N14: 46253 | O14: 0.632
C15: 11 | D15: Clay and Sandly 1 | E15: 46181 | F15: 1.963 | L15: 61 | M15: Crusher 17:00 | N15: 46253 | O15: 1.043
C16: 12 | D16: Clay and Sandly 2 | E16: 46181 | F16: 0.735 | L16: 62 | M16: Crusher 17:30 | N16: 46253 | O16: 1.59
... C54: 50 | D54: Crusher 10:30 | E54: 46253 | F54: 0.506 | L54: 100 | M54: Crusher 15:00 | N54: 46258 | O54: 0.326
L55: 101 | M55: Crusher 16:00 | N55: 46258 | O55: 0.24
L56: 102 | M56: Crusher 17:00 | N56: 46258 | O56: 1.077
L57: 103 | M57: Crusher 13:00 | N57: 46261 | O57: 0.253
L58: 104 | M58: Crusher 14:00 | N58: 46261 | O58: 0.732
L59: 105 | M59: Crusher 15:00 | N59: 46261 | O59: 0.454
L60: 106 | M60: Crusher 16:00 | N60: 46261 | O60: 0.616
L61: 107 | M61: Crusher 17:00 | N61: 46261 | O61: 0.242
L62: 108 | M62: Crusher 18:00 | N62: 46261 | O62: 2.098
L63: 109 | M63: Crusher 19:00 | N63: 46261 | O63: 0.863

Sheet Daily Summary 
H1: Daily summary Production PT Bulawan Daya Lestari
H2: Site Gunung Patung, Mopait, Bolaang Mongondow, Sulawesi Utara
B5: Date | C5: Feeding, ton | I5: Hours Run Crushing | J5: Hours Milling | K5: Availability, % | N5: Plant Usability | O5: Gold Rom ( Elution and Electrowinning ) | Z5: Consumption | AH5: Stockpile, Estimated | AJ5: Inventory PPA | AP5: SHE | AS5: Result per month
C6: Tpd | D6: Mtd | E6: tph | F6: Au Lab, gpt | G6: Au, gr | H6: Au, kg | K6: Crusher | L6: Mill | M6: CIP | O6: Carbon to Elution (t) | P6: Carbon Transit (t) | Q6: Elution | R6: Loaded Carbon (g/t) | S6: Barren Carbon (g/t) | T6: Au Recovery gr | U6: Au Recovery Elution (%) | V6: E/W | W6: Smelting | X6: Dore Transit | Y6: Hand Over | Z6: Sandios kg | AA6: Fuel Diesel | AB6: Carbon kg | AC6: Lime kg | AD6: NaOH, kg | AE6: HCL, Liter | AF6: Floculant, kg | AG6: Fuel, L | AH6: Ore Inventory, ton | AI6: Au Inventory, kg | AJ6: Cyanide, kg | AK6: Carbon kg | AL6: Lime kg | AM6: NaOH, kg | AN6: HCL, Liter | AO6: Floculant, kg | AP6: LTA Free Hours | AQ6: Spills, Liter | AS6: Tpm
B7: 46174 | C7: =Crushing!N6 -> 0 | D7: =C7 -> 0 | E7: =IFERROR(C7/I7,"") | G7: =C7*F7 -> 0 | H7: =G7/1000 -> 0 | J7: 0 | L7: 0 | M7: 1 | N7: =IF(L7=100%,I7/24*100%,L7) -> 0 | T7: =(O7*R7)-(S7*O7) -> 0 | U7: =IFERROR((R7-S7)/R7,"") | Z7: ='Reagent Consumption'!O7 -> 0 | AA7: ='Fuel Consumption'!D4 -> 320 | AB7: ='Reagent Consumption'!Q7 -> 0 | AC7: ='Reagent Consumption'!P7 -> 0 | AD7: ='Reagent Consumption'!R7 -> 0 | AE7: ='Reagent Consumption'!S7 -> 0 | AF7: ='Reagent Consumption'!T7 -> 0 | AG7: ='Fuel Consumption'!D4 -> 320 | AS7: avarage tpd
B8: 46175 | C8: =Crushing!N8 -> 78.0435 | D8: =D7+C8 -> 78.0435 | E8: =C8/I8 -> 7.073429 | F8: 1.45 | G8: =C8*F8 -> 113.16308 | H8: =G8/1000 -> 0.11316308 | I8: ='Crushing Down Time Hours'!L7 -> 11.033333 | J8: 0 | L8: =J8/24 -> 0 | M8: 1 | N8: =IF(L8=100%,I8/24*100%,L8) -> 0 | T8: =(P8*R8)-(S8*P8) -> 0 | U8: =IFERROR((R8-S8)/R8,"") | Z8: ='Reagent Consumption'!O8 -> 0 | AA8: ='Fuel Consumption'!D5 -> 320 | AB8: ='Reagent Consumption'!Q8 -> 0 | AC8: ='Reagent Consumption'!P8 -> 0 | AD8: ='Reagent Consumption'!R8 -> 0 | AE8: ='Reagent Consumption'!S8 -> 0 | AF8: ='Reagent Consumption'!T8 -> 0 | AG8: ='Fuel Consumption'!D5 -> 320 | AS8: Percentage ore blend
B9: 46176 | C9: =Crushing!N10 -> 17.712 | D9: =D8+C9 -> 95.7555 | E9: =C9/I9 -> 1.6053172 | F9: 1.45 | G9: =F9*C9 -> 25.6824 | H9: =G9/1000 -> 0.0256824 | I9: ='Crushing Down Time Hours'!L8 -> 11.033333 | J9: 0 | L9: =J9/24 -> 0 | M9: 1 | N9: =IF(L9=100%,(I9/24),L9) -> 0 | T9: =(P9*R9)-(S9*P9) -> 0 | U9: =IFERROR((R9-S9)/R9,"") | Z9: ='Reagent Consumption'!O9 -> 0 | AA9: ='Fuel Consumption'!D6 -> 388 | AB9: ='Reagent Consumption'!Q9 -> 0 | AC9: ='Reagent Consumption'!P9 -> 0 | AD9: ='Reagent Consumption'!R9 -> 0 | AE9: ='Reagent Consumption'!S9 -> 0 | AF9: ='Reagent Consumption'!T9 -> 0 | AG9: ='Fuel Consumption'!D6 -> 388 | AS9: Ops Time Crusher
B10: 46177 | C10: =Crushing!N12 -> 157.9905 | D10: =D9+C10 -> 253.746 | E10: =C10/I10 -> 16.74811 | F10: 1.45 | G10: =F10*C10 -> 229.08622 | H10: =G10/1000 -> 0.22908622 | I10: ='Crushing Down Time Hours'!L9 -> 9.4333333 | J10: 0 | L10: =J10/24 -> 0 | M10: 1 | N10: =IF(L10=100%,I10/24*100%,L10) -> 0 | T10: =(P10*R10)-(S10*P10) -> 0 | U10: =IFERROR((R10-S10)/R10,"") | Z10: ='Reagent Consumption'!O10 -> 150 | AA10: ='Fuel Consumption'!D7 -> 425 | AB10: ='Reagent Consumption'!Q10 -> 0 | AC10: ='Reagent Consumption'!P10 -> 250 | AD10: ='Reagent Consumption'!R10 -> 0 | AE10: ='Reagent Consumption'!S10 -> 0 | AF10: ='Reagent Consumption'!T10 -> 0 | AG10: ='Fuel Consumption'!D7 -> 425 | AS10: Ops Time Ballmill
B11: 46252 | C11: =Crushing!N14 -> 37.9192 | D11: =D10+C11 -> 291.6652 | E11: =C11/I11 -> 18.648787 | F11: 0.77 | G11: =F11*C11 -> 29.197784 | H11: =G11/1000 -> 0.029197784 | I11: ='Crushing Down Time Hours'!L6 -> 2.0333333 | J11: 0 | K11: ='Crushing Down Time Hours'!M6 -> 0.16944444 | L11: =J11/24 -> 0 | M11: 1 | N11: =IF(L11=100%,I11/24*100%,L11) -> 0 | T11: =(P11*R11)-(S11*P11) -> 0 | U11: =IFERROR((R11-S11)/R11,"") | Z11: ='Reagent Consumption'!O11 -> 225 | AA11: ='Fuel Consumption'!D8 -> 452 | AB11: ='Reagent Consumption'!Q11 -> 1000 | AC11: ='Reagent Consumption'!P11 -> 1250 | AD11: ='Reagent Consumption'!R11 -> 0 | AE11: ='Reagent Consumption'!S11 -> 0 | AF11: ='Reagent Consumption'!T11 -> 25 | AG11: ='Fuel Consumption'!D8 -> 452 | AS11: Grinding Ball Consumption
B12: 46253 | C12: =Crushing!N16 -> 283.1708 | D12: =D11+C12 -> 574.836 | E12: =C12/I12 -> 25.665027 | F12: 1.021 | G12: =F12*C12 -> 289.11739 | H12: =G12/1000 -> 0.28911739 | I12: ='Crushing Down Time Hours'!L7 -> 11.033333 | J12: 0 | K12: ='Crushing Down Time Hours'!M7 -> 0.91944444 | L12: =J12/24 -> 0 | M12: 1 | N12: =IF(L12=100%,I12/24*100%,L12) -> 0 | T12: =(P12*R12)-(S12*P12) -> 0 | U12: =IFERROR((R12-S12)/R12,"") | Z12: ='Reagent Consumption'!O13 -> 100 | AA12: ='Fuel Consumption'!D9 -> 397 | AB12: ='Reagent Consumption'!Q13 -> 0 | AC12: ='Reagent Consumption'!P13 -> 250 | AD12: ='Reagent Consumption'!R13 -> 0 | AE12: ='Reagent Consumption'!S13 -> 0 | AF12: ='Reagent Consumption'!T13 -> 0 | AG12: ='Fuel Consumption'!D9 -> 397 | AS12: Kwh
B13: 46254 | C13: =Crushing!N18 -> 337.1445 | D13: =D12+C13 -> 911.9805 | E13: =C13/I13 -> 33.658353 | F13: 0.604 | G13: =F13*C13 -> 203.63528 | H13: =G13/1000 -> 0.20363528 | I13: ='Crushing Down Time Hours'!L12 -> 10.016667 | J13: 0 | K13: ='Crushing Down Time Hours'!M8 -> 0.91944444 | L13: =J13/24 -> 0 | M13: 1 | N13: =IF(L13=100%,I13/24*100%,L13) -> 0 | T13: =(P13*R13)-(S13*P13) -> 0 | U13: =IFERROR((R13-S13)/R13,"") | Z13: ='Reagent Consumption'!O15 -> 100 | AA13: ='Fuel Consumption'!D10 -> 283 | AB13: ='Reagent Consumption'!Q15 -> 0 | AC13: ='Reagent Consumption'!P15 -> 0 | AD13: ='Reagent Consumption'!R15 -> 0 | AE13: ='Reagent Consumption'!S15 -> 0 | AF13: ='Reagent Consumption'!T15 -> 0 | AG13: ='Fuel Consumption'!D10 -> 283 | AS13: Flocculant Consumption
B14: 46255 | C14: =Crushing!N20 -> 293.3595 | D14: =D13+C14 -> 1205.34 | E14: =C14/I14 -> 31.09818 | F14: 0.442 | G14: =F14*C14 -> 129.6649 | H14: =G14/1000 -> 0.1296649 | I14: ='Crushing Down Time Hours'!L9 -> 9.4333333 | J14: 0 | K14: ='Crushing Down Time Hours'!M9 -> 0.78611111 | L14: =J14/24 -> 0 | M14: 1 | N14: =IF(L14=100%,I14/24*100%,L14) -> 0 | T14: =(P14*R14)-(S14*P14) -> 0 | U14: =IFERROR((R14-S14)/R14,"") | Z14: ='Reagent Consumption'!O16 -> 175 | AA14: ='Fuel Consumption'!D11 -> 347 | AB14: ='Reagent Consumption'!Q16 -> 0 | AC14: ='Reagent Consumption'!P16 -> 500 | AD14: ='Reagent Consumption'!R16 -> 0 | AE14: ='Reagent Consumption'!S16 -> 0 | AF14: ='Reagent Consumption'!T16 -> 0 | AG14: ='Fuel Consumption'!D11 -> 347 | AS14: Cyanide Consumption
B15: 46256 | C15: =Crushing!N22 -> 197.0325 | D15: =D14+C15 -> 1402.3725 | E15: =C15/I15 -> 21.852033 | F15: =AVERAGE('Rom File Inventory'!T87:T95) -> 0.96788889 | G15: =F15*C15 -> 190.70557 | H15: =G15/1000 -> 0.19070557 | I15: ='Crushing Down Time Hours'!L10 -> 9.0166667 | J15: 0 | K15: ='Crushing Down Time Hours'!M10 -> 0.75138889 | L15: =J15/24 -> 0 | M15: 1 | N15: =IF(L15=100%,I15/24*100%,L15) -> 0 | T15: =(P15*R15)-(S15*P15) -> 0 | U15: =IFERROR((R15-S15)/R15,"") | Z15: ='Reagent Consumption'!O17 -> 300 | AA15: ='Fuel Consumption'!D12 -> 346 | AB15: ='Reagent Consumption'!Q17 -> 0 | AC15: ='Reagent Consumption'!P17 -> 750 | AD15: ='Reagent Consumption'!R17 -> 0 | AE15: ='Reagent Consumption'!S17 -> 0 | AF15: ='Reagent Consumption'!T17 -> 0 | AG15: ='Fuel Consumption'!D12 -> 346 | AS15: Lime Consumption
B16: 46257 | C16: =Crushing!N24 -> 0 | D16: =D15+C16 -> 1402.3725 | E16: =C16/I16 -> 0 | G16: =F16*C16 -> 0 | H16: =G16/1000 -> 0 | I16: ='Crushing Down Time Hours'!L11 -> 0.033333333 | J16: 0 | K16: ='Crushing Down Time Hours'!M11 -> 0.0027777778 | L16: =J16/24 -> 0 | M16: 1 | N16: =IF(L16=100%,I16/24*100%,L16) -> 0 | T16: =(P16*R16)-(S16*P16) -> 0 | U16: =IFERROR((R16-S16)/R16,"") | Z16: ='Reagent Consumption'!O18 -> 175 | AA16: ='Fuel Consumption'!D13 -> 297 | AB16: ='Reagent Consumption'!Q18 -> 0 | AC16: ='Reagent Consumption'!P18 -> 0 | AD16: ='Reagent Consumption'!R18 -> 0 | AE16: ='Reagent Consumption'!S18 -> 0 | AF16: ='Reagent Consumption'!T18 -> 0 | AG16: ='Fuel Consumption'!D13 -> 297 | AS16: Carbon Consumption
B17: 46258 | C17: =Crushing!N26 -> 165.132 | D17: =D16+C17 -> 1567.5045 | E17: =C17/I17 -> 16.485724 | F17: =AVERAGE('Rom File Inventory'!T96:T104) -> 0.67088889 | G17: =F17*C17 -> 110.78522 | H17: =G17/1000 -> 0.11078522 | I17: ='Crushing Down Time Hours'!L12 -> 10.016667 | J17: 0 | K17: ='Crushing Down Time Hours'!M12 -> 0.83472222 | L17: =J17/24 -> 0 | M17: 1 | N17: =IF(L17=100%,I17/24*100%,L17) -> 0 | T17: =(P17*R17)-(S17*P17) -> 0 | U17: =IFERROR((R17-S17)/R17,"") | Z17: ='Reagent Consumption'!O19 -> 175 | AA17: ='Fuel Consumption'!D14 -> 304 | AB17: ='Reagent Consumption'!Q19 -> 0 | AC17: ='Reagent Consumption'!P19 -> 0 | AD17: ='Reagent Consumption'!R19 -> 0 | AE17: ='Reagent Consumption'!S19 -> 0 | AF17: ='Reagent Consumption'!T19 -> 0 | AG17: ='Fuel Consumption'!D14 -> 304
B18: 46259 | C18: =Crushing!N28 -> 0 | D18: =D17+C18 -> 1567.5045 | E18: =C18/I18 -> 0 | G18: =F18*C18 -> 0 | H18: =G18/1000 -> 0 | I18: ='Crushing Down Time Hours'!L13 -> 0.033333333 | J18: 0 | K18: ='Crushing Down Time Hours'!M13 -> 0.0027777778 | L18: =J18/24 -> 0 | M18: 1 | N18: =IF(L18=100%,I18/24*100%,L18) -> 0 | T18: =(P18*R18)-(S18*P18) -> 0 | U18: =IFERROR((R18-S18)/R18,"") | Z18: ='Reagent Consumption'!O21 -> 200 | AA18: ='Fuel Consumption'!D15 -> 510 | AB18: ='Reagent Consumption'!Q21 -> 500 | AC18: ='Reagent Consumption'!P21 -> 0 | AD18: ='Reagent Consumption'!R21 -> 0 | AE18: ='Reagent Consumption'!S21 -> 0 | AF18: ='Reagent Consumption'!T21 -> 50 | AG18: ='Fuel Consumption'!D15 -> 510
B19: 46260 | C19: 0 | D19: =D18+C19 -> 1567.5045 | E19: =C19/I19 -> 0 | G19: =F19*C19 -> 0 | H19: =G19/1000 -> 0 | I19: ='Crushing Down Time Hours'!L14 -> 0.033333333 | J19: 0 | K19: ='Crushing Down Time Hours'!M14 -> 0.0027777778 | L19: =J19/24 -> 0 | M19: 1 | N19: =IF(L19=100%,I19/24*100%,L19) -> 0 | T19: =(P19*R19)-(S19*P19) -> 0 | U19: =IFERROR((R19-S19)/R19,"") | Z19: ='Reagent Consumption'!O22 -> 100 | AA19: ='Fuel Consumption'!D16 -> 524 | AB19: ='Reagent Consumption'!Q22 -> 0 | AC19: ='Reagent Consumption'!P22 -> 0 | AD19: ='Reagent Consumption'!R22 -> 0 | AE19: ='Reagent Consumption'!S22 -> 0 | AF19: ='Reagent Consumption'!T22 -> 0 | AG19: ='Fuel Consumption'!D16 -> 524
B20: 46261 | C20: =Crushing!N32 -> 124.9471 | D20: =D19+C20 -> 1692.4516 | E20: =C20/I20 -> 23.724133 | F20: =AVERAGE('Rom File Inventory'!T105:T111) -> 0.55457143 | G20: =F20*C20 -> 69.292092 | H20: =G20/1000 -> 0.069292092 | I20: ='Crushing Down Time Hours'!L15 -> 5.2666667 | J20: 0 | K20: ='Crushing Down Time Hours'!M15 -> 0.43888889 | L20: =J20/24 -> 0 | M20: 1 | N20: =IF(L20=100%,I20/24*100%,L20) -> 0 | T20: =(P20*R20)-(S20*P20) -> 0 | U20: =IFERROR((R20-S20)/R20,"") | Z20: ='Reagent Consumption'!O24 -> 125 | AA20: ='Fuel Consumption'!D17 -> 300 | AB20: ='Reagent Consumption'!Q24 -> 0 | AC20: ='Reagent Consumption'!P24 -> 0 | AD20: ='Reagent Consumption'!R24 -> 0 | AE20: ='Reagent Consumption'!S24 -> 0 | AF20: ='Reagent Consumption'!T24 -> 0 | AG20: ='Fuel Consumption'!D17 -> 300
B21: 46262 | C21: =Crushing!N34 -> 167.765 | D21: =D20+C21 -> 1860.2166 | E21: =C21/I21 -> 20.927027 | F21: =AVERAGE('Rom File Inventory'!T112:T120) -> 1.1255556 | G21: =F21*C21 -> 188.82883 | H21: =G21/1000 -> 0.18882883 | I21: ='Crushing Down Time Hours'!L16 -> 8.0166667 | J21: 0 | K21: ='Crushing Down Time Hours'!M16 -> 0.66805556 | L21: =J21/24 -> 0 | M21: 1 | N21: =IF(L21=100%,I21/24*100%,L21) -> 0 | T21: =(P21*R21)-(S21*P21) -> 0 | U21: =IFERROR((R21-S21)/R21,"") | Z21: ='Reagent Consumption'!O26 -> 200 | AA21: ='Fuel Consumption'!D18 -> 1798 | AB21: ='Reagent Consumption'!Q26 -> 0 | AC21: ='Reagent Consumption'!P26 -> 0 | AD21: ='Reagent Consumption'!R26 -> 0 | AE21: ='Reagent Consumption'!S26 -> 0 | AF21: ='Reagent Consumption'!T26 -> 0 | AG21: ='Fuel Consumption'!D18 -> 1798
B22: 46263 | C22: =Crushing!N36 -> 240.435 | D22: =D21+C22 -> 2100.6516 | E22: =C22/I22 -> 24.003494 | F22: =AVERAGE('Rom File Inventory'!T121:T131) -> 0.60627273 | G22: =F22*C22 -> 145.76918 | H22: =G22/1000 -> 0.14576918 | I22: ='Crushing Down Time Hours'!L17 -> 10.016667 | J22: 0 | K22: ='Crushing Down Time Hours'!M17 -> 0.83472222 | L22: =J22/24 -> 0 | M22: 1 | N22: =IF(L22=100%,I22/24*100%,L22) -> 0 | T22: =(P22*R22)-(S22*P22) -> 0 | U22: =IFERROR((R22-S22)/R22,"") | Z22: ='Reagent Consumption'!O27 -> 250 | AA22: ='Fuel Consumption'!D19 -> 1841 | AB22: ='Reagent Consumption'!Q27 -> 0 | AC22: ='Reagent Consumption'!P27 -> 0 | AD22: ='Reagent Consumption'!R27 -> 0 | AE22: ='Reagent Consumption'!S27 -> 0 | AF22: ='Reagent Consumption'!T27 -> 0 | AG22: ='Fuel Consumption'!D19 -> 1841
B23: 46264 | C23: =Crushing!N38 -> 53.82 | D23: =D22+C23 -> 2154.4716 | E23: =C23/I23 -> 26.468852 | F23: =AVERAGE('Rom File Inventory'!T132:T135) -> 0.3535 | G23: =F23*C23 -> 19.02537 | H23: =G23/1000 -> 0.01902537 | I23: ='Crushing Down Time Hours'!L18 -> 2.0333333 | J23: 0 | K23: ='Crushing Down Time Hours'!M18 -> 0.16944444 | L23: =J23/24 -> 0 | M23: 1 | N23: =IF(L23=100%,I23/24*100%,L23) -> 0 | T23: =(P23*R23)-(S23*P23) -> 0 | U23: =IFERROR((R23-S23)/R23,"") | Z23: ='Reagent Consumption'!O28 -> 275 | AA23: ='Fuel Consumption'!D20 -> 2492 | AB23: ='Reagent Consumption'!Q28 -> 0 | AC23: ='Reagent Consumption'!P28 -> 325 | AD23: ='Reagent Consumption'!R28 -> 0 | AE23: ='Reagent Consumption'!S28 -> 0 | AF23: ='Reagent Consumption'!T28 -> 25 | AG23: ='Fuel Consumption'!D20 -> 2492
B24: 46265 | C24: =Crushing!N40 -> 0 | D24: =D23+C24 -> 2154.4716 | E24: =IFERROR(C24/I24,"") | G24: =F24*C24 -> 0 | H24: =G24/1000 -> 0 | I24: ='Crushing Down Time Hours'!L19 -> 0 | J24: ='Milling Down Time Hours'!Q5 -> 22.433333 | K24: ='Crushing Down Time Hours'!M24 -> 0 | L24: ='Milling Down Time Hours'!R5 -> 0.93472222 | M24: 1 | N24: =IF(L24=100%,J24/24*100%,L24) -> 0.93472222 | T24: =(P24*R24)-(S24*P24) -> 0 | U24: =IFERROR((R24-S24)/R24,"") | Z24: ='Reagent Consumption'!O29 -> 0 | AA24: ='Fuel Consumption'!D21 -> 864 | AB24: ='Reagent Consumption'!Q29 -> 0 | AC24: ='Reagent Consumption'!P29 -> 0 | AD24: ='Reagent Consumption'!R29 -> 0 | AE24: ='Reagent Consumption'!S29 -> 0 | AF24: ='Reagent Consumption'!T29 -> 0 | AG24: ='Fuel Consumption'!D21 -> 864
B25: 46266 | C25: =Crushing!N42 -> 0 | D25: =D24+C25 -> 2154.4716 | E25: =IFERROR(C25/I25,"") | G25: =F25*C25 -> 0 | H25: =G25/1000 -> 0 | I25: ='Crushing Down Time Hours'!L20 -> 0 | J25: ='Milling Down Time Hours'!Q6 -> 22.9 | K25: ='Crushing Down Time Hours'!M25 -> 0 | L25: ='Milling Down Time Hours'!R6 -> 0.95416667 | M25: 1 | N25: =IF(L25=100%,J25/24*100%,L25) -> 0.95416667 | T25: =(P25*R25)-(S25*P25) -> 0 | U25: =IFERROR((R25-S25)/R25,"") | Z25: ='Reagent Consumption'!O30 -> 0 | AA25: ='Fuel Consumption'!D22 -> 837 | AB25: ='Reagent Consumption'!Q30 -> 0 | AC25: ='Reagent Consumption'!P30 -> 0 | AD25: ='Reagent Consumption'!R30 -> 0 | AE25: ='Reagent Consumption'!S30 -> 0 | AF25: ='Reagent Consumption'!T30 -> 0 | AG25: ='Fuel Consumption'!D22 -> 837
B26: 46267 | C26: =Crushing!N44 -> 0 | D26: =D25+C26 -> 2154.4716 | E26: =IFERROR(C26/I26,"") | G26: =F26*C26 -> 0 | H26: =G26/1000 -> 0 | I26: ='Crushing Down Time Hours'!L21 -> 0 | J26: ='Milling Down Time Hours'!Q7 -> 22 | K26: ='Crushing Down Time Hours'!M26 -> 0 | L26: ='Milling Down Time Hours'!R7 -> 0.91666667 | M26: 1 | N26: =IF(L26=100%,J26/24*100%,L26) -> 0.91666667 | T26: =(P26*R26)-(S26*P26) -> 0 | U26: =IFERROR((R26-S26)/R26,"") | Z26: ='Reagent Consumption'!O31 -> 175 | AA26: ='Fuel Consumption'!D23 -> 810 | AB26: ='Reagent Consumption'!Q31 -> 0 | AC26: ='Reagent Consumption'!P31 -> 0 | AD26: ='Reagent Consumption'!R31 -> 0 | AE26: ='Reagent Consumption'!S31 -> 0 | AF26: ='Reagent Consumption'!T31 -> 0 | AG26: ='Fuel Consumption'!D23 -> 810
B27: 46268 | C27: =Crushing!N46 -> 0 | D27: =D26+C27 -> 2154.4716 | E27: =IFERROR(C27/I27,"") | G27: =F27*C27 -> 0 | H27: =G27/1000 -> 0 | I27: ='Crushing Down Time Hours'!L22 -> 0 | J27: ='Milling Down Time Hours'!Q8 -> 23 | K27: ='Crushing Down Time Hours'!M27 -> 0 | L27: ='Milling Down Time Hours'!R8 -> 0.95833333 | M27: 1 | N27: =IF(L27=100%,J27/24*100%,L27) -> 0.95833333 | T27: =(P27*R27)-(S27*P27) -> 0 | U27: =IFERROR((R27-S27)/R27,"") | Z27: ='Reagent Consumption'!O32 -> 250 | AA27: ='Fuel Consumption'!D24 -> 1841 | AB27: ='Reagent Consumption'!Q32 -> 0 | AC27: ='Reagent Consumption'!P32 -> 0 | AD27: ='Reagent Consumption'!R32 -> 0 | AE27: ='Reagent Consumption'!S32 -> 0 | AF27: ='Reagent Consumption'!T32 -> 50 | AG27: ='Fuel Consumption'!D24 -> 1841
B28: 46269 | C28: =Crushing!N43 -> 0 | D28: =D27+C28 -> 2154.4716 | E28: =IFERROR(C28/I28,"") | G28: =F28*C28 -> 0 | H28: =G28/1000 -> 0 | I28: ='Crushing Down Time Hours'!L23 -> 0 | J28: ='Milling Down Time Hours'!Q9 -> 0 | K28: ='Crushing Down Time Hours'!M28 -> 0 | L28: ='Milling Down Time Hours'!R9 -> 0 | M28: 1 | N28: =IF(L28=100%,J28/24*100%,L28) -> 0 | T28: =(P28*R28)-(S28*P28) -> 0 | U28: =IFERROR((R28-S28)/R28,"") | Z28: ='Reagent Consumption'!O33 -> 125 | AA28: ='Fuel Consumption'!D25 -> 1784 | AB28: ='Reagent Consumption'!Q33 -> 0 | AC28: ='Reagent Consumption'!P33 -> 0 | AD28: ='Reagent Consumption'!R33 -> 0 | AE28: ='Reagent Consumption'!S33 -> 0 | AF28: ='Reagent Consumption'!T33 -> 0 | AG28: ='Fuel Consumption'!D25 -> 1784
B29: 46270 | C29: =Crushing!N44 -> 0 | D29: =D28+C29 -> 2154.4716 | E29: =IFERROR(C29/I29,"") | G29: =F29*C29 -> 0 | H29: =G29/1000 -> 0 | I29: ='Crushing Down Time Hours'!L24 -> 0 | J29: ='Milling Down Time Hours'!Q10 -> 11 | K29: ='Crushing Down Time Hours'!M29 -> 0 | L29: ='Milling Down Time Hours'!R10 -> 0.45833333 | M29: 1 | N29: =IF(L29=100%,J29/24*100%,L29) -> 0.45833333 | T29: =(P29*R29)-(S29*P29) -> 0 | U29: =IFERROR((R29-S29)/R29,"") | Z29: ='Reagent Consumption'!O38 -> 175 | AA29: ='Fuel Consumption'!D26 -> 2237 | AB29: ='Reagent Consumption'!Q38 -> 0 | AC29: ='Reagent Consumption'!P38 -> 0 | AD29: ='Reagent Consumption'!R38 -> 0 | AE29: ='Reagent Consumption'!S38 -> 0 | AF29: ='Reagent Consumption'!T38 -> 25 | AG29: ='Fuel Consumption'!D26 -> 2237
B30: 46271 | C30: =Crushing!N45 -> 0 | D30: =D29+C30 -> 2154.4716 | E30: =IFERROR(C30/I30,"") | G30: =F30*C30 -> 0 | H30: =G30/1000 -> 0 | I30: ='Crushing Down Time Hours'!L25 -> 0 | J30: ='Milling Down Time Hours'!Q11 -> 21.833333 | K30: ='Crushing Down Time Hours'!M30 -> 0 | L30: ='Milling Down Time Hours'!R11 -> 0.90972222 | M30: 1 | N30: =IF(L30=100%,J30/24*100%,L30) -> 0.90972222 | T30: =(P30*R30)-(S30*P30) -> 0 | U30: =IFERROR((R30-S30)/R30,"") | Z30: ='Reagent Consumption'!O39 -> 175 | AA30: ='Fuel Consumption'!D27 -> 1203 | AB30: ='Reagent Consumption'!Q39 -> 0 | AC30: ='Reagent Consumption'!P39 -> 0 | AD30: ='Reagent Consumption'!R39 -> 0 | AE30: ='Reagent Consumption'!S39 -> 0 | AF30: ='Reagent Consumption'!T39 -> 0 | AG30: ='Fuel Consumption'!D27 -> 1203
B31: 46272 | C31: =Crushing!N46 -> 0 | D31: =D30+C31 -> 2154.4716 | E31: =IFERROR(C31/I31,"") | G31: =F31*C31 -> 0 | H31: =G31/1000 -> 0 | I31: ='Crushing Down Time Hours'!L26 -> 0 | J31: ='Milling Down Time Hours'!Q12 -> 22.45 | K31: ='Crushing Down Time Hours'!M31 -> 0 | L31: ='Milling Down Time Hours'!R12 -> 0.93541667 | M31: 1 | N31: =IF(L31=100%,J31/24*100%,L31) -> 0.93541667 | T31: =(P31*R31)-(S31*P31) -> 0 | U31: =IFERROR((R31-S31)/R31,"") | Z31: ='Reagent Consumption'!O41 -> 0 | AA31: ='Fuel Consumption'!D28 -> 2655 | AB31: ='Reagent Consumption'!Q41 -> 0 | AC31: ='Reagent Consumption'!P41 -> 0 | AD31: ='Reagent Consumption'!R41 -> 0 | AE31: ='Reagent Consumption'!S41 -> 0 | AF31: ='Reagent Consumption'!T41 -> 0 | AG31: ='Fuel Consumption'!D28 -> 2655
B32: 46273 | C32: =Crushing!N47 -> 0 | D32: =D31+C32 -> 2154.4716 | E32: =IFERROR(C32/I32,"") | G32: =F32*C32 -> 0 | H32: =G32/1000 -> 0 | I32: ='Crushing Down Time Hours'!L27 -> 0 | J32: ='Milling Down Time Hours'!Q13 -> 19.783333 | K32: ='Crushing Down Time Hours'!M32 -> 0 | L32: ='Milling Down Time Hours'!R13 -> 0.82430556 | M32: 1 | N32: =IF(L32=100%,J32/24*100%,L32) -> 0.82430556 | T32: =(P32*R32)-(S32*P32) -> 0 | U32: =IFERROR((R32-S32)/R32,"") | Z32: ='Reagent Consumption'!O43 -> 0 | AA32: ='Fuel Consumption'!D29 -> 1557 | AB32: ='Reagent Consumption'!Q43 -> 0 | AC32: ='Reagent Consumption'!P43 -> 0 | AD32: ='Reagent Consumption'!R43 -> 100 | AE32: ='Reagent Consumption'!S43 -> 7 | AF32: ='Reagent Consumption'!T43 -> 0 | AG32: ='Fuel Consumption'!D29 -> 1557
B33: 46274 | C33: =Crushing!N48 -> 0 | D33: =D32+C33 -> 2154.4716 | E33: =IFERROR(C33/I33,"") | G33: =F33*C33 -> 0 | H33: =G33/1000 -> 0 | I33: ='Crushing Down Time Hours'!L28 -> 0 | J33: ='Milling Down Time Hours'!Q15 -> 21.033333 | K33: ='Crushing Down Time Hours'!M33 -> 0 | L33: ='Milling Down Time Hours'!R14 -> 0.51875 | M33: 1 | N33: =IF(L33=100%,J33/24*100%,L33) -> 0.51875 | T33: =(P33*R33)-(S33*P33) -> 0 | U33: =IFERROR((R33-S33)/R33,"") | Z33: ='Reagent Consumption'!O45 -> 225 | AA33: ='Fuel Consumption'!D30 -> 1278 | AB33: ='Reagent Consumption'!Q45 -> 1000 | AC33: ='Reagent Consumption'!P45 -> 0 | AD33: ='Reagent Consumption'!R45 -> 0 | AE33: ='Reagent Consumption'!S45 -> 0 | AF33: ='Reagent Consumption'!T45 -> 0 | AG33: ='Fuel Consumption'!D30 -> 1278
B34: 46275 | C34: =Crushing!N60 -> 73.125 | D34: =D33+C34 -> 2227.5966 | E34: =IFERROR(C34/I34,"") | G34: =F34*C34 -> 0 | H34: =G34/1000 -> 0 | I34: ='Crushing Down Time Hours'!L29 -> 0 | J34: ='Milling Down Time Hours'!Q16 -> 12.983333 | K34: ='Crushing Down Time Hours'!M34 -> 0 | L34: ='Milling Down Time Hours'!R15 -> 0.87638889 | M34: 1 | N34: =IF(L34=100%,J34/24*100%,L34) -> 0.87638889 | T34: =(P34*R34)-(S34*P34) -> 0 | U34: =IFERROR((R34-S34)/R34,"") | Z34: ='Reagent Consumption'!O47 -> 0 | AA34: ='Fuel Consumption'!D31 -> 1099 | AB34: ='Reagent Consumption'!Q47 -> 0 | AC34: ='Reagent Consumption'!P47 -> 0 | AD34: ='Reagent Consumption'!R47 -> 0 | AE34: ='Reagent Consumption'!S47 -> 0 | AF34: ='Reagent Consumption'!T47 -> 0 | AG34: ='Fuel Consumption'!D31 -> 1099
B35: 46276 | C35: =Crushing!N50 -> 0 | D35: =D34+C35 -> 2227.5966 | E35: =IFERROR(C35/I35,"") | G35: =F35*C35 -> 0 | H35: =G35/1000 -> 0 | I35: ='Crushing Down Time Hours'!L30 -> 0 | J35: ='Milling Down Time Hours'!Q18 -> 0 | K35: ='Crushing Down Time Hours'!M35 -> 0 | L35: ='Milling Down Time Hours'!R16 -> 0.54097222 | M35: 1 | N35: =IF(L35=100%,J35/24*100%,L35) -> 0.54097222 | T35: =(P35*R35)-(S35*P35) -> 0 | U35: =IFERROR((R35-S35)/R35,"") | Z35: ='Reagent Consumption'!O49 -> 0 | AA35: ='Fuel Consumption'!D32 -> 1988 | AB35: ='Reagent Consumption'!Q49 -> 0 | AC35: ='Reagent Consumption'!P49 -> 0 | AD35: ='Reagent Consumption'!R49 -> 0 | AE35: ='Reagent Consumption'!S49 -> 0 | AF35: ='Reagent Consumption'!T49 -> 0 | AG35: ='Fuel Consumption'!D32 -> 1988
B36: 46277 | C36: =Crushing!N64 -> 328.77 | D36: =D35+C36 -> 2556.3666 | E36: =IFERROR(C36/I36,"") | F36: =AVERAGE('Rom File Inventory'!$T$136:$T$147) -> 0.52608333 | G36: =F36*C36 -> 172.96042 | H36: =G36/1000 -> 0.17296042 | I36: ='Crushing Down Time Hours'!L31 -> 0 | J36: ='Milling Down Time Hours'!Q19 -> 10 | K36: ='Crushing Down Time Hours'!M36 -> 0 | L36: ='Milling Down Time Hours'!R17 -> 0 | M36: 1 | N36: =IF(L36=100%,J36/24*100%,L36) -> 0 | T36: =(P36*R36)-(S36*P36) -> 0 | U36: =IFERROR((R36-S36)/R36,"") | Z36: ='Reagent Consumption'!O51 -> 0 | AA36: ='Fuel Consumption'!D33 -> 1588 | AB36: ='Reagent Consumption'!Q51 -> 0 | AC36: ='Reagent Consumption'!P51 -> 0 | AD36: ='Reagent Consumption'!R51 -> 0 | AE36: ='Reagent Consumption'!S51 -> 0 | AF36: ='Reagent Consumption'!T51 -> 0 | AG36: ='Fuel Consumption'!D33 -> 1588
B37: 46278 | C37: =Crushing!N66 -> 262.665 | D37: =D36+C37 -> 2819.0316 | E37: =IFERROR(C37/I37,"") | F37: =AVERAGE('Rom File Inventory'!T142:T155) -> 0.62457143 | G37: =F37*C37 -> 164.05305 | H37: =G37/1000 -> 0.16405305 | I37: ='Crushing Down Time Hours'!L32 -> 0 | J37: ='Milling Down Time Hours'!Q20 -> 24 | K37: ='Crushing Down Time Hours'!M37 -> 0 | L37: ='Milling Down Time Hours'!R18 -> 0 | M37: 1 | N37: =IF(L37=100%,J37/24*100%,L37) -> 0 | T37: =(P37*R37)-(S37*P37) -> 0 | U37: =IFERROR((R37-S37)/R37,"") | Z37: ='Reagent Consumption'!O52 -> 0 | AA37: ='Fuel Consumption'!D34 -> 2109 | AB37: ='Reagent Consumption'!Q52 -> 0 | AC37: ='Reagent Consumption'!P52 -> 0 | AD37: ='Reagent Consumption'!R52 -> 0 | AE37: ='Reagent Consumption'!S52 -> 0 | AF37: ='Reagent Consumption'!T52 -> 0 | AG37: ='Fuel Consumption'!D34 -> 2109
B38: 46279 | C38: =Crushing!N68 -> 0 | D38: =D37+C38 -> 2819.0316 | E38: =IFERROR(C38/I38,"") | G38: =F38*C38 -> 0 | H38: =G38/1000 -> 0 | I38: ='Crushing Down Time Hours'!L33 -> 0 | J38: ='Milling Down Time Hours'!Q21 -> 22.933333 | K38: ='Crushing Down Time Hours'!M38 -> 0 | L38: ='Milling Down Time Hours'!R19 -> 0.41666667 | M38: 1 | N38: =IF(L38=100%,J38/24*100%,L38) -> 0.41666667 | U38: =IFERROR((R38-S38)/R38,"") | Z38: ='Reagent Consumption'!O54 -> 0 | AA38: ='Fuel Consumption'!D35 -> 2436 | AB38: ='Reagent Consumption'!Q54 -> 0 | AC38: ='Reagent Consumption'!P54 -> 0 | AD38: ='Reagent Consumption'!R54 -> 0 | AE38: ='Reagent Consumption'!S54 -> 0 | AF38: ='Reagent Consumption'!T54 -> 0 | AG38: ='Fuel Consumption'!D35 -> 2436
B39: 46280 | C39: =Crushing!N54 -> 0 | D39: =D38+C39 -> 2819.0316 | E39: =IFERROR(C39/I39,"") | G39: =F39*C39 -> 0 | H39: =G39/1000 -> 0 | I39: ='Crushing Down Time Hours'!L34 -> 0 | J39: ='Milling Down Time Hours'!Q22 -> 24 | K39: ='Crushing Down Time Hours'!M39 -> 0 | L39: ='Milling Down Time Hours'!R20 -> 1 | M39: 1 | N39: =IF(L39=100%,J39/24*100%,L39) -> 1 | U39: =IFERROR((R39-S39)/R39,"") | Z39: ='Reagent Consumption'!O56 -> 0 | AA39: ='Fuel Consumption'!D36 -> 2232 | AB39: ='Reagent Consumption'!Q56 -> 0 | AC39: ='Reagent Consumption'!P56 -> 0 | AD39: ='Reagent Consumption'!R56 -> 0 | AE39: ='Reagent Consumption'!S56 -> 0 | AF39: ='Reagent Consumption'!T56 -> 0 | AG39: ='Fuel Consumption'!D36 -> 2232
B40: 46281 | C40: =Crushing!N55 -> 0 | D40: =D39+C40 -> 2819.0316 | E40: =IFERROR(C40/I40,"") | G40: =F40*C40 -> 0 | H40: =G40/1000 -> 0 | I40: ='Crushing Down Time Hours'!L35 -> 0 | J40: ='Milling Down Time Hours'!Q23 -> 21.083333 | K40: ='Crushing Down Time Hours'!M40 -> 0 | L40: ='Milling Down Time Hours'!R21 -> 0.95555556 | M40: 1 | N40: =IF(L40=100%,J40/24*100%,L40) -> 0.95555556 | U40: =IFERROR((R40-S40)/R40,"") | Z40: ='Reagent Consumption'!O57 -> 0 | AA40: ='Fuel Consumption'!D37 -> 1968 | AB40: ='Reagent Consumption'!Q57 -> 0 | AC40: ='Reagent Consumption'!P57 -> 0 | AD40: ='Reagent Consumption'!R57 -> 0 | AE40: ='Reagent Consumption'!S57 -> 0 | AF40: ='Reagent Consumption'!T57 -> 0 | AG40: ='Fuel Consumption'!D37 -> 1968
B41: 46282 | C41: =Crushing!N56 -> 0 | D41: =D40+C41 -> 2819.0316 | E41: =IFERROR(C41/I41,"") | G41: =F41*C41 -> 0 | H41: =G41/1000 -> 0 | I41: ='Crushing Down Time Hours'!L36 -> 0 | J41: ='Milling Down Time Hours'!Q24 -> 18 | K41: ='Crushing Down Time Hours'!M41 -> 0 | L41: ='Milling Down Time Hours'!R22 -> 1 | M41: 1 | N41: =IF(L41=100%,J41/24*100%,L41) -> 0.75 | U41: =IFERROR((R41-S41)/R41,"") | Z41: ='Reagent Consumption'!O58 -> 0 | AA41: ='Fuel Consumption'!D38 -> 0 | AB41: ='Reagent Consumption'!Q58 -> 0 | AC41: ='Reagent Consumption'!P58 -> 0 | AD41: ='Reagent Consumption'!R58 -> 0 | AE41: ='Reagent Consumption'!S58 -> 0 | AF41: ='Reagent Consumption'!T58 -> 0 | AG41: ='Fuel Consumption'!D38 -> 0
B42: 46283 | C42: =Crushing!N76 -> 201.24 | D42: =D41+C42 -> 3020.2716 | E42: =IFERROR(C42/I42,"") | F42: =F43 -> 0.58594118 | G42: =F42*C42 -> 117.9148 | H42: =G42/1000 -> 0.1179148 | I42: ='Crushing Down Time Hours'!L37 -> 0 | J42: ='Milling Down Time Hours'!Q25 -> 0 | K42: ='Crushing Down Time Hours'!M42 -> 0 | L42: ='Milling Down Time Hours'!R23 -> 0.87847222 | M42: 1 | N42: =IF(L42=100%,J42/24*100%,L42) -> 0.87847222 | U42: =IFERROR((R42-S42)/R42,"") | Z42: ='Reagent Consumption'!O59 -> 0 | AA42: ='Fuel Consumption'!D39 -> 0 | AB42: ='Reagent Consumption'!Q59 -> 0 | AC42: ='Reagent Consumption'!P59 -> 0 | AD42: ='Reagent Consumption'!R59 -> 0 | AE42: ='Reagent Consumption'!S59 -> 0 | AF42: ='Reagent Consumption'!T59 -> 0 | AG42: ='Fuel Consumption'!D39 -> 0
...

Sheet Reagent Consumption
B1: Data Reagent Additional and Reagent Consumption Processing Plant
B2: PT Bulawan Daya Lestari
B3: Metalurgi PT BDL, PIC DYAN RAMDHANI
A5: Data ragents consumption | D5: Leaching | G5: Goldroom | J5: Thickener Tank | L5: Crushing | U5: Gold Rom
A6: Date | B6: Shift | C6: PIC | D6: Sandios (kg) : | E6: Lime (kg) : | F6: Carbon (kg) : | G6: NaCN (kg) : | H6: NaOH (kg) : | I6: HCL (Jerigen) : | J6: Lime (kg) : | K6: Floculant (kg) : | L6: Cement (kg) | N6: Date | O6: Sandios (kg) : | P6: Lime (kg) : | Q6: Carbon (kg) : | R6: NaOH (kg) : | S6: HCL (Jerigen) : | T6: Floculant (kg) : | U6: NaCN (kg) : | V6: HCL (jerigen) | X6: Reagent Additional (kg)
A7: 46262 | B7: Day | C7: Hadi/Yan | N7: 46262 | O7: =SUMIF($A$7:$A$109,N7,$D$7:$D$109) -> 0 | P7: =SUMIF(A$7:A$52,N7,E$7:E$52)+SUMIF(A$7:A$52,N7,J$7:J$52) -> 0 | Q7: =SUMIF(A$7:A$142,N7,F$7:F$142) -> 0 | R7: =SUMIF(A$7:A$71,N7,H$7:H$72) -> 0 | S7: =SUMIF(A$7:A$72,N7,I$7:I$72) -> 0 | T7: =SUMIF(A$7:A$72,N7,K$7:K$72) -> 0 | U7: =SUMIF(A$7:A$72,N7,G$7:G$72) -> 0 | V7: =SUMIF(A$7:A$72,N7,I$7:I$72) -> 0 | X7: Sandios (kg) | Y7: Lime (kg) | Z7: Carbon (kg) | AA7: Floculant (kg) | AB7: NaOH (kg) | AC7: Hcl (jerigen) | AD7: NaCN (kg)
A8: 46263 | N8: 46263 | O8: =SUMIF($A$7:$A$109,N8,$D$7:$D$109) -> 0 | P8: =SUMIF(A$7:A$52,N8,E$7:E$52)+SUMIF(A$7:A$52,N8,J$7:J$52) -> 0 | Q8: =SUMIF(A$7:A$142,N8,F$7:F$142) -> 0 | R8: =SUMIF(A$7:A$71,N8,H$7:H$72) -> 0 | S8: =SUMIF(A$7:A$72,N8,I$7:I$72) -> 0 | T8: =SUMIF(A$7:A$72,N8,K$7:K$72) -> 0 | U8: =SUMIF(A$7:A$72,N8,G$7:G$72) -> 0 | V8: =SUMIF(A$7:A$72,N8,I$7:I$72) -> 0 | X8: =O72+U72 -> 6050 | Y8: =P72 -> 4150 | Z8: =Q72 -> 4000 | AA8: =T72 -> 325 | AB8: =R72 -> 100 | AC8: =V72 -> 7 | AD8: =U72 -> 25
A9: 46264 | N9: 46264 | O9: =SUMIF($A$7:$A$109,N9,$D$7:$D$109) -> 0 | P9: =SUMIF(A$7:A$52,N9,E$7:E$52)+SUMIF(A$7:A$52,N9,J$7:J$52) -> 0 | Q9: =SUMIF(A$7:A$142,N9,F$7:F$142) -> 0 | R9: =SUMIF(A$7:A$71,N9,H$7:H$72) -> 0 | S9: =SUMIF(A$7:A$72,N9,I$7:I$72) -> 0 | T9: =SUMIF(A$7:A$72,N9,K$7:K$72) -> 0 | U9: =SUMIF(A$7:A$72,N9,G$7:G$72) -> 0 | V9: =SUMIF(A$7:A$72,N9,I$7:I$72) -> 0 | AP9: =30/1.16 -> 25.862069
A10: 46265 | B10: Day | C10: Hadi/Yan | D10: 150 | E10: 250 | N10: 46265 | O10: =SUMIF($A$7:$A$109,N10,$D$7:$D$109) -> 150 | P10: =SUMIF(A$7:A$52,N10,E$7:E$52)+SUMIF(A$7:A$52,N10,J$7:J$52) -> 250 | Q10: =SUMIF(A$7:A$142,N10,F$7:F$142) -> 0 | R10: =SUMIF(A$7:A$71,N10,H$7:H$72) -> 0 | S10: =SUMIF(A$7:A$72,N10,I$7:I$72) -> 0 | T10: =SUMIF(A$7:A$72,N10,K$7:K$72) -> 0 | U10: =SUMIF(A$7:A$72,N10,G$7:G$72) -> 0 | V10: =SUMIF(A$7:A$72,N10,I$7:I$72) -> 0 | X10: Reagent Consumption
A11: 46266 | B11: Day | C11: Yanli/Hadi | D11: 100 | E11: 1250 | F11: 1000 | K11: 25 | N11: 46266 | O11: =SUMIF($A$7:$A$109,N11,$D$7:$D$109) -> 225 | P11: =SUMIF(A$7:A$52,N11,E$7:E$52)+SUMIF(A$7:A$52,N11,J$7:J$52) -> 1250 | Q11: =SUMIF(A$7:A$142,N11,F$7:F$142) -> 1000 | R11: =SUMIF(A$7:A$71,N11,H$7:H$72) -> 0 | S11: =SUMIF(A$7:A$72,N11,I$7:I$72) -> 0 | T11: =SUMIF(A$7:A$72,N11,K$7:K$72) -> 25 | U11: =SUMIF(A$7:A$72,N11,G$7:G$72) -> 0 | V11: =SUMIF(A$7:A$72,N11,I$7:I$72) -> 0 | X11: =X8/'Au Cal Leaching Tank'!$N$61 -> 1.5146571 | Y11: =Y8/'Au Cal Leaching Tank'!$N$61 -> 1.0389796 | Z11: =Z8/'Au Cal Leaching Tank'!$N$61 -> 1.0014262 | AA11: =AA8/'Au Cal Leaching Tank'!$N$61 -> 0.081365875 | AB11: =AB8/'Au Cal Leaching Tank'!$N$61 -> 0.025035654 | AC11: =(AC8*30)/'Au Cal Leaching Tank'!$N$61 -> 0.052574873 | AD11: =AD8/'Au Cal Leaching Tank'!$N$61 -> 0.0062589135
A12: 46266 | B12: Night | C12: Kristo/Ulan | D12: 125 | N12: 46267 | O12: =SUMIF($A$7:$A$109,N12,$D$7:$D$109) -> 275 | P12: =SUMIF(A$7:A$52,N12,E$7:E$52)+SUMIF(A$7:A$52,N12,J$7:J$52) -> 500 | Q12: =SUMIF(A$7:A$142,N12,F$7:F$142) -> 1000 | R12: =SUMIF(A$7:A$71,N12,H$7:H$72) -> 0 | S12: =SUMIF(A$7:A$72,N12,I$7:I$72) -> 0 | T12: =SUMIF(A$7:A$72,N12,K$7:K$72) -> 25 | U12: =SUMIF(A$7:A$72,N12,G$7:G$72) -> 0 | V12: =SUMIF(A$7:A$72,N12,I$7:I$72) -> 0 | X12: Sandios (kg/t) | Y12: Lime (kg/t) | Z12: Carbon (kg/t) | AA12: Floculant (kg/t) | AB12: NaOH (kg/t) | AC12: HCL (L/t) | AD12: NaCN (kg/t)
A13: 46267 | B13: Day | C13: Yanli/Hadi | D13: 150 | E13: 500 | K13: 25 | N13: 46268 | O13: =SUMIF($A$7:$A$109,N13,$D$7:$D$109) -> 100 | P13: =SUMIF(A$7:A$52,N13,E$7:E$52)+SUMIF(A$7:A$52,N13,J$7:J$52) -> 250 | Q13: =SUMIF(A$7:A$142,N13,F$7:F$142) -> 0 | R13: =SUMIF(A$7:A$71,N13,H$7:H$72) -> 0 | S13: =SUMIF(A$7:A$72,N13,I$7:I$72) -> 0 | T13: =SUMIF(A$7:A$72,N13,K$7:K$72) -> 0 | U13: =SUMIF(A$7:A$72,N13,G$7:G$72) -> 0 | V13: =SUMIF(A$7:A$72,N13,I$7:I$72) -> 0
A14: 46267 | B14: Night | C14: Kristo/Ulan | D14: 125 | F14: 1000 | N14: 46269 | O14: =SUMIF($A$7:$A$109,N14,$D$7:$D$109) -> 0 | P14: =SUMIF(A$7:A$52,N14,E$7:E$52)+SUMIF(A$7:A$52,N14,J$7:J$52) -> 0 | Q14: =SUMIF(A$7:A$142,N14,F$7:F$142) -> 0 | R14: =SUMIF(A$7:A$71,N14,H$7:H$72) -> 0 | S14: =SUMIF(A$7:A$72,N14,I$7:I$72) -> 0 | T14: =SUMIF(A$7:A$72,N14,K$7:K$72) -> 25 | U14: =SUMIF(A$7:A$72,N14,G$7:G$72) -> 0 | V14: =SUMIF(A$7:A$72,N14,I$7:I$72) -> 0
A15: 46268 | B15: Day | C15: Yanli/Hadi | D15: 100 | E15: 250 | N15: 46270 | O15: =SUMIF($A$7:$A$109,N15,$D$7:$D$109) -> 100 | P15: =SUMIF(A$7:A$52,N15,E$7:E$52)+SUMIF(A$7:A$52,N15,J$7:J$52) -> 0 | Q15: =SUMIF(A$7:A$142,N15,F$7:F$142) -> 0 | R15: =SUMIF(A$7:A$71,N15,H$7:H$72) -> 0 | S15: =SUMIF(A$7:A$72,N15,I$7:I$72) -> 0 | T15: =SUMIF(A$7:A$72,N15,K$7:K$72) -> 0 | U15: =SUMIF(A$7:A$72,N15,G$7:G$72) -> 0 | V15: =SUMIF(A$7:A$72,N15,I$7:I$72) -> 0
A16: 46269 | B16: Day | C16: Yanli/Hadi | K16: 25 | N16: 46271 | O16: =SUMIF($A$7:$A$109,N16,$D$7:$D$109) -> 175 | P16: =SUMIF(A$7:A$52,N16,E$7:E$52)+SUMIF(A$7:A$52,N16,J$7:J$52) -> 500 | Q16: =SUMIF(A$7:A$142,N16,F$7:F$142) -> 0 | R16: =SUMIF(A$7:A$71,N16,H$7:H$72) -> 0 | S16: =SUMIF(A$7:A$72,N16,I$7:I$72) -> 0 | T16: =SUMIF(A$7:A$72,N16,K$7:K$72) -> 0 | U16: =SUMIF(A$7:A$72,N16,G$7:G$72) -> 0 | V16: =SUMIF(A$7:A$72,N16,I$7:I$72) -> 0 | Y16: =1200000 -> 1200000 | Z16: =1700000 -> 1700000
A17: 46270 | B17: Night | C17: Kristo/Ulan | D17: 100 | N17: 46272 | O17: =SUMIF($A$7:$A$109,N17,$D$7:$D$109) -> 300 | P17: =SUMIF(A$7:A$52,N17,E$7:E$52)+SUMIF(A$7:A$52,N17,J$7:J$52) -> 750 | Q17: =SUMIF(A$7:A$142,N17,F$7:F$142) -> 0 | R17: =SUMIF(A$7:A$71,N17,H$7:H$72) -> 0 | S17: =SUMIF(A$7:A$72,N17,I$7:I$72) -> 0 | T17: =SUMIF(A$7:A$72,N17,K$7:K$72) -> 0 | U17: =SUMIF(A$7:A$72,N17,G$7:G$72) -> 0 | V17: =SUMIF(A$7:A$72,N17,I$7:I$72) -> 0 | Y17: =Y16/25 -> 48000 | Z17: =Z16/25 -> 68000
A18: 46271 | B18: Day | C18: Yanli/Hadi | D18: 175 | E18: 500 | N18: 46273 | O18: =SUMIF($A$7:$A$109,N18,$D$7:$D$109) -> 175 | P18: =SUMIF(A$7:A$52,N18,E$7:E$52)+SUMIF(A$7:A$52,N18,J$7:J$52) -> 0 | Q18: =SUMIF(A$7:A$142,N18,F$7:F$142) -> 0 | R18: =SUMIF(A$7:A$71,N18,H$7:H$72) -> 0 | S18: =SUMIF(A$7:A$72,N18,I$7:I$72) -> 0 | T18: =SUMIF(A$7:A$72,N18,K$7:K$72) -> 0 | U18: =SUMIF(A$7:A$72,N18,G$7:G$72) -> 0 | V18: =SUMIF(A$7:A$72,N18,I$7:I$72) -> 0
A19: 46272 | B19: Day | C19: Ulan | D19: 150 | E19: 750 | N19: 46274 | O19: =SUMIF($A$7:$A$109,N19,$D$7:$D$109) -> 175 | P19: =SUMIF(A$7:A$52,N19,E$7:E$52)+SUMIF(A$7:A$52,N19,J$7:J$52) -> 0 | Q19: =SUMIF(A$7:A$142,N19,F$7:F$142) -> 0 | R19: =SUMIF(A$7:A$71,N19,H$7:H$72) -> 0 | S19: =SUMIF(A$7:A$72,N19,I$7:I$72) -> 0 | T19: =SUMIF(A$7:A$72,N19,K$7:K$72) -> 0 | U19: =SUMIF(A$7:A$72,N19,G$7:G$72) -> 0 | V19: =SUMIF(A$7:A$72,N19,I$7:I$72) -> 0
A20: 46272 | B20: Night | D20: 150 | N20: 46275 | O20: =SUMIF($A$7:$A$109,N20,$D$7:$D$109) -> 300 | P20: =SUMIF(A$7:A$52,N20,E$7:E$52)+SUMIF(A$7:A$52,N20,J$7:J$52) -> 0 | Q20: =SUMIF(A$7:A$142,N20,F$7:F$142) -> 500 | R20: =SUMIF(A$7:A$71,N20,H$7:H$72) -> 0 | S20: =SUMIF(A$7:A$72,N20,I$7:I$72) -> 0 | T20: =SUMIF(A$7:A$72,N20,K$7:K$72) -> 0 | U20: =SUMIF(A$7:A$72,N20,G$7:G$72) -> 0 | V20: =SUMIF(A$7:A$72,N20,I$7:I$72) -> 0 | X20: Reagent Price (Rp)
A21: 46273 | B21: Day | D21: 175 | N21: 46276 | O21: =SUMIF($A$7:$A$109,N21,$D$7:$D$109) -> 200 | P21: =SUMIF(A$7:A$52,N21,E$7:E$52)+SUMIF(A$7:A$52,N21,J$7:J$52) -> 0 | Q21: =SUMIF(A$7:A$142,N21,F$7:F$142) -> 500 | R21: =SUMIF(A$7:A$71,N21,H$7:H$72) -> 0 | S21: =SUMIF(A$7:A$72,N21,I$7:I$72) -> 0 | T21: =SUMIF(A$7:A$72,N21,K$7:K$72) -> 50 | U21: =SUMIF(A$7:A$72,N21,G$7:G$72) -> 0 | V21: =SUMIF(A$7:A$72,N21,I$7:I$72) -> 0 | X21: Sandios kg | Y21: Lime kg | Z21: Carbon | AA21: Flculant | AB21: NaOH kg | AC21: HCl/Jerigen
A22: 46274 | B22: Day | D22: 175 | N22: 46277 | O22: =SUMIF($A$7:$A$109,N22,$D$7:$D$109) -> 100 | P22: =SUMIF(A$7:A$52,N22,E$7:E$52)+SUMIF(A$7:A$52,N22,J$7:J$52) -> 0 | Q22: =SUMIF(A$7:A$142,N22,F$7:F$142) -> 0 | R22: =SUMIF(A$7:A$71,N22,H$7:H$72) -> 0 | S22: =SUMIF(A$7:A$72,N22,I$7:I$72) -> 0 | T22: =SUMIF(A$7:A$72,N22,K$7:K$72) -> 0 | U22: =SUMIF(A$7:A$72,N22,G$7:G$72) -> 0 | V22: =SUMIF(A$7:A$72,N22,I$7:I$72) -> 0 | X22: 68000 | Y22: 2300 | Z22: 44000 | AA22: 30000 | AB22: 28000 | AC22: 450000
A23: 46274 | B23: Night | N23: 46278 | O23: =SUMIF($A$7:$A$109,N23,$D$7:$D$109) -> 225 | P23: =SUMIF(A$7:A$52,N23,E$7:E$52)+SUMIF(A$7:A$52,N23,J$7:J$52) -> 0 | Q23: =SUMIF(A$7:A$142,N23,F$7:F$142) -> 0 | R23: =SUMIF(A$7:A$71,N23,H$7:H$72) -> 0 | S23: =SUMIF(A$7:A$72,N23,I$7:I$72) -> 0 | T23: =SUMIF(A$7:A$72,N23,K$7:K$72) -> 25 | U23: =SUMIF(A$7:A$72,N23,G$7:G$72) -> 0 | V23: =SUMIF(A$7:A$72,N23,I$7:I$72) -> 0
A24: 46275 | B24: Day | C24: Ulan/Kristo | D24: 150 | F24: 500 | N24: 46279 | O24: =SUMIF($A$7:$A$109,N24,$D$7:$D$109) -> 125 | P24: =SUMIF(A$7:A$52,N24,E$7:E$52)+SUMIF(A$7:A$52,N24,J$7:J$52) -> 0 | Q24: =SUMIF(A$7:A$142,N24,F$7:F$142) -> 0 | R24: =SUMIF(A$7:A$71,N24,H$7:H$72) -> 0 | S24: =SUMIF(A$7:A$72,N24,I$7:I$72) -> 0 | T24: =SUMIF(A$7:A$72,N24,K$7:K$72) -> 0 | U24: =SUMIF(A$7:A$72,N24,G$7:G$72) -> 0 | V24: =SUMIF(A$7:A$72,N24,I$7:I$72) -> 0 | X24: Total Estimasi Biaya Reagent Pengolahan
A25: 46275 | B25: Night | C25: Yanli/Hadi | D25: 150 | N25: 46280 | O25: =SUMIF($A$7:$A$109,N25,$D$7:$D$109) -> 375 | P25: =SUMIF(A$7:A$52,N25,E$7:E$52)+SUMIF(A$7:A$52,N25,J$7:J$52) -> 0 | Q25: =SUMIF(A$7:A$142,N25,F$7:F$142) -> 0 | R25: =SUMIF(A$7:A$71,N25,H$7:H$72) -> 0 | S25: =SUMIF(A$7:A$72,N25,I$7:I$72) -> 0 | T25: =SUMIF(A$7:A$72,N25,K$7:K$72) -> 25 | U25: =SUMIF(A$7:A$72,N25,G$7:G$72) -> 0 | V25: =SUMIF(A$7:A$72,N25,I$7:I$72) -> 0 | X25: Sandios | Y25: Lime | Z25: Carbon | AA25: Floculant | AB25: NaOH | AC25: HCl
A26: 46276 | B26: Day | C26: Ulan | D26: 200 | F26: 500 | K26: 50 | N26: 46281 | O26: =SUMIF($A$7:$A$109,N26,$D$7:$D$109) -> 200 | P26: =SUMIF(A$7:A$52,N26,E$7:E$52)+SUMIF(A$7:A$52,N26,J$7:J$52) -> 0 | Q26: =SUMIF(A$7:A$142,N26,F$7:F$142) -> 0 | R26: =SUMIF(A$7:A$71,N26,H$7:H$72) -> 0 | S26: =SUMIF(A$7:A$72,N26,I$7:I$72) -> 0 | T26: =SUMIF(A$7:A$72,N26,K$7:K$72) -> 0 | U26: =SUMIF(A$7:A$72,N26,G$7:G$72) -> 0 | V26: =SUMIF(A$7:A$72,N26,I$7:I$72) -> 0 | X26: =X22*X8 -> 411400000 | Y26: =Y22*Y8 -> 9545000 | Z26: =Z22*Z8 -> 176000000 | AA26: =AA22*AA8 -> 9750000 | AB26: =AB22*AB8 -> 2800000 | AC26: =AC22*AC8 -> 3150000
A27: 46277 | D27: 100 | N27: 46282 | O27: =SUMIF($A$7:$A$109,N27,$D$7:$D$109) -> 250 | P27: =SUMIF(A$7:A$52,N27,E$7:E$52)+SUMIF(A$7:A$52,N27,J$7:J$52) -> 0 | Q27: =SUMIF(A$7:A$142,N27,F$7:F$142) -> 0 | R27: =SUMIF(A$7:A$71,N27,H$7:H$72) -> 0 | S27: =SUMIF(A$7:A$72,N27,I$7:I$72) -> 0 | T27: =SUMIF(A$7:A$72,N27,K$7:K$72) -> 0 | U27: =SUMIF(A$7:A$72,N27,G$7:G$72) -> 0 | V27: =SUMIF(A$7:A$72,N27,I$7:I$72) -> 0 | X27: Total Estimasi Biaya Reagent Pengolahan | Z27: =SUM(X26:AC26) -> 612645000
A28: 46278 | D28: 225 | K28: 25 | N28: 46283 | O28: =SUMIF($A$7:$A$109,N28,$D$7:$D$109) -> 275 | P28: =SUMIF(A$7:A$52,N28,E$7:E$52)+SUMIF(A$7:A$52,N28,J$7:J$52) -> 325 | Q28: =SUMIF(A$7:A$142,N28,F$7:F$142) -> 0 | R28: =SUMIF(A$7:A$71,N28,H$7:H$72) -> 0 | S28: =SUMIF(A$7:A$72,N28,I$7:I$72) -> 0 | T28: =SUMIF(A$7:A$72,N28,K$7:K$72) -> 25 | U28: =SUMIF(A$7:A$72,N28,G$7:G$72) -> 0 | V28: =SUMIF(A$7:A$72,N28,I$7:I$72) -> 0 | X28: =X26/$Z$27 -> 0.6715145 | Y28: =Y26/$Z$27 -> 0.015579985 | Z28: =Z26/$Z$27 -> 0.28727893 | AA28: =AA26/$Z$27 -> 0.0159146 | AB28: =AB26/$Z$27 -> 0.0045703466 | AC28: =AC26/$Z$27 -> 0.0051416399
A29: 46279 | B29: Night | C29: Ulan | D29: 125 | N29: 46284 | O29: =SUMIF($A$7:$A$109,N29,$D$7:$D$109) -> 0 | P29: =SUMIF(A$7:A$52,N29,E$7:E$52)+SUMIF(A$7:A$52,N29,J$7:J$52) -> 0 | Q29: =SUMIF(A$7:A$142,N29,F$7:F$142) -> 0 | R29: =SUMIF(A$7:A$71,N29,H$7:H$72) -> 0 | S29: =SUMIF(A$7:A$72,N29,I$7:I$72) -> 0 | T29: =SUMIF(A$7:A$72,N29,K$7:K$72) -> 0 | U29: =SUMIF(A$7:A$72,N29,G$7:G$72) -> 0 | V29: =SUMIF(A$7:A$72,N29,I$7:I$72) -> 0
A30: 46280 | B30: Day | C30: Yan leee | D30: 150 | K30: 25 | N30: 46285 | O30: =SUMIF($A$7:$A$109,N30,$D$7:$D$109) -> 0 | P30: =SUMIF(A$7:A$52,N30,E$7:E$52)+SUMIF(A$7:A$52,N30,J$7:J$52) -> 0 | Q30: =SUMIF(A$7:A$142,N30,F$7:F$142) -> 0 | R30: =SUMIF(A$7:A$71,N30,H$7:H$72) -> 0 | S30: =SUMIF(A$7:A$72,N30,I$7:I$72) -> 0 | T30: =SUMIF(A$7:A$72,N30,K$7:K$72) -> 0 | U30: =SUMIF(A$7:A$72,N30,G$7:G$72) -> 0 | V30: =SUMIF(A$7:A$72,N30,I$7:I$72) -> 0
A31: 46280 | B31: Night | C31: Ulan | D31: 225 | N31: 46286 | O31: =SUMIF($A$7:$A$109,N31,$D$7:$D$109) -> 175 | P31: =SUMIF(A$7:A$52,N31,E$7:E$52)+SUMIF(A$7:A$52,N31,J$7:J$52) -> 0 | Q31: =SUMIF(A$7:A$142,N31,F$7:F$142) -> 0 | R31: =SUMIF(A$7:A$71,N31,H$7:H$72) -> 0 | S31: =SUMIF(A$7:A$72,N31,I$7:I$72) -> 0 | T31: =SUMIF(A$7:A$72,N31,K$7:K$72) -> 0 | U31: =SUMIF(A$7:A$72,N31,G$7:G$72) -> 0 | V31: =SUMIF(A$7:A$72,N31,I$7:I$72) -> 0
A32: 46281 | B32: Day | C32: Yan leee Huang | D32: 175 | N32: 46287 | O32: =SUMIF($A$7:$A$109,N32,$D$7:$D$109) -> 250 | P32: =SUMIF(A$7:A$52,N32,E$7:E$52)+SUMIF(A$7:A$52,N32,J$7:J$52) -> 0 | Q32: =SUMIF(A$7:A$142,N32,F$7:F$142) -> 0 | R32: =SUMIF(A$7:A$71,N32,H$7:H$72) -> 0 | S32: =SUMIF(A$7:A$72,N32,I$7:I$72) -> 0 | T32: =SUMIF(A$7:A$72,N32,K$7:K$72) -> 50 | U32: =SUMIF(A$7:A$72,N32,G$7:G$72) -> 0 | V32: =SUMIF(A$7:A$72,N32,I$7:I$72) -> 0
A33: 46281 | B33: Night | C33: Ulan | D33: 25 | N33: 46288 | O33: =SUMIF($A$7:$A$109,N33,$D$7:$D$109) -> 125 | P33: =SUMIF(A$7:A$52,N33,E$7:E$52)+SUMIF(A$7:A$52,N33,J$7:J$52) -> 0 | Q33: =SUMIF(A$7:A$142,N33,F$7:F$142) -> 0 | R33: =SUMIF(A$7:A$71,N33,H$7:H$72) -> 0 | S33: =SUMIF(A$7:A$72,N33,I$7:I$72) -> 0 | T33: =SUMIF(A$7:A$72,N33,K$7:K$72) -> 0 | U33: =SUMIF(A$7:A$72,N33,G$7:G$72) -> 0 | V33: =SUMIF(A$7:A$72,N33,I$7:I$72) -> 0
A34: 46282 | B34: Day | D34: 125 | N34: 46289 | O34: =SUMIF($A$7:$A$109,N34,$D$7:$D$109) -> 675 | P34: =SUMIF(A$7:A$52,N34,E$7:E$52)+SUMIF(A$7:A$52,N34,J$7:J$52) -> 325 | Q34: =SUMIF(A$7:A$142,N34,F$7:F$142) -> 0 | R34: =SUMIF(A$7:A$71,N34,H$7:H$72) -> 0 | S34: =SUMIF(A$7:A$72,N34,I$7:I$72) -> 0 | T34: =SUMIF(A$7:A$72,N34,K$7:K$72) -> 25 | U34: =SUMIF(A$7:A$72,N34,G$7:G$72) -> 0 | V34: =SUMIF(A$7:A$72,N34,I$7:I$72) -> 0
A35: 46282 | B35: Night | D35: 125 | N35: 46290 | O35: =SUMIF($A$7:$A$109,N35,$D$7:$D$109) -> 175 | P35: =SUMIF(A$7:A$52,N35,E$7:E$52)+SUMIF(A$7:A$52,N35,J$7:J$52) -> 0 | Q35: =SUMIF(A$7:A$142,N35,F$7:F$142) -> 0 | R35: =SUMIF(A$7:A$71,N35,H$7:H$72) -> 0 | S35: =SUMIF(A$7:A$72,N35,I$7:I$72) -> 0 | T35: =SUMIF(A$7:A$72,N35,K$7:K$72) -> 25 | U35: =SUMIF(A$7:A$72,N35,G$7:G$72) -> 0 | V35: =SUMIF(A$7:A$72,N35,I$7:I$72) -> 0
A36: 46283 | B36: Day | D36: 50 | E36: 325 | K36: 25 | N36: 46291 | O36: =SUMIF($A$7:$A$109,N36,$D$7:$D$109) -> 0 | P36: =SUMIF(A$7:A$52,N36,E$7:E$52)+SUMIF(A$7:A$52,N36,J$7:J$52) -> 0 | Q36: =SUMIF(A$7:A$142,N36,F$7:F$142) -> 0 | R36: =SUMIF(A$7:A$71,N36,H$7:H$72) -> 0 | S36: =SUMIF(A$7:A$72,N36,I$7:I$72) -> 0 | T36: =SUMIF(A$7:A$72,N36,K$7:K$72) -> 0 | U36: =SUMIF(A$7:A$72,N36,G$7:G$72) -> 0 | V36: =SUMIF(A$7:A$72,N36,I$7:I$72) -> 0
A37: 46283 | B37: Night | D37: 225 | N37: 46292 | O37: =SUMIF($A$7:$A$109,N37,$D$7:$D$109) -> 150 | P37: =SUMIF(A$7:A$52,N37,E$7:E$52)+SUMIF(A$7:A$52,N37,J$7:J$52) -> 0 | Q37: =SUMIF(A$7:A$142,N37,F$7:F$142) -> 0 | R37: =SUMIF(A$7:A$71,N37,H$7:H$72) -> 0 | S37: =SUMIF(A$7:A$72,N37,I$7:I$72) -> 0 | T37: =SUMIF(A$7:A$72,N37,K$7:K$72) -> 0 | U37: =SUMIF(A$7:A$72,N37,G$7:G$72) -> 0 | V37: =SUMIF(A$7:A$72,N37,I$7:I$72) -> 0
A38: 46284 | N38: 46293 | O38: =SUMIF($A$7:$A$109,N38,$D$7:$D$109) -> 175 | P38: =SUMIF(A$7:A$52,N38,E$7:E$52)+SUMIF(A$7:A$52,N38,J$7:J$52) -> 0 | Q38: =SUMIF(A$7:A$142,N38,F$7:F$142) -> 0 | R38: =SUMIF(A$7:A$71,N38,H$7:H$72) -> 0 | S38: =SUMIF(A$7:A$72,N38,I$7:I$72) -> 0 | T38: =SUMIF(A$7:A$72,N38,K$7:K$72) -> 25 | U38: =SUMIF(A$7:A$72,N38,G$7:G$72) -> 0 | V38: =SUMIF(A$7:A$72,N38,I$7:I$72) -> 0
A39: 46285 | B39: Day | C39: Kristo/Ulan | N39: 46294 | O39: =SUMIF($A$7:$A$109,N39,$D$7:$D$109) -> 175 | P39: =SUMIF(A$7:A$52,N39,E$7:E$52)+SUMIF(A$7:A$52,N39,J$7:J$52) -> 0 | Q39: =SUMIF(A$7:A$142,N39,F$7:F$142) -> 0 | R39: =SUMIF(A$7:A$71,N39,H$7:H$72) -> 0 | S39: =SUMIF(A$7:A$72,N39,I$7:I$72) -> 0 | T39: =SUMIF(A$7:A$72,N39,K$7:K$72) -> 0 | U39: =SUMIF(A$7:A$72,N39,G$7:G$72) -> 0 | V39: =SUMIF(A$7:A$72,N39,I$7:I$72) -> 0
A40: 46285 | B40: Night | N40: 46295 | O40: =SUMIF($A$7:$A$109,N40,$D$7:$D$109) -> 0 | P40: =SUMIF(A$7:A$52,N40,E$7:E$52)+SUMIF(A$7:A$52,N40,J$7:J$52) -> 0 | Q40: =SUMIF(A$7:A$142,N40,F$7:F$142) -> 0 | R40: =SUMIF(A$7:A$71,N40,H$7:H$72) -> 0 | S40: =SUMIF(A$7:A$72,N40,I$7:I$72) -> 0 | T40: =SUMIF(A$7:A$72,N40,K$7:K$72) -> 0 | U40: =SUMIF(A$7:A$72,N40,G$7:G$72) -> 0 | V40: =SUMIF(A$7:A$72,N40,I$7:I$72) -> 0
A41: 46286 | B41: Day | C41: Kristo Ulan | D41: 25 | N41: 46296 | O41: =SUMIF($A$7:$A$109,N41,$D$7:$D$109) -> 0 | P41: =SUMIF(A$7:A$52,N41,E$7:E$52)+SUMIF(A$7:A$52,N41,J$7:J$52) -> 0 | Q41: =SUMIF(A$7:A$142,N41,F$7:F$142) -> 0 | R41: =SUMIF(A$7:A$71,N41,H$7:H$72) -> 0 | S41: =SUMIF(A$7:A$72,N41,I$7:I$72) -> 0 | T41: =SUMIF(A$7:A$72,N41,K$7:K$72) -> 0 | U41: =SUMIF(A$7:A$72,N41,G$7:G$72) -> 0 | V41: =SUMIF(A$7:A$72,N41,I$7:I$72) -> 0
...

Sheet Crushing
B4: Crushing Production
B5: Date | D5: Shift | E5: PIC | F5: Bucket | G5: Type | H5: Moisture % | I5: Volume Bucket | J5: SG Bulk Density (ton/m3) | K5: WMT/SHIFT (wet metrix ton) | L5: DMT/SHIFT (dry metrix ton) | M5: Ton/hour (tph) | N5: Tonage/Day (Tpd) | O5: Keterangan | S5: Volume Unit (m3) | W5: Moisture Check Daily
B6: 46174 | D6: Day | I6: =IFERROR((VLOOKUP(G6,S$6:T$8,2,FALSE)),"") | K6: =IFERROR((F6*I6*J6),"") | L6: =IFERROR(((F6*I6)*J6)*(1-H6),"") | M6: =IFERROR((K6/12),"") | N6: =SUM(L6:L7) -> 0 | S6: Exca PC 130 | T6: 0.5 | U6: 0.6 | W6: Tanggal | X6: BT | Y6: Wet | Z6: Dry | AA6: %
D7: Night | I7: =IFERROR((VLOOKUP(G7,S$6:T$8,2,FALSE)),"") | K7: =IFERROR((F7*I7*J7),"") | L7: =IFERROR(((F7*I7)*J7)*(1-H7),"") | M7: =IFERROR((K7/12),"") | S7: Exca PC 200 | T7: 0.7 | Y7: 2860 | Z7: 2795 | AA7: =(Y7-Z7)/Y7 -> 0.022727273
B8: 46175 | D8: Day | E8: Toni | F8: 141 | G8: Exca PC 130 | H8: 0.18 | I8: =IFERROR((VLOOKUP(G8,S$6:T$8,2,FALSE)),"") -> 0.5 | J8: 1.35 | K8: =IFERROR((F8*I8*J8),"") -> 95.175 | L8: =IFERROR(((F8*I8)*J8)*(1-H8),"") -> 78.0435 | M8: =IFERROR((K8/6),"") -> 15.8625 | N8: =SUM(L8:L9) -> 78.0435 | S8: Loader | T8: 3 | U8: 3 | Y8: 3025 | Z8: 2935 | AA8: =(Y8-Z8)/Y8 -> 0.029752066
D9: Night | I9: =IFERROR((VLOOKUP(G9,S$6:T$8,2,FALSE)),"") | K9: =IFERROR((F9*I9*J9),"") | L9: =IFERROR(((F9*I9)*J9)*(1-H9),"") | M9: =IFERROR((K9/12),"") | Y9: 2535 | Z9: 2430 | AA9: =(Y9-Z9)/Y9 -> 0.041420118
B10: 46176 | D10: Day | E10: Toni | F10: 32 | G10: Exca PC 130 | H10: 0.18 | I10: =IFERROR((VLOOKUP(G10,S$6:T$8,2,FALSE)),"") -> 0.5 | J10: 1.35 | K10: =IFERROR((F10*I10*J10),"") -> 21.6 | L10: =IFERROR(((F10*I10)*J10)*(1-H10),"") -> 17.712 | M10: =IFERROR((K10/12),"") -> 1.8 | N10: =SUM(L10:L11) -> 17.712 | Y10: 2695 | Z10: 2555 | AA10: =(Y10-Z10)/Y10 -> 0.051948052
D11: Night | I11: =IFERROR((VLOOKUP(G11,S$6:T$8,2,FALSE)),"") | K11: =IFERROR((F11*I11*J11),"") | L11: =IFERROR(((F11*I11)*J11)*(1-H11),"") | M11: =IFERROR((K11/12),"") | Y11: 2530 | Z11: 2460 | AA11: =(Y11-Z11)/Y11 -> 0.027667984
B12: 46177 | D12: Day | E12: Deni | F12: 282 | G12: Exca PC 130 | H12: 0.17 | I12: =IFERROR((VLOOKUP(G12,S$6:T$8,2,FALSE)),"") -> 0.5 | J12: 1.35 | K12: =IFERROR((F12*I12*J12),"") -> 190.35 | L12: =IFERROR(((F12*I12)*J12)*(1-H12),"") -> 157.9905 | M12: =IFERROR((K12/12),"") -> 15.8625 | N12: =SUM(L12:L13) -> 157.9905 | Y12: 2130 | Z12: 2075 | AA12: =(Y12-Z12)/Y12 -> 0.025821596
D13: Night | I13: =IFERROR((VLOOKUP(G13,S$6:T$8,2,FALSE)),"") | K13: =IFERROR((F13*I13*J13),"") | L13: =IFERROR(((F13*I13)*J13)*(1-H13),"") | M13: =IFERROR((K13/12),"") | Y13: 2235 | Z13: 2185 | AA13: =(Y13-Z13)/Y13 -> 0.022371365
B14: 46252 | D14: Day | E14: Adi | F14: 62 | G14: Exca PC 130 | H14: 0.12 | I14: =IFERROR((VLOOKUP(G14,S$6:T$8,2,FALSE)),"") -> 0.5 | J14: 1.39 | K14: =IFERROR((F14*I14*J14),"") -> 43.09 | L14: =IFERROR(((F14*I14)*J14)*(1-H14),"") -> 37.9192 | M14: =IFERROR((K14/12),"") -> 3.5908333 | N14: =SUM(L14:L15) -> 37.9192 | O14: perbaikan conveyor cone crusher to ball mill | S14: =16*4 -> 64 | Y14: 2450 | Z14: 2415 | AA14: =(Y14-Z14)/Y14 -> 0.014285714
D15: Night | I15: =IFERROR((VLOOKUP(G15,S$6:T$8,2,FALSE)),"") | K15: =IFERROR((F15*I15*J15),"") | L15: =IFERROR(((F15*I15)*J15)*(1-H15),"") | M15: =IFERROR((K15/12),"")
B16: 46253 | D16: Day | E16: Adi | F16: 463 | G16: Exca PC 130 | H16: 0.12 | I16: =IFERROR((VLOOKUP(G16,S$6:T$8,2,FALSE)),"") -> 0.5 | J16: 1.39 | K16: =IFERROR((F16*I16*J16),"") -> 321.785 | L16: =IFERROR(((F16*I16)*J16)*(1-H16),"") -> 283.1708 | M16: =IFERROR((K16/12),"") -> 26.815417 | N16: =SUM(L16:L17) -> 283.1708 | O16: Istirahat jam 12:00-13:00 | S16: =S14/1.4 -> 45.714286
D17: Night | I17: =IFERROR((VLOOKUP(G17,S$6:T$8,2,FALSE)),"") | K17: =IFERROR((F17*I17*J17),"") | L17: =IFERROR(((F17*I17)*J17)*(1-H17),"") | M17: =IFERROR((K17/12),"") | O17: material vein bolder agustus 2026
B18: 46254 | D18: Day | E18: Adi | F18: 539 | G18: Exca PC 130 | H18: 0.1 | I18: =IFERROR((VLOOKUP(G18,S$6:T$8,2,FALSE)),"") -> 0.5 | J18: 1.39 | K18: =IFERROR((F18*I18*J18),"") -> 374.605 | L18: =IFERROR(((F18*I18)*J18)*(1-H18),"") -> 337.1445 | M18: =IFERROR((K18/12),"") -> 31.217083 | N18: =SUM(L18:L19) -> 337.1445 | O18: Istirahat jam 12:00-13:00 | V18: =(T8*3)*(1-12%) -> 7.92 | W18: 3 bucket louder 24 april 2026
D19: Night | I19: =IFERROR((VLOOKUP(G19,S$6:T$8,2,FALSE)),"") | K19: =IFERROR((F19*I19*J19),"") | L19: =IFERROR(((F19*I19)*J19)*(1-H19),"") | M19: =IFERROR((K19/12),"") | O19: Vein Bolder Agustus
B20: 46255 | D20: Day | E20: Adi | F20: 409 | G20: Exca PC 130 | H20: 0.1 | I20: =IFERROR((VLOOKUP(G20,S$6:T$8,2,FALSE)),"") -> 0.5 | J20: 1.39 | K20: =IFERROR((F20*I20*J20),"") -> 284.255 | L20: =IFERROR(((F20*I20)*J20)*(1-H20),"") -> 255.8295 | M20: =IFERROR(((K20+K21)/12),"") -> 27.162917 | N20: =SUM(L20:L21) -> 293.3595 | O20: ='Crushing Down Time Hours'!G9 -> isitrahat jumat 11-13, 16:20-16:55 Perbaikan Cone Crusher
D21: Night | F21: 10 | G21: Loader | H21: 0.1 | I21: =IFERROR((VLOOKUP(G21,S$6:T$8,2,FALSE)),"") -> 3 | J21: 1.39 | K21: =IFERROR((F21*I21*J21),"") -> 41.7 | L21: =IFERROR(((F21*I21)*J21)*(1-H21),"") -> 37.53
B22: 46256 | D22: Day | E22: Adi | F22: 315 | G22: Exca PC 130 | H22: 0.1 | I22: =IFERROR((VLOOKUP(G22,S$6:T$8,2,FALSE)),"") -> 0.5 | J22: 1.39 | K22: =IFERROR((F22*I22*J22),"") -> 218.925 | L22: =IFERROR(((F22*I22)*J22)*(1-H22),"") -> 197.0325 | M22: =IFERROR((K22/12),"") -> 18.24375 | N22: =SUM(L22:L23) -> 197.0325 | O22: ='Crushing Down Time Hours'!G10 -> Material Habis hanya running 9 Jam
D23: Night | I23: =IFERROR((VLOOKUP(G23,S$6:T$8,2,FALSE)),"") | K23: =IFERROR((F23*I23*J23),"") | L23: =IFERROR(((F23*I23)*J23)*(1-H23),"") | M23: =IFERROR((K23/12),"")
B24: 46257 | D24: Day | I24: =IFERROR((VLOOKUP(G24,S$6:T$8,2,FALSE)),"") | K24: =IFERROR((F24*I24*J24),"") | L24: =IFERROR(((F24*I24)*J24)*(1-H24),"") | M24: =IFERROR((K24/12),"") | N24: =SUM(L24:L25) -> 0
D25: Night | I25: =IFERROR((VLOOKUP(G25,S$6:T$8,2,FALSE)),"") | K25: =IFERROR((F25*I25*J25),"") | L25: =IFERROR(((F25*I25)*J25)*(1-H25),"") | M25: =IFERROR((K25/12),"")
B26: 46258 | D26: Day | E26: Adi | F26: 234 | G26: Exca PC 130 | H26: 0.1 | I26: =IFERROR((VLOOKUP(G26,S$6:T$8,2,FALSE)),"") -> 0.5 | J26: 1.39 | K26: =IFERROR((F26*I26*J26),"") -> 162.63 | L26: =IFERROR(((F26*I26)*J26)*(1-H26),"") -> 146.367 | M26: =IFERROR((K26/12),"") -> 13.5525 | N26: =SUM(L26:L27) -> 165.132 | O26: ='Crushing Down Time Hours'!G12 -> istirahat jam 12-13, material habis dan selesai jam 17:30
D27: Night | E27: Toni | F27: 5 | G27: Loader | H27: 0.1 | I27: =IFERROR((VLOOKUP(G27,S$6:T$8,2,FALSE)),"") -> 3 | J27: 1.39 | K27: =IFERROR((F27*I27*J27),"") -> 20.85 | L27: =IFERROR(((F27*I27)*J27)*(1-H27),"") -> 18.765 | M27: =IFERROR((K27/12),"") -> 1.7375
B28: 46259 | D28: Day | I28: =IFERROR((VLOOKUP(G28,S$6:T$8,2,FALSE)),"") | K28: =IFERROR((F28*I28*J28),"") | L28: =IFERROR(((F28*I28)*J28)*(1-H28),"") | M28: =IFERROR((K28/12),"") | N28: =SUM(L28:L29) -> 0
D29: Night | I29: =IFERROR((VLOOKUP(G29,S$6:T$8,2,FALSE)),"") | K29: =IFERROR((F29*I29*J29),"") | L29: =IFERROR(((F29*I29)*J29)*(1-H29),"") | M29: =IFERROR((K29/12),"")
B30: 46260 | D30: Day | I30: =IFERROR((VLOOKUP(G30,S$6:T$8,2,FALSE)),"") | K30: =IFERROR((F30*I30*J30),"") | L30: =IFERROR(((F30*I30)*J30)*(1-H30),"") | M30: =IFERROR((K30/12),"") | N30: =SUM(L30:L31) -> 0
D31: Night | I31: =IFERROR((VLOOKUP(G31,S$6:T$8,2,FALSE)),"") | K31: =IFERROR((F31*I31*J31),"") | L31: =IFERROR(((F31*I31)*J31)*(1-H31),"") | M31: =IFERROR((K31/12),"")
B32: 46261 | D32: Day | E32: Toni | F32: 202 | G32: Exca PC 130 | H32: 0.11 | I32: =IFERROR((VLOOKUP(G32,S$6:T$8,2,FALSE)),"") -> 0.5 | J32: 1.39 | K32: =IFERROR((F32*I32*J32),"") -> 140.39 | L32: =IFERROR(((F32*I32)*J32)*(1-H32),"") -> 124.9471 | M32: =IFERROR((K32/12),"") -> 11.699167 | N32: =SUM(L32:L33) -> 124.9471 | O32: ='Crushing Down Time Hours'!G15 -> Start Crusher jam 10:00, dikarenakan bari loading material jam 08:00, pada jam 15:30-17:15 stop dikarenakan material stuck pada cone crusher
D33: Night | I33: =IFERROR((VLOOKUP(G33,S$6:T$8,2,FALSE)),"") | K33: =IFERROR((F33*I33*J33),"") | L33: =IFERROR(((F33*I33)*J33)*(1-H33),"") | M33: =IFERROR((K33/12),"")
B34: 46262 | D34: Day | E34: Toni | F34: 290 | G34: Exca PC 130 | H34: 0.11 | I34: =IFERROR((VLOOKUP(G34,S$6:T$8,2,FALSE)),"") -> 0.5 | J34: 1.3 | K34: =IFERROR((F34*I34*J34),"") -> 188.5 | L34: =IFERROR(((F34*I34)*J34)*(1-H34),"") -> 167.765 | M34: =IFERROR((K34/12),"") -> 15.708333 | N34: =SUM(L34:L35) -> 167.765 | O34: ='Crushing Down Time Hours'!G16 -> Start Crusher jam 08:00, istirahat jam 11:00-13:00
D35: Night | I35: =IFERROR((VLOOKUP(G35,S$6:T$8,2,FALSE)),"") | K35: =IFERROR((F35*I35*J35),"") | L35: =IFERROR(((F35*I35)*J35)*(1-H35),"") | M35: =IFERROR((K35/12),"")
B36: 46263 | D36: Day | E36: Toni | F36: 411 | G36: Exca PC 130 | H36: 0.1 | I36: =IFERROR((VLOOKUP(G36,S$6:T$8,2,FALSE)),"") -> 0.5 | J36: 1.3 | K36: =IFERROR((F36*I36*J36),"") -> 267.15 | L36: =IFERROR(((F36*I36)*J36)*(1-H36),"") -> 240.435 | M36: =IFERROR((K36/12),"") -> 22.2625 | N36: =SUM(L36:L37) -> 240.435 | O36: ='Crushing Down Time Hours'!G17 -> istirahat jam 12-13, 14:00-15:00 ada loading material dari mining
D37: Night | I37: =IFERROR((VLOOKUP(G37,S$6:T$8,2,FALSE)),"") | K37: =IFERROR((F37*I37*J37),"") | L37: =IFERROR(((F37*I37)*J37)*(1-H37),"") | M37: =IFERROR((K37/12),"")
B38: 46264 | D38: Day | E38: Toni | F38: 92 | G38: Exca PC 130 | H38: 0.1 | I38: =IFERROR((VLOOKUP(G38,S$6:T$8,2,FALSE)),"") -> 0.5 | J38: 1.3 | K38: =IFERROR((F38*I38*J38),"") -> 59.8 | L38: =IFERROR(((F38*I38)*J38)*(1-H38),"") -> 53.82 | M38: =IFERROR((K38/12),"") -> 4.9833333 | N38: =SUM(L38:L39) -> 53.82
D39: Night | I39: =IFERROR((VLOOKUP(G39,S$6:T$8,2,FALSE)),"") | K39: =IFERROR((F39*I39*J39),"") | L39: =IFERROR(((F39*I39)*J39)*(1-H39),"") | M39: =IFERROR((K39/12),"")
B40: 46265 | D40: Day | I40: =IFERROR((VLOOKUP(G40,S$6:T$8,2,FALSE)),"") | K40: =IFERROR((F40*I40*J40),"") | L40: =IFERROR(((F40*I40)*J40)*(1-H40),"") | M40: =IFERROR((K40/12),"") | N40: =SUM(L40:L41) -> 0
D41: Night | I41: =IFERROR((VLOOKUP(G41,S$6:T$8,2,FALSE)),"") | K41: =IFERROR((F41*I41*J41),"") | L41: =IFERROR(((F41*I41)*J41)*(1-H41),"") | M41: =IFERROR((K41/12),"")
B42: 46266 | D42: Day | I42: =IFERROR((VLOOKUP(G42,S$6:T$8,2,FALSE)),"") | K42: =IFERROR((F42*I42*J42),"") | L42: =IFERROR(((F42*I42)*J42)*(1-H42),"") | M42: =IFERROR((K42/12),"") | N42: =SUM(L42:L43) -> 0
D43: Night | I43: =IFERROR((VLOOKUP(G43,S$6:T$8,2,FALSE)),"") | K43: =IFERROR((F43*I43*J43),"") | L43: =IFERROR(((F43*I43)*J43)*(1-H43),"") | M43: =IFERROR((K43/12),"")
...

Sheet Crushing Down Time Hours
B1: Down Time Process Crushing PT Bulawan Daya Lestari
F2: Agustus 2026
A3: DOWN TIME (HOUR)
A4: Date | C4: PIC | D4: Stop Time | E4: Start Time | F4: Down Time (Mins) | G4: Reason | J4: Date | K4: Total Down Time (Mins) | L4: Running Time (Hours) | M4: Availability (%) | N4: Down Time (Hours)
A6: 46252 | C6: Toni | D6: 0.00069444444 | E6: 0.91597222 | F6: =(E6-D6)*1440 -> 1318 | G6: Perbaikan Conveyor Cone Crusher, dan satu shift kerja | J6: 46252 | K6: =F6 -> 1318 | L6: =(1440-K6)/60 -> 2.0333333 | M6: =L6/12 -> 0.16944444 | N6: =12-L6 -> 9.9666667
A7: 46253 | C7: Toni | D7: 0.00069444444 | E7: 0.54097222 | F7: =(E7-D7)*1440 -> 778 | G7: Satu shift kerja, istirahat jam 12-13:00 | J7: 46253 | K7: =F7 -> 778 | L7: =(1440-K7)/60 -> 11.033333 | M7: =L7/12 -> 0.91944444 | N7: =12-L7 -> 0.96666667
A8: 46254 | C8: Toni | D8: 0.00069444444 | E8: 0.54097222 | F8: =(E8-D8)*1440 -> 778 | J8: 46254 | K8: =F8 -> 778 | L8: =(1440-K8)/60 -> 11.033333 | M8: =L8/12 -> 0.91944444 | N8: =12-L8 -> 0.96666667 | Z8: Running Hours Vs Down Time Hours
A9: 46255 | C9: Toni | D9: 0.00069444444 | E9: 0.60763889 | F9: =(E9-D9)*1440 -> 874 | G9: isitrahat jumat 11-13, 16:20-16:55 Perbaikan Cone Crusher | J9: 46255 | K9: =F9 -> 874 | L9: =(1440-K9)/60 -> 9.4333333 | M9: =L9/12 -> 0.78611111 | N9: =12-L9 -> 2.5666667 | Z9: Total Running Hour | AA9: =L43 -> 65.95
